Workbook
Name Anchor: Config!$B$8
Name CostEq: Config!$B$4
Name CostFI: Config!$B$5
Name EdgeEq: Config!$B$6
Name EdgeFI: Config!$B$7
Name ExDivFlag: Config!$B$10
Name SessionLeft: Feed!$R$2
Name StaleMin: Config!$B$9

Sheet Dashboard
A1: 09:00 market closed
A2: Ticker | B2: Signal | C2: β / Wt | D2: Last | E2: Bid | F2: Ask | G2: Bid Sz | H2: Ask Sz | I2: Spread bps | J2: Chg % | K2: Volume | L2: Avg Vol | M2: Rel Vol | N2: σ 1D | O2: Move σ | P2: P>1σ | Q2: P>2σ | R2: P>3σ | S2: NAV T-1 | T2: Prem T-1 bps | U2: Und Move | V2: Fair Value | W2: vs FV bps | X2: Sell Edge | Y2: Buy Edge | Z2: Resid Z | AA2: Yield | AB2: Time
A3: SPY | B3: =IF(NOT(ISNUMBER(V3)),"",IF((NOW()-N(AB3))*1440>StaleMin,"STALE",IF(AND($AF3="EQUITY",ABS(N(T3))>ExDivFlag),"EX-DIV?",IF(X3>IF($AF3="FI",EdgeFI,EdgeEq),"SELL ETF / BUY "&UPPER($A$4),IF(Y3>IF($AF3="FI",EdgeFI,EdgeEq),"BUY ETF / SELL "&UPPER($A$4),""))))) -> STALE | C3: =IFERROR(IF(INDEX(Feed!$N:$N,$AG3)="","",INDEX(Feed!$N:$N,$AG3)),"") -> 1 | D3: =IFERROR(IF(INDEX(Feed!$B:$B,$AG3)="","",INDEX(Feed!$B:$B,$AG3)),"") -> 773.6197 | E3: =IFERROR(IF(INDEX(Feed!$C:$C,$AG3)="","",INDEX(Feed!$C:$C,$AG3)),"") -> 773.61 | F3: =IFERROR(IF(INDEX(Feed!$D:$D,$AG3)="","",INDEX(Feed!$D:$D,$AG3)),"") -> 773.66 | G3: =IFERROR(IF(INDEX(Feed!$E:$E,$AG3)="","",INDEX(Feed!$E:$E,$AG3)),"") -> 246 | H3: =IFERROR(IF(INDEX(Feed!$F:$F,$AG3)="","",INDEX(Feed!$F:$F,$AG3)),"") -> 1620 | I3: =IF(AND(N(E3)>0,N(F3)>0),(F3-E3)/((F3+E3)/2)*10000,"") -> 0.64629961 | J3: =IF(N(D3)>0,IFERROR(D3/INDEX(Feed!$G:$G,$AG3)-1,""),"") -> 0.015662146 | K3: =IFERROR(IF(INDEX(Feed!$H:$H,$AG3)="","",INDEX(Feed!$H:$H,$AG3)),"") -> 50486686 | L3: =IFERROR(IF(INDEX(Feed!$I:$I,$AG3)="","",INDEX(Feed!$I:$I,$AG3)),"") | M3: =IF(AND(N(K3)>0,N(L3)>0),K3/L3,"") | N3: =IFERROR(IF(INDEX(Feed!$L:$L,$AG3)="","",INDEX(Feed!$L:$L,$AG3)),"") -> 0.0073762093 | O3: =IF(AND(ISNUMBER(J3),N(N3)>0),J3/N3,"") -> 2.1233326 | P3: =IF(ISNUMBER(O3),IF(SessionLeft<=0,--(ABS(O3)>1),_xlfn.NORM.S.DIST((-1-O3)/SQRT(SessionLeft),TRUE)+1-_xlfn.NORM.S.DIST((1-O3)/SQRT(SessionLeft),TRUE)),"") -> 1 | Q3: =IF(ISNUMBER(O3),IF(SessionLeft<=0,--(ABS(O3)>2),_xlfn.NORM.S.DIST((-2-O3)/SQRT(SessionLeft),TRUE)+1-_xlfn.NORM.S.DIST((2-O3)/SQRT(SessionLeft),TRUE)),"") -> 1 | R3: =IF(ISNUMBER(O3),IF(SessionLeft<=0,--(ABS(O3)>3),_xlfn.NORM.S.DIST((-3-O3)/SQRT(SessionLeft),TRUE)+1-_xlfn.NORM.S.DIST((3-O3)/SQRT(SessionLeft),TRUE)),"") -> 0 | S3: =IFERROR(IF(INDEX(Feed!$J:$J,$AG3)="","",INDEX(Feed!$J:$J,$AG3)),"") -> 762.0114 | T3: =IFERROR(IF(N(S3)>0,(INDEX(Feed!$G:$G,$AG3)/S3-1)*10000,""),"") -> -4.2177847 | U3: =IFERROR(C3*$J$4,"") -> 0.015108122 | V3: =IF(ISNUMBER(U3),IF(AND(Anchor="NAV",N(S3)>0),S3,INDEX(Feed!$G:$G,$AG3))*(1+U3),"") -> 773.19771 | W3: =IF(ISNUMBER(V3),(IF(AND(N(E3)>0,N(F3)>0),(E3+F3)/2,D3)/V3-1)*10000,"") -> 5.655662 | X3: =IF(ISNUMBER(V3),(IF(N(E3)>0,E3,D3)/V3-1)*10000-IF($AF3="FI",CostFI,CostEq),"") -> 2.3323295 | Y3: =IF(ISNUMBER(V3),(1-IF(N(F3)>0,F3,D3)/V3)*10000-IF($AF3="FI",CostFI,CostEq),"") -> -8.9789946 | Z3: =IFERROR((J3-U3-INDEX(Feed!$O:$O,$AG3))/INDEX(Feed!$P:$P,$AG3),"") -> 0.53567994 | AA3: =IFERROR(IF(INDEX(Feed!$K:$K,$AG3)="","",INDEX(Feed!$K:$K,$AG3)),"") -> 0.0098 | AB3: =IFERROR(IF(INDEX(Feed!$M:$M,$AG3)="","",INDEX(Feed!$M:$M,$AG3)),"") -> 46287.672 | AD3: SPY | AE3: ETF | AF3: EQUITY | AG3: =IFERROR(MATCH($AD3,Feed!$A:$A,0),"") -> 2
A4: Basket | C4: =IFERROR(SUMIFS(Holdings!$G:$G,Holdings!$A:$A,$A$3)/SUMIFS(Holdings!$D:$D,Holdings!$A:$A,$A$3),"") -> 0.8010182 | J4: =IFERROR(SUMIFS(Holdings!$F:$F,Holdings!$A:$A,$A$3)/SUMIFS(Holdings!$G:$G,Holdings!$A:$A,$A$3),"") -> 0.015108122 | N4: =IFERROR(IF(INDEX(Feed!$L:$L,$AG4)="","",INDEX(Feed!$L:$L,$AG4)),"") -> 0.0072114745 | O4: =IF(AND(ISNUMBER(J4),N(N4)>0),J4/N4,"") -> 2.0950115 | P4: =IF(ISNUMBER(O4),IF(SessionLeft<=0,--(ABS(O4)>1),_xlfn.NORM.S.DIST((-1-O4)/SQRT(SessionLeft),TRUE)+1-_xlfn.NORM.S.DIST((1-O4)/SQRT(SessionLeft),TRUE)),"") -> 1 | Q4: =IF(ISNUMBER(O4),IF(SessionLeft<=0,--(ABS(O4)>2),_xlfn.NORM.S.DIST((-2-O4)/SQRT(SessionLeft),TRUE)+1-_xlfn.NORM.S.DIST((2-O4)/SQRT(SessionLeft),TRUE)),"") -> 1 | R4: =IF(ISNUMBER(O4),IF(SessionLeft<=0,--(ABS(O4)>3),_xlfn.NORM.S.DIST((-3-O4)/SQRT(SessionLeft),TRUE)+1-_xlfn.NORM.S.DIST((3-O4)/SQRT(SessionLeft),TRUE)),"") -> 0 | AD4: SPY BASKET | AE4: Basket | AF4: EQUITY | AG4: =IFERROR(MATCH($AD4,Feed!$A:$A,0),"") -> 559
A5: NVDA | C5: =SUMIFS(Holdings!$D:$D,Holdings!$A:$A,$A$3,Holdings!$B:$B,A5) -> 0.08276795 | D5: =IFERROR(IF(INDEX(Feed!$B:$B,$AG5)="","",INDEX(Feed!$B:$B,$AG5)),"") -> 228.3882 | E5: =IFERROR(IF(INDEX(Feed!$C:$C,$AG5)="","",INDEX(Feed!$C:$C,$AG5)),"") | F5: =IFERROR(IF(INDEX(Feed!$D:$D,$AG5)="","",INDEX(Feed!$D:$D,$AG5)),"") | G5: =IFERROR(IF(INDEX(Feed!$E:$E,$AG5)="","",INDEX(Feed!$E:$E,$AG5)),"") | H5: =IFERROR(IF(INDEX(Feed!$F:$F,$AG5)="","",INDEX(Feed!$F:$F,$AG5)),"") | I5: =IF(AND(N(E5)>0,N(F5)>0),(F5-E5)/((F5+E5)/2)*10000,"") | J5: =IF(N(D5)>0,IFERROR(D5/INDEX(Feed!$G:$G,$AG5)-1,""),"") -> 0.027525982 | K5: =IFERROR(IF(INDEX(Feed!$H:$H,$AG5)="","",INDEX(Feed!$H:$H,$AG5)),"") -> 109980196 | L5: =IFERROR(IF(INDEX(Feed!$I:$I,$AG5)="","",INDEX(Feed!$I:$I,$AG5)),"") | M5: =IF(AND(N(K5)>0,N(L5)>0),K5/L5,"") | N5: =IFERROR(IF(INDEX(Feed!$L:$L,$AG5)="","",INDEX(Feed!$L:$L,$AG5)),"") -> 0.025073562 | O5: =IF(AND(ISNUMBER(J5),N(N5)>0),J5/N5,"") -> 1.097809 | P5: =IF(ISNUMBER(O5),IF(SessionLeft<=0,--(ABS(O5)>1),_xlfn.NORM.S.DIST((-1-O5)/SQRT(SessionLeft),TRUE)+1-_xlfn.NORM.S.DIST((1-O5)/SQRT(SessionLeft),TRUE)),"") -> 1 | Q5: =IF(ISNUMBER(O5),IF(SessionLeft<=0,--(ABS(O5)>2),_xlfn.NORM.S.DIST((-2-O5)/SQRT(SessionLeft),TRUE)+1-_xlfn.NORM.S.DIST((2-O5)/SQRT(SessionLeft),TRUE)),"") -> 0 | R5: =IF(ISNUMBER(O5),IF(SessionLeft<=0,--(ABS(O5)>3),_xlfn.NORM.S.DIST((-3-O5)/SQRT(SessionLeft),TRUE)+1-_xlfn.NORM.S.DIST((3-O5)/SQRT(SessionLeft),TRUE)),"") -> 0 | AB5: =IFERROR(IF(INDEX(Feed!$M:$M,$AG5)="","",INDEX(Feed!$M:$M,$AG5)),"") -> 46287.671 | AD5: NVDA | AE5: Holding | AF5: EQUITY | AG5: =IFERROR(MATCH($AD5,Feed!$A:$A,0),"") -> 373
A6: AAPL | C6: =SUMIFS(Holdings!$D:$D,Holdings!$A:$A,$A$3,Holdings!$B:$B,A6) -> 0.07409622 | D6: =IFERROR(IF(INDEX(Feed!$B:$B,$AG6)="","",INDEX(Feed!$B:$B,$AG6)),"") | E6: =IFERROR(IF(INDEX(Feed!$C:$C,$AG6)="","",INDEX(Feed!$C:$C,$AG6)),"") | F6: =IFERROR(IF(INDEX(Feed!$D:$D,$AG6)="","",INDEX(Feed!$D:$D,$AG6)),"") | G6: =IFERROR(IF(INDEX(Feed!$E:$E,$AG6)="","",INDEX(Feed!$E:$E,$AG6)),"") | H6: =IFERROR(IF(INDEX(Feed!$F:$F,$AG6)="","",INDEX(Feed!$F:$F,$AG6)),"") | I6: =IF(AND(N(E6)>0,N(F6)>0),(F6-E6)/((F6+E6)/2)*10000,"") | J6: =IF(N(D6)>0,IFERROR(D6/INDEX(Feed!$G:$G,$AG6)-1,""),"") | K6: =IFERROR(IF(INDEX(Feed!$H:$H,$AG6)="","",INDEX(Feed!$H:$H,$AG6)),"") | L6: =IFERROR(IF(INDEX(Feed!$I:$I,$AG6)="","",INDEX(Feed!$I:$I,$AG6)),"") | M6: =IF(AND(N(K6)>0,N(L6)>0),K6/L6,"") | N6: =IFERROR(IF(INDEX(Feed!$L:$L,$AG6)="","",INDEX(Feed!$L:$L,$AG6)),"") -> 0.018439339 | O6: =IF(AND(ISNUMBER(J6),N(N6)>0),J6/N6,"") | P6: =IF(ISNUMBER(O6),IF(SessionLeft<=0,--(ABS(O6)>1),_xlfn.NORM.S.DIST((-1-O6)/SQRT(SessionLeft),TRUE)+1-_xlfn.NORM.S.DIST((1-O6)/SQRT(SessionLeft),TRUE)),"") | Q6: =IF(ISNUMBER(O6),IF(SessionLeft<=0,--(ABS(O6)>2),_xlfn.NORM.S.DIST((-2-O6)/SQRT(SessionLeft),TRUE)+1-_xlfn.NORM.S.DIST((2-O6)/SQRT(SessionLeft),TRUE)),"") | R6: =IF(ISNUMBER(O6),IF(SessionLeft<=0,--(ABS(O6)>3),_xlfn.NORM.S.DIST((-3-O6)/SQRT(SessionLeft),TRUE)+1-_xlfn.NORM.S.DIST((3-O6)/SQRT(SessionLeft),TRUE)),"") | AB6: =IFERROR(IF(INDEX(Feed!$M:$M,$AG6)="","",INDEX(Feed!$M:$M,$AG6)),"") | AD6: AAPL | AE6: Holding | AF6: EQUITY | AG6: =IFERROR(MATCH($AD6,Feed!$A:$A,0),"") -> 20
A7: MSFT | C7: =SUMIFS(Holdings!$D:$D,Holdings!$A:$A,$A$3,Holdings!$B:$B,A7) -> 0.05525998 | D7: =IFERROR(IF(INDEX(Feed!$B:$B,$AG7)="","",INDEX(Feed!$B:$B,$AG7)),"") -> 497.8325 | E7: =IFERROR(IF(INDEX(Feed!$C:$C,$AG7)="","",INDEX(Feed!$C:$C,$AG7)),"") | F7: =IFERROR(IF(INDEX(Feed!$D:$D,$AG7)="","",INDEX(Feed!$D:$D,$AG7)),"") | G7: =IFERROR(IF(INDEX(Feed!$E:$E,$AG7)="","",INDEX(Feed!$E:$E,$AG7)),"") | H7: =IFERROR(IF(INDEX(Feed!$F:$F,$AG7)="","",INDEX(Feed!$F:$F,$AG7)),"") | I7: =IF(AND(N(E7)>0,N(F7)>0),(F7-E7)/((F7+E7)/2)*10000,"") | J7: =IF(N(D7)>0,IFERROR(D7/INDEX(Feed!$G:$G,$AG7)-1,""),"") -> -0.007530751 | K7: =IFERROR(IF(INDEX(Feed!$H:$H,$AG7)="","",INDEX(Feed!$H:$H,$AG7)),"") -> 16019410 | L7: =IFERROR(IF(INDEX(Feed!$I:$I,$AG7)="","",INDEX(Feed!$I:$I,$AG7)),"") | M7: =IF(AND(N(K7)>0,N(L7)>0),K7/L7,"") | N7: =IFERROR(IF(INDEX(Feed!$L:$L,$AG7)="","",INDEX(Feed!$L:$L,$AG7)),"") -> 0.026179693 | O7: =IF(AND(ISNUMBER(J7),N(N7)>0),J7/N7,"") -> -0.2876562 | P7: =IF(ISNUMBER(O7),IF(SessionLeft<=0,--(ABS(O7)>1),_xlfn.NORM.S.DIST((-1-O7)/SQRT(SessionLeft),TRUE)+1-_xlfn.NORM.S.DIST((1-O7)/SQRT(SessionLeft),TRUE)),"") -> 0 | Q7: =IF(ISNUMBER(O7),IF(SessionLeft<=0,--(ABS(O7)>2),_xlfn.NORM.S.DIST((-2-O7)/SQRT(SessionLeft),TRUE)+1-_xlfn.NORM.S.DIST((2-O7)/SQRT(SessionLeft),TRUE)),"") -> 0 | R7: =IF(ISNUMBER(O7),IF(SessionLeft<=0,--(ABS(O7)>3),_xlfn.NORM.S.DIST((-3-O7)/SQRT(SessionLeft),TRUE)+1-_xlfn.NORM.S.DIST((3-O7)/SQRT(SessionLeft),TRUE)),"") -> 0 | AB7: =IFERROR(IF(INDEX(Feed!$M:$M,$AG7)="","",INDEX(Feed!$M:$M,$AG7)),"") -> 46287.671 | AD7: MSFT | AE7: Holding | AF7: EQUITY | AG7: =IFERROR(MATCH($AD7,Feed!$A:$A,0),"") -> 351
A8: QQQ | B8: =IF(NOT(ISNUMBER(V8)),"",IF((NOW()-N(AB8))*1440>StaleMin,"STALE",IF(AND($AF8="EQUITY",ABS(N(T8))>ExDivFlag),"EX-DIV?",IF(X8>IF($AF8="FI",EdgeFI,EdgeEq),"SELL ETF / BUY "&UPPER($A$9),IF(Y8>IF($AF8="FI",EdgeFI,EdgeEq),"BUY ETF / SELL "&UPPER($A$9),""))))) -> STALE | C8: =IFERROR(IF(INDEX(Feed!$N:$N,$AG8)="","",INDEX(Feed!$N:$N,$AG8)),"") -> 1 | D8: =IFERROR(IF(INDEX(Feed!$B:$B,$AG8)="","",INDEX(Feed!$B:$B,$AG8)),"") -> 747.45 | E8: =IFERROR(IF(INDEX(Feed!$C:$C,$AG8)="","",INDEX(Feed!$C:$C,$AG8)),"") -> 747.45 | F8: =IFERROR(IF(INDEX(Feed!$D:$D,$AG8)="","",INDEX(Feed!$D:$D,$AG8)),"") -> 747.48 | G8: =IFERROR(IF(INDEX(Feed!$E:$E,$AG8)="","",INDEX(Feed!$E:$E,$AG8)),"") -> 180 | H8: =IFERROR(IF(INDEX(Feed!$F:$F,$AG8)="","",INDEX(Feed!$F:$F,$AG8)),"") -> 100 | I8: =IF(AND(N(E8)>0,N(F8)>0),(F8-E8)/((F8+E8)/2)*10000,"") -> 0.40135659 | J8: =IF(N(D8)>0,IFERROR(D8/INDEX(Feed!$G:$G,$AG8)-1,""),"") -> 0.037118707 | K8: =IFERROR(IF(INDEX(Feed!$H:$H,$AG8)="","",INDEX(Feed!$H:$H,$AG8)),"") -> 46731300 | L8: =IFERROR(IF(INDEX(Feed!$I:$I,$AG8)="","",INDEX(Feed!$I:$I,$AG8)),"") | M8: =IF(AND(N(K8)>0,N(L8)>0),K8/L8,"") | N8: =IFERROR(IF(INDEX(Feed!$L:$L,$AG8)="","",INDEX(Feed!$L:$L,$AG8)),"") -> 0.01324884 | O8: =IF(AND(ISNUMBER(J8),N(N8)>0),J8/N8,"") -> 2.8016571 | P8: =IF(ISNUMBER(O8),IF(SessionLeft<=0,--(ABS(O8)>1),_xlfn.NORM.S.DIST((-1-O8)/SQRT(SessionLeft),TRUE)+1-_xlfn.NORM.S.DIST((1-O8)/SQRT(SessionLeft),TRUE)),"") -> 1 | Q8: =IF(ISNUMBER(O8),IF(SessionLeft<=0,--(ABS(O8)>2),_xlfn.NORM.S.DIST((-2-O8)/SQRT(SessionLeft),TRUE)+1-_xlfn.NORM.S.DIST((2-O8)/SQRT(SessionLeft),TRUE)),"") -> 1 | R8: =IF(ISNUMBER(O8),IF(SessionLeft<=0,--(ABS(O8)>3),_xlfn.NORM.S.DIST((-3-O8)/SQRT(SessionLeft),TRUE)+1-_xlfn.NORM.S.DIST((3-O8)/SQRT(SessionLeft),TRUE)),"") -> 0 | S8: =IFERROR(IF(INDEX(Feed!$J:$J,$AG8)="","",INDEX(Feed!$J:$J,$AG8)),"") -> 721.72 | T8: =IFERROR(IF(N(S8)>0,(INDEX(Feed!$G:$G,$AG8)/S8-1)*10000,""),"") -> -14.152303 | U8: =IFERROR(C8*$J$9,"") -> 0.035298946 | V8: =IF(ISNUMBER(U8),IF(AND(Anchor="NAV",N(S8)>0),S8,INDEX(Feed!$G:$G,$AG8))*(1+U8),"") -> 746.1385 | W8: =IF(ISNUMBER(V8),(IF(AND(N(E8)>0,N(F8)>0),(E8+F8)/2,D8)/V8-1)*10000,"") -> 17.778188 | X8: =IF(ISNUMBER(V8),(IF(N(E8)>0,E8,D8)/V8-1)*10000-IF($AF8="FI",CostFI,CostEq),"") -> 14.577153 | Y8: =IF(ISNUMBER(V8),(1-IF(N(F8)>0,F8,D8)/V8)*10000-IF($AF8="FI",CostFI,CostEq),"") -> -20.979223 | Z8: =IFERROR((J8-U8-INDEX(Feed!$O:$O,$AG8))/INDEX(Feed!$P:$P,$AG8),"") -> 2.0779963 | AA8: =IFERROR(IF(INDEX(Feed!$K:$K,$AG8)="","",INDEX(Feed!$K:$K,$AG8)),"") -> 0.0042 | AB8: =IFERROR(IF(INDEX(Feed!$M:$M,$AG8)="","",INDEX(Feed!$M:$M,$AG8)),"") -> 46287.672 | AD8: QQQ | AE8: ETF | AF8: EQUITY | AG8: =IFERROR(MATCH($AD8,Feed!$A:$A,0),"") -> 3
A9: Basket | C9: =IFERROR(SUMIFS(Holdings!$G:$G,Holdings!$A:$A,$A$8)/SUMIFS(Holdings!$D:$D,Holdings!$A:$A,$A$8),"") -> 0.80563984 | J9: =IFERROR(SUMIFS(Holdings!$F:$F,Holdings!$A:$A,$A$8)/SUMIFS(Holdings!$G:$G,Holdings!$A:$A,$A$8),"") -> 0.035298946 | N9: =IFERROR(IF(INDEX(Feed!$L:$L,$AG9)="","",INDEX(Feed!$L:$L,$AG9)),"") -> 0.01338235 | O9: =IF(AND(ISNUMBER(J9),N(N9)>0),J9/N9,"") -> 2.6377241 | P9: =IF(ISNUMBER(O9),IF(SessionLeft<=0,--(ABS(O9)>1),_xlfn.NORM.S.DIST((-1-O9)/SQRT(SessionLeft),TRUE)+1-_xlfn.NORM.S.DIST((1-O9)/SQRT(SessionLeft),TRUE)),"") -> 1 | Q9: =IF(ISNUMBER(O9),IF(SessionLeft<=0,--(ABS(O9)>2),_xlfn.NORM.S.DIST((-2-O9)/SQRT(SessionLeft),TRUE)+1-_xlfn.NORM.S.DIST((2-O9)/SQRT(SessionLeft),TRUE)),"") -> 1 | R9: =IF(ISNUMBER(O9),IF(SessionLeft<=0,--(ABS(O9)>3),_xlfn.NORM.S.DIST((-3-O9)/SQRT(SessionLeft),TRUE)+1-_xlfn.NORM.S.DIST((3-O9)/SQRT(SessionLeft),TRUE)),"") -> 0 | AD9: QQQ BASKET | AE9: Basket | AF9: EQUITY | AG9: =IFERROR(MATCH($AD9,Feed!$A:$A,0),"") -> 560
A10: NVDA | C10: =SUMIFS(Holdings!$D:$D,Holdings!$A:$A,$A$8,Holdings!$B:$B,A10) -> 0.08277194 | D10: =IFERROR(IF(INDEX(Feed!$B:$B,$AG10)="","",INDEX(Feed!$B:$B,$AG10)),"") -> 228.3882 | E10: =IFERROR(IF(INDEX(Feed!$C:$C,$AG10)="","",INDEX(Feed!$C:$C,$AG10)),"") | F10: =IFERROR(IF(INDEX(Feed!$D:$D,$AG10)="","",INDEX(Feed!$D:$D,$AG10)),"") | G10: =IFERROR(IF(INDEX(Feed!$E:$E,$AG10)="","",INDEX(Feed!$E:$E,$AG10)),"") | H10: =IFERROR(IF(INDEX(Feed!$F:$F,$AG10)="","",INDEX(Feed!$F:$F,$AG10)),"") | I10: =IF(AND(N(E10)>0,N(F10)>0),(F10-E10)/((F10+E10)/2)*10000,"") | J10: =IF(N(D10)>0,IFERROR(D10/INDEX(Feed!$G:$G,$AG10)-1,""),"") -> 0.027525982 | K10: =IFERROR(IF(INDEX(Feed!$H:$H,$AG10)="","",INDEX(Feed!$H:$H,$AG10)),"") -> 109980196 | L10: =IFERROR(IF(INDEX(Feed!$I:$I,$AG10)="","",INDEX(Feed!$I:$I,$AG10)),"") | M10: =IF(AND(N(K10)>0,N(L10)>0),K10/L10,"") | N10: =IFERROR(IF(INDEX(Feed!$L:$L,$AG10)="","",INDEX(Feed!$L:$L,$AG10)),"") -> 0.025073562 | O10: =IF(AND(ISNUMBER(J10),N(N10)>0),J10/N10,"") -> 1.097809 | P10: =IF(ISNUMBER(O10),IF(SessionLeft<=0,--(ABS(O10)>1),_xlfn.NORM.S.DIST((-1-O10)/SQRT(SessionLeft),TRUE)+1-_xlfn.NORM.S.DIST((1-O10)/SQRT(SessionLeft),TRUE)),"") -> 1 | Q10: =IF(ISNUMBER(O10),IF(SessionLeft<=0,--(ABS(O10)>2),_xlfn.NORM.S.DIST((-2-O10)/SQRT(SessionLeft),TRUE)+1-_xlfn.NORM.S.DIST((2-O10)/SQRT(SessionLeft),TRUE)),"") -> 0 | R10: =IF(ISNUMBER(O10),IF(SessionLeft<=0,--(ABS(O10)>3),_xlfn.NORM.S.DIST((-3-O10)/SQRT(SessionLeft),TRUE)+1-_xlfn.NORM.S.DIST((3-O10)/SQRT(SessionLeft),TRUE)),"") -> 0 | AB10: =IFERROR(IF(INDEX(Feed!$M:$M,$AG10)="","",INDEX(Feed!$M:$M,$AG10)),"") -> 46287.671 | AD10: NVDA | AE10: Holding | AF10: EQUITY | AG10: =IFERROR(MATCH($AD10,Feed!$A:$A,0),"") -> 373
A11: AAPL | C11: =SUMIFS(Holdings!$D:$D,Holdings!$A:$A,$A$8,Holdings!$B:$B,A11) -> 0.07432348 | D11: =IFERROR(IF(INDEX(Feed!$B:$B,$AG11)="","",INDEX(Feed!$B:$B,$AG11)),"") | E11: =IFERROR(IF(INDEX(Feed!$C:$C,$AG11)="","",INDEX(Feed!$C:$C,$AG11)),"") | F11: =IFERROR(IF(INDEX(Feed!$D:$D,$AG11)="","",INDEX(Feed!$D:$D,$AG11)),"") | G11: =IFERROR(IF(INDEX(Feed!$E:$E,$AG11)="","",INDEX(Feed!$E:$E,$AG11)),"") | H11: =IFERROR(IF(INDEX(Feed!$F:$F,$AG11)="","",INDEX(Feed!$F:$F,$AG11)),"") | I11: =IF(AND(N(E11)>0,N(F11)>0),(F11-E11)/((F11+E11)/2)*10000,"") | J11: =IF(N(D11)>0,IFERROR(D11/INDEX(Feed!$G:$G,$AG11)-1,""),"") | K11: =IFERROR(IF(INDEX(Feed!$H:$H,$AG11)="","",INDEX(Feed!$H:$H,$AG11)),"") | L11: =IFERROR(IF(INDEX(Feed!$I:$I,$AG11)="","",INDEX(Feed!$I:$I,$AG11)),"") | M11: =IF(AND(N(K11)>0,N(L11)>0),K11/L11,"") | N11: =IFERROR(IF(INDEX(Feed!$L:$L,$AG11)="","",INDEX(Feed!$L:$L,$AG11)),"") -> 0.018439339 | O11: =IF(AND(ISNUMBER(J11),N(N11)>0),J11/N11,"") | P11: =IF(ISNUMBER(O11),IF(SessionLeft<=0,--(ABS(O11)>1),_xlfn.NORM.S.DIST((-1-O11)/SQRT(SessionLeft),TRUE)+1-_xlfn.NORM.S.DIST((1-O11)/SQRT(SessionLeft),TRUE)),"") | Q11: =IF(ISNUMBER(O11),IF(SessionLeft<=0,--(ABS(O11)>2),_xlfn.NORM.S.DIST((-2-O11)/SQRT(SessionLeft),TRUE)+1-_xlfn.NORM.S.DIST((2-O11)/SQRT(SessionLeft),TRUE)),"") | R11: =IF(ISNUMBER(O11),IF(SessionLeft<=0,--(ABS(O11)>3),_xlfn.NORM.S.DIST((-3-O11)/SQRT(SessionLeft),TRUE)+1-_xlfn.NORM.S.DIST((3-O11)/SQRT(SessionLeft),TRUE)),"") | AB11: =IFERROR(IF(INDEX(Feed!$M:$M,$AG11)="","",INDEX(Feed!$M:$M,$AG11)),"") | AD11: AAPL | AE11: Holding | AF11: EQUITY | AG11: =IFERROR(MATCH($AD11,Feed!$A:$A,0),"") -> 20
A12: MSFT | C12: =SUMIFS(Holdings!$D:$D,Holdings!$A:$A,$A$8,Holdings!$B:$B,A12) -> 0.05542997 | D12: =IFERROR(IF(INDEX(Feed!$B:$B,$AG12)="","",INDEX(Feed!$B:$B,$AG12)),"") -> 497.8325 | E12: =IFERROR(IF(INDEX(Feed!$C:$C,$AG12)="","",INDEX(Feed!$C:$C,$AG12)),"") | F12: =IFERROR(IF(INDEX(Feed!$D:$D,$AG12)="","",INDEX(Feed!$D:$D,$AG12)),"") | G12: =IFERROR(IF(INDEX(Feed!$E:$E,$AG12)="","",INDEX(Feed!$E:$E,$AG12)),"") | H12: =IFERROR(IF(INDEX(Feed!$F:$F,$AG12)="","",INDEX(Feed!$F:$F,$AG12)),"") | I12: =IF(AND(N(E12)>0,N(F12)>0),(F12-E12)/((F12+E12)/2)*10000,"") | J12: =IF(N(D12)>0,IFERROR(D12/INDEX(Feed!$G:$G,$AG12)-1,""),"") -> -0.007530751 | K12: =IFERROR(IF(INDEX(Feed!$H:$H,$AG12)="","",INDEX(Feed!$H:$H,$AG12)),"") -> 16019410 | L12: =IFERROR(IF(INDEX(Feed!$I:$I,$AG12)="","",INDEX(Feed!$I:$I,$AG12)),"") | M12: =IF(AND(N(K12)>0,N(L12)>0),K12/L12,"") | N12: =IFERROR(IF(INDEX(Feed!$L:$L,$AG12)="","",INDEX(Feed!$L:$L,$AG12)),"") -> 0.026179693 | O12: =IF(AND(ISNUMBER(J12),N(N12)>0),J12/N12,"") -> -0.2876562 | P12: =IF(ISNUMBER(O12),IF(SessionLeft<=0,--(ABS(O12)>1),_xlfn.NORM.S.DIST((-1-O12)/SQRT(SessionLeft),TRUE)+1-_xlfn.NORM.S.DIST((1-O12)/SQRT(SessionLeft),TRUE)),"") -> 0 | Q12: =IF(ISNUMBER(O12),IF(SessionLeft<=0,--(ABS(O12)>2),_xlfn.NORM.S.DIST((-2-O12)/SQRT(SessionLeft),TRUE)+1-_xlfn.NORM.S.DIST((2-O12)/SQRT(SessionLeft),TRUE)),"") -> 0 | R12: =IF(ISNUMBER(O12),IF(SessionLeft<=0,--(ABS(O12)>3),_xlfn.NORM.S.DIST((-3-O12)/SQRT(SessionLeft),TRUE)+1-_xlfn.NORM.S.DIST((3-O12)/SQRT(SessionLeft),TRUE)),"") -> 0 | AB12: =IFERROR(IF(INDEX(Feed!$M:$M,$AG12)="","",INDEX(Feed!$M:$M,$AG12)),"") -> 46287.671 | AD12: MSFT | AE12: Holding | AF12: EQUITY | AG12: =IFERROR(MATCH($AD12,Feed!$A:$A,0),"") -> 351
A13: XLK | B13: =IF(NOT(ISNUMBER(V13)),"",IF((NOW()-N(AB13))*1440>StaleMin,"STALE",IF(AND($AF13="EQUITY",ABS(N(T13))>ExDivFlag),"EX-DIV?",IF(X13>IF($AF13="FI",EdgeFI,EdgeEq),"SELL ETF / BUY "&UPPER($A$14),IF(Y13>IF($AF13="FI",EdgeFI,EdgeEq),"BUY ETF / SELL "&UPPER($A$14),""))))) -> STALE | C13: =IFERROR(IF(INDEX(Feed!$N:$N,$AG13)="","",INDEX(Feed!$N:$N,$AG13)),"") -> 1 | D13: =IFERROR(IF(INDEX(Feed!$B:$B,$AG13)="","",INDEX(Feed!$B:$B,$AG13)),"") -> 196.229 | E13: =IFERROR(IF(INDEX(Feed!$C:$C,$AG13)="","",INDEX(Feed!$C:$C,$AG13)),"") -> 195.6 | F13: =IFERROR(IF(INDEX(Feed!$D:$D,$AG13)="","",INDEX(Feed!$D:$D,$AG13)),"") -> 196.24 | G13: =IFERROR(IF(INDEX(Feed!$E:$E,$AG13)="","",INDEX(Feed!$E:$E,$AG13)),"") -> 400 | H13: =IFERROR(IF(INDEX(Feed!$F:$F,$AG13)="","",INDEX(Feed!$F:$F,$AG13)),"") -> 100 | I13: =IF(AND(N(E13)>0,N(F13)>0),(F13-E13)/((F13+E13)/2)*10000,"") -> 32.666394 | J13: =IF(N(D13)>0,IFERROR(D13/INDEX(Feed!$G:$G,$AG13)-1,""),"") -> 0.03496308 | K13: =IFERROR(IF(INDEX(Feed!$H:$H,$AG13)="","",INDEX(Feed!$H:$H,$AG13)),"") -> 9047360 | L13: =IFERROR(IF(INDEX(Feed!$I:$I,$AG13)="","",INDEX(Feed!$I:$I,$AG13)),"") | M13: =IF(AND(N(K13)>0,N(L13)>0),K13/L13,"") | N13: =IFERROR(IF(INDEX(Feed!$L:$L,$AG13)="","",INDEX(Feed!$L:$L,$AG13)),"") -> 0.018249068 | O13: =IF(AND(ISNUMBER(J13),N(N13)>0),J13/N13,"") -> 1.9158831 | P13: =IF(ISNUMBER(O13),IF(SessionLeft<=0,--(ABS(O13)>1),_xlfn.NORM.S.DIST((-1-O13)/SQRT(SessionLeft),TRUE)+1-_xlfn.NORM.S.DIST((1-O13)/SQRT(SessionLeft),TRUE)),"") -> 1 | Q13: =IF(ISNUMBER(O13),IF(SessionLeft<=0,--(ABS(O13)>2),_xlfn.NORM.S.DIST((-2-O13)/SQRT(SessionLeft),TRUE)+1-_xlfn.NORM.S.DIST((2-O13)/SQRT(SessionLeft),TRUE)),"") -> 0 | R13: =IF(ISNUMBER(O13),IF(SessionLeft<=0,--(ABS(O13)>3),_xlfn.NORM.S.DIST((-3-O13)/SQRT(SessionLeft),TRUE)+1-_xlfn.NORM.S.DIST((3-O13)/SQRT(SessionLeft),TRUE)),"") -> 0 | S13: =IFERROR(IF(INDEX(Feed!$J:$J,$AG13)="","",INDEX(Feed!$J:$J,$AG13)),"") -> 189.69778 | T13: =IFERROR(IF(N(S13)>0,(INDEX(Feed!$G:$G,$AG13)/S13-1)*10000,""),"") -> -5.1545147 | U13: =IFERROR(C13*$J$14,"") -> 0.031931105 | V13: =IF(ISNUMBER(U13),IF(AND(Anchor="NAV",N(S13)>0),S13,INDEX(Feed!$G:$G,$AG13))*(1+U13),"") -> 195.65414 | W13: =IF(ISNUMBER(V13),(IF(AND(N(E13)>0,N(F13)>0),(E13+F13)/2,D13)/V13-1)*10000,"") -> 13.588395 | X13: =IF(ISNUMBER(V13),(IF(N(E13)>0,E13,D13)/V13-1)*10000-IF($AF13="FI",CostFI,CostEq),"") -> -5.7669969 | Y13: =IF(ISNUMBER(V13),(1-IF(N(F13)>0,F13,D13)/V13)*10000-IF($AF13="FI",CostFI,CostEq),"") -> -32.943786 | Z13: =IFERROR((J13-U13-INDEX(Feed!$O:$O,$AG13))/INDEX(Feed!$P:$P,$AG13),"") -> 3.8391935 | AA13: =IFERROR(IF(INDEX(Feed!$K:$K,$AG13)="","",INDEX(Feed!$K:$K,$AG13)),"") -> 0.0043 | AB13: =IFERROR(IF(INDEX(Feed!$M:$M,$AG13)="","",INDEX(Feed!$M:$M,$AG13)),"") -> 46287.673 | AD13: XLK | AE13: ETF | AF13: EQUITY | AG13: =IFERROR(MATCH($AD13,Feed!$A:$A,0),"") -> 4
A14: Basket | C14: =IFERROR(SUMIFS(Holdings!$G:$G,Holdings!$A:$A,$A$13)/SUMIFS(Holdings!$D:$D,Holdings!$A:$A,$A$13),"") -> 0.79367953 | J14: =IFERROR(SUMIFS(Holdings!$F:$F,Holdings!$A:$A,$A$13)/SUMIFS(Holdings!$G:$G,Holdings!$A:$A,$A$13),"") -> 0.031931105 | N14: =IFERROR(IF(INDEX(Feed!$L:$L,$AG14)="","",INDEX(Feed!$L:$L,$AG14)),"") -> 0.017895276 | O14: =IF(AND(ISNUMBER(J14),N(N14)>0),J14/N14,"") -> 1.7843315 | P14: =IF(ISNUMBER(O14),IF(SessionLeft<=0,--(ABS(O14)>1),_xlfn.NORM.S.DIST((-1-O14)/SQRT(SessionLeft),TRUE)+1-_xlfn.NORM.S.DIST((1-O14)/SQRT(SessionLeft),TRUE)),"") -> 1 | Q14: =IF(ISNUMBER(O14),IF(SessionLeft<=0,--(ABS(O14)>2),_xlfn.NORM.S.DIST((-2-O14)/SQRT(SessionLeft),TRUE)+1-_xlfn.NORM.S.DIST((2-O14)/SQRT(SessionLeft),TRUE)),"") -> 0 | R14: =IF(ISNUMBER(O14),IF(SessionLeft<=0,--(ABS(O14)>3),_xlfn.NORM.S.DIST((-3-O14)/SQRT(SessionLeft),TRUE)+1-_xlfn.NORM.S.DIST((3-O14)/SQRT(SessionLeft),TRUE)),"") -> 0 | AD14: XLK BASKET | AE14: Basket | AF14: EQUITY | AG14: =IFERROR(MATCH($AD14,Feed!$A:$A,0),"") -> 561
A15: NVDA | C15: =SUMIFS(Holdings!$D:$D,Holdings!$A:$A,$A$13,Holdings!$B:$B,A15) -> 0.15457152 | D15: =IFERROR(IF(INDEX(Feed!$B:$B,$AG15)="","",INDEX(Feed!$B:$B,$AG15)),"") -> 228.3882 | E15: =IFERROR(IF(INDEX(Feed!$C:$C,$AG15)="","",INDEX(Feed!$C:$C,$AG15)),"") | F15: =IFERROR(IF(INDEX(Feed!$D:$D,$AG15)="","",INDEX(Feed!$D:$D,$AG15)),"") | G15: =IFERROR(IF(INDEX(Feed!$E:$E,$AG15)="","",INDEX(Feed!$E:$E,$AG15)),"") | H15: =IFERROR(IF(INDEX(Feed!$F:$F,$AG15)="","",INDEX(Feed!$F:$F,$AG15)),"") | I15: =IF(AND(N(E15)>0,N(F15)>0),(F15-E15)/((F15+E15)/2)*10000,"") | J15: =IF(N(D15)>0,IFERROR(D15/INDEX(Feed!$G:$G,$AG15)-1,""),"") -> 0.027525982 | K15: =IFERROR(IF(INDEX(Feed!$H:$H,$AG15)="","",INDEX(Feed!$H:$H,$AG15)),"") -> 109980196 | L15: =IFERROR(IF(INDEX(Feed!$I:$I,$AG15)="","",INDEX(Feed!$I:$I,$AG15)),"") | M15: =IF(AND(N(K15)>0,N(L15)>0),K15/L15,"") | N15: =IFERROR(IF(INDEX(Feed!$L:$L,$AG15)="","",INDEX(Feed!$L:$L,$AG15)),"") -> 0.025073562 | O15: =IF(AND(ISNUMBER(J15),N(N15)>0),J15/N15,"") -> 1.097809 | P15: =IF(ISNUMBER(O15),IF(SessionLeft<=0,--(ABS(O15)>1),_xlfn.NORM.S.DIST((-1-O15)/SQRT(SessionLeft),TRUE)+1-_xlfn.NORM.S.DIST((1-O15)/SQRT(SessionLeft),TRUE)),"") -> 1 | Q15: =IF(ISNUMBER(O15),IF(SessionLeft<=0,--(ABS(O15)>2),_xlfn.NORM.S.DIST((-2-O15)/SQRT(SessionLeft),TRUE)+1-_xlfn.NORM.S.DIST((2-O15)/SQRT(SessionLeft),TRUE)),"") -> 0 | R15: =IF(ISNUMBER(O15),IF(SessionLeft<=0,--(ABS(O15)>3),_xlfn.NORM.S.DIST((-3-O15)/SQRT(SessionLeft),TRUE)+1-_xlfn.NORM.S.DIST((3-O15)/SQRT(SessionLeft),TRUE)),"") -> 0 | AB15: =IFERROR(IF(INDEX(Feed!$M:$M,$AG15)="","",INDEX(Feed!$M:$M,$AG15)),"") -> 46287.671 | AD15: NVDA | AE15: Holding | AF15: EQUITY | AG15: =IFERROR(MATCH($AD15,Feed!$A:$A,0),"") -> 373
A16: AAPL | C16: =SUMIFS(Holdings!$D:$D,Holdings!$A:$A,$A$13,Holdings!$B:$B,A16) -> 0.13837713 | D16: =IFERROR(IF(INDEX(Feed!$B:$B,$AG16)="","",INDEX(Feed!$B:$B,$AG16)),"") | E16: =IFERROR(IF(INDEX(Feed!$C:$C,$AG16)="","",INDEX(Feed!$C:$C,$AG16)),"") | F16: =IFERROR(IF(INDEX(Feed!$D:$D,$AG16)="","",INDEX(Feed!$D:$D,$AG16)),"") | G16: =IFERROR(IF(INDEX(Feed!$E:$E,$AG16)="","",INDEX(Feed!$E:$E,$AG16)),"") | H16: =IFERROR(IF(INDEX(Feed!$F:$F,$AG16)="","",INDEX(Feed!$F:$F,$AG16)),"") | I16: =IF(AND(N(E16)>0,N(F16)>0),(F16-E16)/((F16+E16)/2)*10000,"") | J16: =IF(N(D16)>0,IFERROR(D16/INDEX(Feed!$G:$G,$AG16)-1,""),"") | K16: =IFERROR(IF(INDEX(Feed!$H:$H,$AG16)="","",INDEX(Feed!$H:$H,$AG16)),"") | L16: =IFERROR(IF(INDEX(Feed!$I:$I,$AG16)="","",INDEX(Feed!$I:$I,$AG16)),"") | M16: =IF(AND(N(K16)>0,N(L16)>0),K16/L16,"") | N16: =IFERROR(IF(INDEX(Feed!$L:$L,$AG16)="","",INDEX(Feed!$L:$L,$AG16)),"") -> 0.018439339 | O16: =IF(AND(ISNUMBER(J16),N(N16)>0),J16/N16,"") | P16: =IF(ISNUMBER(O16),IF(SessionLeft<=0,--(ABS(O16)>1),_xlfn.NORM.S.DIST((-1-O16)/SQRT(SessionLeft),TRUE)+1-_xlfn.NORM.S.DIST((1-O16)/SQRT(SessionLeft),TRUE)),"") | Q16: =IF(ISNUMBER(O16),IF(SessionLeft<=0,--(ABS(O16)>2),_xlfn.NORM.S.DIST((-2-O16)/SQRT(SessionLeft),TRUE)+1-_xlfn.NORM.S.DIST((2-O16)/SQRT(SessionLeft),TRUE)),"") | R16: =IF(ISNUMBER(O16),IF(SessionLeft<=0,--(ABS(O16)>3),_xlfn.NORM.S.DIST((-3-O16)/SQRT(SessionLeft),TRUE)+1-_xlfn.NORM.S.DIST((3-O16)/SQRT(SessionLeft),TRUE)),"") | AB16: =IFERROR(IF(INDEX(Feed!$M:$M,$AG16)="","",INDEX(Feed!$M:$M,$AG16)),"") | AD16: AAPL | AE16: Holding | AF16: EQUITY | AG16: =IFERROR(MATCH($AD16,Feed!$A:$A,0),"") -> 20
A17: MSFT | C17: =SUMIFS(Holdings!$D:$D,Holdings!$A:$A,$A$13,Holdings!$B:$B,A17) -> 0.10320077 | D17: =IFERROR(IF(INDEX(Feed!$B:$B,$AG17)="","",INDEX(Feed!$B:$B,$AG17)),"") -> 497.8325 | E17: =IFERROR(IF(INDEX(Feed!$C:$C,$AG17)="","",INDEX(Feed!$C:$C,$AG17)),"") | F17: =IFERROR(IF(INDEX(Feed!$D:$D,$AG17)="","",INDEX(Feed!$D:$D,$AG17)),"") | G17: =IFERROR(IF(INDEX(Feed!$E:$E,$AG17)="","",INDEX(Feed!$E:$E,$AG17)),"") | H17: =IFERROR(IF(INDEX(Feed!$F:$F,$AG17)="","",INDEX(Feed!$F:$F,$AG17)),"") | I17: =IF(AND(N(E17)>0,N(F17)>0),(F17-E17)/((F17+E17)/2)*10000,"") | J17: =IF(N(D17)>0,IFERROR(D17/INDEX(Feed!$G:$G,$AG17)-1,""),"") -> -0.007530751 | K17: =IFERROR(IF(INDEX(Feed!$H:$H,$AG17)="","",INDEX(Feed!$H:$H,$AG17)),"") -> 16019410 | L17: =IFERROR(IF(INDEX(Feed!$I:$I,$AG17)="","",INDEX(Feed!$I:$I,$AG17)),"") | M17: =IF(AND(N(K17)>0,N(L17)>0),K17/L17,"") | N17: =IFERROR(IF(INDEX(Feed!$L:$L,$AG17)="","",INDEX(Feed!$L:$L,$AG17)),"") -> 0.026179693 | O17: =IF(AND(ISNUMBER(J17),N(N17)>0),J17/N17,"") -> -0.2876562 | P17: =IF(ISNUMBER(O17),IF(SessionLeft<=0,--(ABS(O17)>1),_xlfn.NORM.S.DIST((-1-O17)/SQRT(SessionLeft),TRUE)+1-_xlfn.NORM.S.DIST((1-O17)/SQRT(SessionLeft),TRUE)),"") -> 0 | Q17: =IF(ISNUMBER(O17),IF(SessionLeft<=0,--(ABS(O17)>2),_xlfn.NORM.S.DIST((-2-O17)/SQRT(SessionLeft),TRUE)+1-_xlfn.NORM.S.DIST((2-O17)/SQRT(SessionLeft),TRUE)),"") -> 0 | R17: =IF(ISNUMBER(O17),IF(SessionLeft<=0,--(ABS(O17)>3),_xlfn.NORM.S.DIST((-3-O17)/SQRT(SessionLeft),TRUE)+1-_xlfn.NORM.S.DIST((3-O17)/SQRT(SessionLeft),TRUE)),"") -> 0 | AB17: =IFERROR(IF(INDEX(Feed!$M:$M,$AG17)="","",INDEX(Feed!$M:$M,$AG17)),"") -> 46287.671 | AD17: MSFT | AE17: Holding | AF17: EQUITY | AG17: =IFERROR(MATCH($AD17,Feed!$A:$A,0),"") -> 351
A18: XLF | B18: =IF(NOT(ISNUMBER(V18)),"",IF((NOW()-N(AB18))*1440>StaleMin,"STALE",IF(AND($AF18="EQUITY",ABS(N(T18))>ExDivFlag),"EX-DIV?",IF(X18>IF($AF18="FI",EdgeFI,EdgeEq),"SELL ETF / BUY "&UPPER($A$19),IF(Y18>IF($AF18="FI",EdgeFI,EdgeEq),"BUY ETF / SELL "&UPPER($A$19),""))))) -> STALE | C18: =IFERROR(IF(INDEX(Feed!$N:$N,$AG18)="","",INDEX(Feed!$N:$N,$AG18)),"") -> 1 | D18: =IFERROR(IF(INDEX(Feed!$B:$B,$AG18)="","",INDEX(Feed!$B:$B,$AG18)),"") -> 54.8 | E18: =IFERROR(IF(INDEX(Feed!$C:$C,$AG18)="","",INDEX(Feed!$C:$C,$AG18)),"") | F18: =IFERROR(IF(INDEX(Feed!$D:$D,$AG18)="","",INDEX(Feed!$D:$D,$AG18)),"") | G18: =IFERROR(IF(INDEX(Feed!$E:$E,$AG18)="","",INDEX(Feed!$E:$E,$AG18)),"") | H18: =IFERROR(IF(INDEX(Feed!$F:$F,$AG18)="","",INDEX(Feed!$F:$F,$AG18)),"") | I18: =IF(AND(N(E18)>0,N(F18)>0),(F18-E18)/((F18+E18)/2)*10000,"") | J18: =IF(N(D18)>0,IFERROR(D18/INDEX(Feed!$G:$G,$AG18)-1,""),"") -> -0.018976011 | K18: =IFERROR(IF(INDEX(Feed!$H:$H,$AG18)="","",INDEX(Feed!$H:$H,$AG18)),"") -> 30640768 | L18: =IFERROR(IF(INDEX(Feed!$I:$I,$AG18)="","",INDEX(Feed!$I:$I,$AG18)),"") | M18: =IF(AND(N(K18)>0,N(L18)>0),K18/L18,"") | N18: =IFERROR(IF(INDEX(Feed!$L:$L,$AG18)="","",INDEX(Feed!$L:$L,$AG18)),"") -> 0.00816815 | O18: =IF(AND(ISNUMBER(J18),N(N18)>0),J18/N18,"") -> -2.3231713 | P18: =IF(ISNUMBER(O18),IF(SessionLeft<=0,--(ABS(O18)>1),_xlfn.NORM.S.DIST((-1-O18)/SQRT(SessionLeft),TRUE)+1-_xlfn.NORM.S.DIST((1-O18)/SQRT(SessionLeft),TRUE)),"") -> 1 | Q18: =IF(ISNUMBER(O18),IF(SessionLeft<=0,--(ABS(O18)>2),_xlfn.NORM.S.DIST((-2-O18)/SQRT(SessionLeft),TRUE)+1-_xlfn.NORM.S.DIST((2-O18)/SQRT(SessionLeft),TRUE)),"") -> 1 | R18: =IF(ISNUMBER(O18),IF(SessionLeft<=0,--(ABS(O18)>3),_xlfn.NORM.S.DIST((-3-O18)/SQRT(SessionLeft),TRUE)+1-_xlfn.NORM.S.DIST((3-O18)/SQRT(SessionLeft),TRUE)),"") -> 0 | S18: =IFERROR(IF(INDEX(Feed!$J:$J,$AG18)="","",INDEX(Feed!$J:$J,$AG18)),"") -> 55.90363 | T18: =IFERROR(IF(N(S18)>0,(INDEX(Feed!$G:$G,$AG18)/S18-1)*10000,""),"") -> -7.8045021 | U18: =IFERROR(C18*$J$19,"") -> -0.01540494 | V18: =IF(ISNUMBER(U18),IF(AND(Anchor="NAV",N(S18)>0),S18,INDEX(Feed!$G:$G,$AG18))*(1+U18),"") -> 54.99948 | W18: =IF(ISNUMBER(V18),(IF(AND(N(E18)>0,N(F18)>0),(E18+F18)/2,D18)/V18-1)*10000,"") -> -36.269447 | X18: =IF(ISNUMBER(V18),(IF(N(E18)>0,E18,D18)/V18-1)*10000-IF($AF18="FI",CostFI,CostEq),"") -> -39.269447 | Y18: =IF(ISNUMBER(V18),(1-IF(N(F18)>0,F18,D18)/V18)*10000-IF($AF18="FI",CostFI,CostEq),"") -> 33.269447 | Z18: =IFERROR((J18-U18-INDEX(Feed!$O:$O,$AG18))/INDEX(Feed!$P:$P,$AG18),"") -> -7.0802113 | AA18: =IFERROR(IF(INDEX(Feed!$K:$K,$AG18)="","",INDEX(Feed!$K:$K,$AG18)),"") -> 0.014 | AB18: =IFERROR(IF(INDEX(Feed!$M:$M,$AG18)="","",INDEX(Feed!$M:$M,$AG18)),"") -> 46287.671 | AD18: XLF | AE18: ETF | AF18: EQUITY | AG18: =IFERROR(MATCH($AD18,Feed!$A:$A,0),"") -> 5
A19: Basket | C19: =IFERROR(SUMIFS(Holdings!$G:$G,Holdings!$A:$A,$A$18)/SUMIFS(Holdings!$D:$D,Holdings!$A:$A,$A$18),"") -> 0.82881439 | J19: =IFERROR(SUMIFS(Holdings!$F:$F,Holdings!$A:$A,$A$18)/SUMIFS(Holdings!$G:$G,Holdings!$A:$A,$A$18),"") -> -0.01540494 | N19: =IFERROR(IF(INDEX(Feed!$L:$L,$AG19)="","",INDEX(Feed!$L:$L,$AG19)),"") -> 0.0081074333 | O19: =IF(AND(ISNUMBER(J19),N(N19)>0),J19/N19,"") -> -1.9001007 | P19: =IF(ISNUMBER(O19),IF(SessionLeft<=0,--(ABS(O19)>1),_xlfn.NORM.S.DIST((-1-O19)/SQRT(SessionLeft),TRUE)+1-_xlfn.NORM.S.DIST((1-O19)/SQRT(SessionLeft),TRUE)),"") -> 1 | Q19: =IF(ISNUMBER(O19),IF(SessionLeft<=0,--(ABS(O19)>2),_xlfn.NORM.S.DIST((-2-O19)/SQRT(SessionLeft),TRUE)+1-_xlfn.NORM.S.DIST((2-O19)/SQRT(SessionLeft),TRUE)),"") -> 0 | R19: =IF(ISNUMBER(O19),IF(SessionLeft<=0,--(ABS(O19)>3),_xlfn.NORM.S.DIST((-3-O19)/SQRT(SessionLeft),TRUE)+1-_xlfn.NORM.S.DIST((3-O19)/SQRT(SessionLeft),TRUE)),"") -> 0 | AD19: XLF BASKET | AE19: Basket | AF19: EQUITY | AG19: =IFERROR(MATCH($AD19,Feed!$A:$A,0),"") -> 562
A20: JPM | C20: =SUMIFS(Holdings!$D:$D,Holdings!$A:$A,$A$18,Holdings!$B:$B,A20) -> 0.11694535 | D20: =IFERROR(IF(INDEX(Feed!$B:$B,$AG20)="","",INDEX(Feed!$B:$B,$AG20)),"") -> 340.19 | E20: =IFERROR(IF(INDEX(Feed!$C:$C,$AG20)="","",INDEX(Feed!$C:$C,$AG20)),"") | F20: =IFERROR(IF(INDEX(Feed!$D:$D,$AG20)="","",INDEX(Feed!$D:$D,$AG20)),"") | G20: =IFERROR(IF(INDEX(Feed!$E:$E,$AG20)="","",INDEX(Feed!$E:$E,$AG20)),"") | H20: =IFERROR(IF(INDEX(Feed!$F:$F,$AG20)="","",INDEX(Feed!$F:$F,$AG20)),"") | I20: =IF(AND(N(E20)>0,N(F20)>0),(F20-E20)/((F20+E20)/2)*10000,"") | J20: =IF(N(D20)>0,IFERROR(D20/INDEX(Feed!$G:$G,$AG20)-1,""),"") -> -0.027111276 | K20: =IFERROR(IF(INDEX(Feed!$H:$H,$AG20)="","",INDEX(Feed!$H:$H,$AG20)),"") -> 6414696 | L20: =IFERROR(IF(INDEX(Feed!$I:$I,$AG20)="","",INDEX(Feed!$I:$I,$AG20)),"") | M20: =IF(AND(N(K20)>0,N(L20)>0),K20/L20,"") | N20: =IFERROR(IF(INDEX(Feed!$L:$L,$AG20)="","",INDEX(Feed!$L:$L,$AG20)),"") -> 0.011337588 | O20: =IF(AND(ISNUMBER(J20),N(N20)>0),J20/N20,"") -> -2.3912738 | P20: =IF(ISNUMBER(O20),IF(SessionLeft<=0,--(ABS(O20)>1),_xlfn.NORM.S.DIST((-1-O20)/SQRT(SessionLeft),TRUE)+1-_xlfn.NORM.S.DIST((1-O20)/SQRT(SessionLeft),TRUE)),"") -> 1 | Q20: =IF(ISNUMBER(O20),IF(SessionLeft<=0,--(ABS(O20)>2),_xlfn.NORM.S.DIST((-2-O20)/SQRT(SessionLeft),TRUE)+1-_xlfn.NORM.S.DIST((2-O20)/SQRT(SessionLeft),TRUE)),"") -> 1 | R20: =IF(ISNUMBER(O20),IF(SessionLeft<=0,--(ABS(O20)>3),_xlfn.NORM.S.DIST((-3-O20)/SQRT(SessionLeft),TRUE)+1-_xlfn.NORM.S.DIST((3-O20)/SQRT(SessionLeft),TRUE)),"") -> 0 | AB20: =IFERROR(IF(INDEX(Feed!$M:$M,$AG20)="","",INDEX(Feed!$M:$M,$AG20)),"") -> 46287.671 | AD20: JPM | AE20: Holding | AF20: EQUITY | AG20: =IFERROR(MATCH($AD20,Feed!$A:$A,0),"") -> 292
A21: BRK-B | C21: =SUMIFS(Holdings!$D:$D,Holdings!$A:$A,$A$18,Holdings!$B:$B,A21) -> 0.12133901 | D21: =IFERROR(IF(INDEX(Feed!$B:$B,$AG21)="","",INDEX(Feed!$B:$B,$AG21)),"") -> 503.57 | E21: =IFERROR(IF(INDEX(Feed!$C:$C,$AG21)="","",INDEX(Feed!$C:$C,$AG21)),"") | F21: =IFERROR(IF(INDEX(Feed!$D:$D,$AG21)="","",INDEX(Feed!$D:$D,$AG21)),"") | G21: =IFERROR(IF(INDEX(Feed!$E:$E,$AG21)="","",INDEX(Feed!$E:$E,$AG21)),"") | H21: =IFERROR(IF(INDEX(Feed!$F:$F,$AG21)="","",INDEX(Feed!$F:$F,$AG21)),"") | I21: =IF(AND(N(E21)>0,N(F21)>0),(F21-E21)/((F21+E21)/2)*10000,"") | J21: =IF(N(D21)>0,IFERROR(D21/INDEX(Feed!$G:$G,$AG21)-1,""),"") -> -0.012162348 | K21: =IFERROR(IF(INDEX(Feed!$H:$H,$AG21)="","",INDEX(Feed!$H:$H,$AG21)),"") -> 4807459 | L21: =IFERROR(IF(INDEX(Feed!$I:$I,$AG21)="","",INDEX(Feed!$I:$I,$AG21)),"") | M21: =IF(AND(N(K21)>0,N(L21)>0),K21/L21,"") | N21: =IFERROR(IF(INDEX(Feed!$L:$L,$AG21)="","",INDEX(Feed!$L:$L,$AG21)),"") -> 0.0096126656 | O21: =IF(AND(ISNUMBER(J21),N(N21)>0),J21/N21,"") -> -1.265242 | P21: =IF(ISNUMBER(O21),IF(SessionLeft<=0,--(ABS(O21)>1),_xlfn.NORM.S.DIST((-1-O21)/SQRT(SessionLeft),TRUE)+1-_xlfn.NORM.S.DIST((1-O21)/SQRT(SessionLeft),TRUE)),"") -> 1 | Q21: =IF(ISNUMBER(O21),IF(SessionLeft<=0,--(ABS(O21)>2),_xlfn.NORM.S.DIST((-2-O21)/SQRT(SessionLeft),TRUE)+1-_xlfn.NORM.S.DIST((2-O21)/SQRT(SessionLeft),TRUE)),"") -> 0 | R21: =IF(ISNUMBER(O21),IF(SessionLeft<=0,--(ABS(O21)>3),_xlfn.NORM.S.DIST((-3-O21)/SQRT(SessionLeft),TRUE)+1-_xlfn.NORM.S.DIST((3-O21)/SQRT(SessionLeft),TRUE)),"") -> 0 | AB21: =IFERROR(IF(INDEX(Feed!$M:$M,$AG21)="","",INDEX(Feed!$M:$M,$AG21)),"") -> 46287.671 | AD21: BRK-B | AE21: Holding | AF21: EQUITY | AG21: =IFERROR(MATCH($AD21,Feed!$A:$A,0),"") -> 91
A22: V | C22: =SUMIFS(Holdings!$D:$D,Holdings!$A:$A,$A$18,Holdings!$B:$B,A22) -> 0.07983334 | D22: =IFERROR(IF(INDEX(Feed!$B:$B,$AG22)="","",INDEX(Feed!$B:$B,$AG22)),"") | E22: =IFERROR(IF(INDEX(Feed!$C:$C,$AG22)="","",INDEX(Feed!$C:$C,$AG22)),"") | F22: =IFERROR(IF(INDEX(Feed!$D:$D,$AG22)="","",INDEX(Feed!$D:$D,$AG22)),"") | G22: =IFERROR(IF(INDEX(Feed!$E:$E,$AG22)="","",INDEX(Feed!$E:$E,$AG22)),"") | H22: =IFERROR(IF(INDEX(Feed!$F:$F,$AG22)="","",INDEX(Feed!$F:$F,$AG22)),"") | I22: =IF(AND(N(E22)>0,N(F22)>0),(F22-E22)/((F22+E22)/2)*10000,"") | J22: =IF(N(D22)>0,IFERROR(D22/INDEX(Feed!$G:$G,$AG22)-1,""),"") | K22: =IFERROR(IF(INDEX(Feed!$H:$H,$AG22)="","",INDEX(Feed!$H:$H,$AG22)),"") | L22: =IFERROR(IF(INDEX(Feed!$I:$I,$AG22)="","",INDEX(Feed!$I:$I,$AG22)),"") | M22: =IF(AND(N(K22)>0,N(L22)>0),K22/L22,"") | N22: =IFERROR(IF(INDEX(Feed!$L:$L,$AG22)="","",INDEX(Feed!$L:$L,$AG22)),"") -> 0.012657042 | O22: =IF(AND(ISNUMBER(J22),N(N22)>0),J22/N22,"") | P22: =IF(ISNUMBER(O22),IF(SessionLeft<=0,--(ABS(O22)>1),_xlfn.NORM.S.DIST((-1-O22)/SQRT(SessionLeft),TRUE)+1-_xlfn.NORM.S.DIST((1-O22)/SQRT(SessionLeft),TRUE)),"") | Q22: =IF(ISNUMBER(O22),IF(SessionLeft<=0,--(ABS(O22)>2),_xlfn.NORM.S.DIST((-2-O22)/SQRT(SessionLeft),TRUE)+1-_xlfn.NORM.S.DIST((2-O22)/SQRT(SessionLeft),TRUE)),"") | R22: =IF(ISNUMBER(O22),IF(SessionLeft<=0,--(ABS(O22)>3),_xlfn.NORM.S.DIST((-3-O22)/SQRT(SessionLeft),TRUE)+1-_xlfn.NORM.S.DIST((3-O22)/SQRT(SessionLeft),TRUE)),"") | AB22: =IFERROR(IF(INDEX(Feed!$M:$M,$AG22)="","",INDEX(Feed!$M:$M,$AG22)),"") | AD22: V | AE22: Holding | AF22: EQUITY | AG22: =IFERROR(MATCH($AD22,Feed!$A:$A,0),"") -> 509
A23: XLE | B23: =IF(NOT(ISNUMBER(V23)),"",IF((NOW()-N(AB23))*1440>StaleMin,"STALE",IF(AND($AF23="EQUITY",ABS(N(T23))>ExDivFlag),"EX-DIV?",IF(X23>IF($AF23="FI",EdgeFI,EdgeEq),"SELL ETF / BUY "&UPPER($A$24),IF(Y23>IF($AF23="FI",EdgeFI,EdgeEq),"BUY ETF / SELL "&UPPER($A$24),""))))) -> STALE | C23: =IFERROR(IF(INDEX(Feed!$N:$N,$AG23)="","",INDEX(Feed!$N:$N,$AG23)),"") -> 1 | D23: =IFERROR(IF(INDEX(Feed!$B:$B,$AG23)="","",INDEX(Feed!$B:$B,$AG23)),"") -> 61.78 | E23: =IFERROR(IF(INDEX(Feed!$C:$C,$AG23)="","",INDEX(Feed!$C:$C,$AG23)),"") | F23: =IFERROR(IF(INDEX(Feed!$D:$D,$AG23)="","",INDEX(Feed!$D:$D,$AG23)),"") | G23: =IFERROR(IF(INDEX(Feed!$E:$E,$AG23)="","",INDEX(Feed!$E:$E,$AG23)),"") | H23: =IFERROR(IF(INDEX(Feed!$F:$F,$AG23)="","",INDEX(Feed!$F:$F,$AG23)),"") | I23: =IF(AND(N(E23)>0,N(F23)>0),(F23-E23)/((F23+E23)/2)*10000,"") | J23: =IF(N(D23)>0,IFERROR(D23/INDEX(Feed!$G:$G,$AG23)-1,""),"") -> -0.039340694 | K23: =IFERROR(IF(INDEX(Feed!$H:$H,$AG23)="","",INDEX(Feed!$H:$H,$AG23)),"") -> 36482216 | L23: =IFERROR(IF(INDEX(Feed!$I:$I,$AG23)="","",INDEX(Feed!$I:$I,$AG23)),"") | M23: =IF(AND(N(K23)>0,N(L23)>0),K23/L23,"") | N23: =IFERROR(IF(INDEX(Feed!$L:$L,$AG23)="","",INDEX(Feed!$L:$L,$AG23)),"") -> 0.013677719 | O23: =IF(AND(ISNUMBER(J23),N(N23)>0),J23/N23,"") -> -2.8762613 | P23: =IF(ISNUMBER(O23),IF(SessionLeft<=0,--(ABS(O23)>1),_xlfn.NORM.S.DIST((-1-O23)/SQRT(SessionLeft),TRUE)+1-_xlfn.NORM.S.DIST((1-O23)/SQRT(SessionLeft),TRUE)),"") -> 1 | Q23: =IF(ISNUMBER(O23),IF(SessionLeft<=0,--(ABS(O23)>2),_xlfn.NORM.S.DIST((-2-O23)/SQRT(SessionLeft),TRUE)+1-_xlfn.NORM.S.DIST((2-O23)/SQRT(SessionLeft),TRUE)),"") -> 1 | R23: =IF(ISNUMBER(O23),IF(SessionLeft<=0,--(ABS(O23)>3),_xlfn.NORM.S.DIST((-3-O23)/SQRT(SessionLeft),TRUE)+1-_xlfn.NORM.S.DIST((3-O23)/SQRT(SessionLeft),TRUE)),"") -> 0 | S23: =IFERROR(IF(INDEX(Feed!$J:$J,$AG23)="","",INDEX(Feed!$J:$J,$AG23)),"") -> 64.3543 | T23: =IFERROR(IF(N(S23)>0,(INDEX(Feed!$G:$G,$AG23)/S23-1)*10000,""),"") -> -6.8837669 | U23: =IFERROR(C23*$J$24,"") -> -0.031958605 | V23: =IF(ISNUMBER(U23),IF(AND(Anchor="NAV",N(S23)>0),S23,INDEX(Feed!$G:$G,$AG23))*(1+U23),"") -> 62.254742 | W23: =IF(ISNUMBER(V23),(IF(AND(N(E23)>0,N(F23)>0),(E23+F23)/2,D23)/V23-1)*10000,"") -> -76.257988 | X23: =IF(ISNUMBER(V23),(IF(N(E23)>0,E23,D23)/V23-1)*10000-IF($AF23="FI",CostFI,CostEq),"") -> -79.257988 | Y23: =IF(ISNUMBER(V23),(1-IF(N(F23)>0,F23,D23)/V23)*10000-IF($AF23="FI",CostFI,CostEq),"") -> 73.257988 | Z23: =IFERROR((J23-U23-INDEX(Feed!$O:$O,$AG23))/INDEX(Feed!$P:$P,$AG23),"") -> -8.2694726 | AA23: =IFERROR(IF(INDEX(Feed!$K:$K,$AG23)="","",INDEX(Feed!$K:$K,$AG23)),"") -> 0.023699999 | AB23: =IFERROR(IF(INDEX(Feed!$M:$M,$AG23)="","",INDEX(Feed!$M:$M,$AG23)),"") -> 46287.671 | AD23: XLE | AE23: ETF | AF23: EQUITY | AG23: =IFERROR(MATCH($AD23,Feed!$A:$A,0),"") -> 6
A24: Basket | C24: =IFERROR(SUMIFS(Holdings!$G:$G,Holdings!$A:$A,$A$23)/SUMIFS(Holdings!$D:$D,Holdings!$A:$A,$A$23),"") -> 0.5851916 | J24: =IFERROR(SUMIFS(Holdings!$F:$F,Holdings!$A:$A,$A$23)/SUMIFS(Holdings!$G:$G,Holdings!$A:$A,$A$23),"") -> -0.031958605 | N24: =IFERROR(IF(INDEX(Feed!$L:$L,$AG24)="","",INDEX(Feed!$L:$L,$AG24)),"") -> 0.013826421 | O24: =IF(AND(ISNUMBER(J24),N(N24)>0),J24/N24,"") -> -2.3114155 | P24: =IF(ISNUMBER(O24),IF(SessionLeft<=0,--(ABS(O24)>1),_xlfn.NORM.S.DIST((-1-O24)/SQRT(SessionLeft),TRUE)+1-_xlfn.NORM.S.DIST((1-O24)/SQRT(SessionLeft),TRUE)),"") -> 1 | Q24: =IF(ISNUMBER(O24),IF(SessionLeft<=0,--(ABS(O24)>2),_xlfn.NORM.S.DIST((-2-O24)/SQRT(SessionLeft),TRUE)+1-_xlfn.NORM.S.DIST((2-O24)/SQRT(SessionLeft),TRUE)),"") -> 1 | R24: =IF(ISNUMBER(O24),IF(SessionLeft<=0,--(ABS(O24)>3),_xlfn.NORM.S.DIST((-3-O24)/SQRT(SessionLeft),TRUE)+1-_xlfn.NORM.S.DIST((3-O24)/SQRT(SessionLeft),TRUE)),"") -> 0 | AD24: XLE BASKET | AE24: Basket | AF24: EQUITY | AG24: =IFERROR(MATCH($AD24,Feed!$A:$A,0),"") -> 563
A25: XOM | C25: =SUMIFS(Holdings!$D:$D,Holdings!$A:$A,$A$23,Holdings!$B:$B,A25) -> 0.23363762 | D25: =IFERROR(IF(INDEX(Feed!$B:$B,$AG25)="","",INDEX(Feed!$B:$B,$AG25)),"") | E25: =IFERROR(IF(INDEX(Feed!$C:$C,$AG25)="","",INDEX(Feed!$C:$C,$AG25)),"") | F25: =IFERROR(IF(INDEX(Feed!$D:$D,$AG25)="","",INDEX(Feed!$D:$D,$AG25)),"") | G25: =IFERROR(IF(INDEX(Feed!$E:$E,$AG25)="","",INDEX(Feed!$E:$E,$AG25)),"") | H25: =IFERROR(IF(INDEX(Feed!$F:$F,$AG25)="","",INDEX(Feed!$F:$F,$AG25)),"") | I25: =IF(AND(N(E25)>0,N(F25)>0),(F25-E25)/((F25+E25)/2)*10000,"") | J25: =IF(N(D25)>0,IFERROR(D25/INDEX(Feed!$G:$G,$AG25)-1,""),"") | K25: =IFERROR(IF(INDEX(Feed!$H:$H,$AG25)="","",INDEX(Feed!$H:$H,$AG25)),"") | L25: =IFERROR(IF(INDEX(Feed!$I:$I,$AG25)="","",INDEX(Feed!$I:$I,$AG25)),"") | M25: =IF(AND(N(K25)>0,N(L25)>0),K25/L25,"") | N25: =IFERROR(IF(INDEX(Feed!$L:$L,$AG25)="","",INDEX(Feed!$L:$L,$AG25)),"") -> 0.016503579 | O25: =IF(AND(ISNUMBER(J25),N(N25)>0),J25/N25,"") | P25: =IF(ISNUMBER(O25),IF(SessionLeft<=0,--(ABS(O25)>1),_xlfn.NORM.S.DIST((-1-O25)/SQRT(SessionLeft),TRUE)+1-_xlfn.NORM.S.DIST((1-O25)/SQRT(SessionLeft),TRUE)),"") | Q25: =IF(ISNUMBER(O25),IF(SessionLeft<=0,--(ABS(O25)>2),_xlfn.NORM.S.DIST((-2-O25)/SQRT(SessionLeft),TRUE)+1-_xlfn.NORM.S.DIST((2-O25)/SQRT(SessionLeft),TRUE)),"") | R25: =IF(ISNUMBER(O25),IF(SessionLeft<=0,--(ABS(O25)>3),_xlfn.NORM.S.DIST((-3-O25)/SQRT(SessionLeft),TRUE)+1-_xlfn.NORM.S.DIST((3-O25)/SQRT(SessionLeft),TRUE)),"") | AB25: =IFERROR(IF(INDEX(Feed!$M:$M,$AG25)="","",INDEX(Feed!$M:$M,$AG25)),"") | AD25: XOM | AE25: Holding | AF25: EQUITY | AG25: =IFERROR(MATCH($AD25,Feed!$A:$A,0),"") -> 552
A26: CVX | C26: =SUMIFS(Holdings!$D:$D,Holdings!$A:$A,$A$23,Holdings!$B:$B,A26) -> 0.17839262 | D26: =IFERROR(IF(INDEX(Feed!$B:$B,$AG26)="","",INDEX(Feed!$B:$B,$AG26)),"") -> 202.41 | E26: =IFERROR(IF(INDEX(Feed!$C:$C,$AG26)="","",INDEX(Feed!$C:$C,$AG26)),"") | F26: =IFERROR(IF(INDEX(Feed!$D:$D,$AG26)="","",INDEX(Feed!$D:$D,$AG26)),"") | G26: =IFERROR(IF(INDEX(Feed!$E:$E,$AG26)="","",INDEX(Feed!$E:$E,$AG26)),"") | H26: =IFERROR(IF(INDEX(Feed!$F:$F,$AG26)="","",INDEX(Feed!$F:$F,$AG26)),"") | I26: =IF(AND(N(E26)>0,N(F26)>0),(F26-E26)/((F26+E26)/2)*10000,"") | J26: =IF(N(D26)>0,IFERROR(D26/INDEX(Feed!$G:$G,$AG26)-1,""),"") -> -0.033888597 | K26: =IFERROR(IF(INDEX(Feed!$H:$H,$AG26)="","",INDEX(Feed!$H:$H,$AG26)),"") -> 8469759 | L26: =IFERROR(IF(INDEX(Feed!$I:$I,$AG26)="","",INDEX(Feed!$I:$I,$AG26)),"") | M26: =IF(AND(N(K26)>0,N(L26)>0),K26/L26,"") | N26: =IFERROR(IF(INDEX(Feed!$L:$L,$AG26)="","",INDEX(Feed!$L:$L,$AG26)),"") -> 0.015788966 | O26: =IF(AND(ISNUMBER(J26),N(N26)>0),J26/N26,"") -> -2.1463468 | P26: =IF(ISNUMBER(O26),IF(SessionLeft<=0,--(ABS(O26)>1),_xlfn.NORM.S.DIST((-1-O26)/SQRT(SessionLeft),TRUE)+1-_xlfn.NORM.S.DIST((1-O26)/SQRT(SessionLeft),TRUE)),"") -> 1 | Q26: =IF(ISNUMBER(O26),IF(SessionLeft<=0,--(ABS(O26)>2),_xlfn.NORM.S.DIST((-2-O26)/SQRT(SessionLeft),TRUE)+1-_xlfn.NORM.S.DIST((2-O26)/SQRT(SessionLeft),TRUE)),"") -> 1 | R26: =IF(ISNUMBER(O26),IF(SessionLeft<=0,--(ABS(O26)>3),_xlfn.NORM.S.DIST((-3-O26)/SQRT(SessionLeft),TRUE)+1-_xlfn.NORM.S.DIST((3-O26)/SQRT(SessionLeft),TRUE)),"") -> 0 | AB26: =IFERROR(IF(INDEX(Feed!$M:$M,$AG26)="","",INDEX(Feed!$M:$M,$AG26)),"") -> 46287.671 | AD26: CVX | AE26: Holding | AF26: EQUITY | AG26: =IFERROR(MATCH($AD26,Feed!$A:$A,0),"") -> 150
A27: COP | C27: =SUMIFS(Holdings!$D:$D,Holdings!$A:$A,$A$23,Holdings!$B:$B,A27) -> 0.06713039 | D27: =IFERROR(IF(INDEX(Feed!$B:$B,$AG27)="","",INDEX(Feed!$B:$B,$AG27)),"") -> 125.27 | E27: =IFERROR(IF(INDEX(Feed!$C:$C,$AG27)="","",INDEX(Feed!$C:$C,$AG27)),"") | F27: =IFERROR(IF(INDEX(Feed!$D:$D,$AG27)="","",INDEX(Feed!$D:$D,$AG27)),"") | G27: =IFERROR(IF(INDEX(Feed!$E:$E,$AG27)="","",INDEX(Feed!$E:$E,$AG27)),"") | H27: =IFERROR(IF(INDEX(Feed!$F:$F,$AG27)="","",INDEX(Feed!$F:$F,$AG27)),"") | I27: =IF(AND(N(E27)>0,N(F27)>0),(F27-E27)/((F27+E27)/2)*10000,"") | J27: =IF(N(D27)>0,IFERROR(D27/INDEX(Feed!$G:$G,$AG27)-1,""),"") -> -0.049761056 | K27: =IFERROR(IF(INDEX(Feed!$H:$H,$AG27)="","",INDEX(Feed!$H:$H,$AG27)),"") -> 6157054 | L27: =IFERROR(IF(INDEX(Feed!$I:$I,$AG27)="","",INDEX(Feed!$I:$I,$AG27)),"") | M27: =IF(AND(N(K27)>0,N(L27)>0),K27/L27,"") | N27: =IFERROR(IF(INDEX(Feed!$L:$L,$AG27)="","",INDEX(Feed!$L:$L,$AG27)),"") -> 0.01979802 | O27: =IF(AND(ISNUMBER(J27),N(N27)>0),J27/N27,"") -> -2.513436 | P27: =IF(ISNUMBER(O27),IF(SessionLeft<=0,--(ABS(O27)>1),_xlfn.NORM.S.DIST((-1-O27)/SQRT(SessionLeft),TRUE)+1-_xlfn.NORM.S.DIST((1-O27)/SQRT(SessionLeft),TRUE)),"") -> 1 | Q27: =IF(ISNUMBER(O27),IF(SessionLeft<=0,--(ABS(O27)>2),_xlfn.NORM.S.DIST((-2-O27)/SQRT(SessionLeft),TRUE)+1-_xlfn.NORM.S.DIST((2-O27)/SQRT(SessionLeft),TRUE)),"") -> 1 | R27: =IF(ISNUMBER(O27),IF(SessionLeft<=0,--(ABS(O27)>3),_xlfn.NORM.S.DIST((-3-O27)/SQRT(SessionLeft),TRUE)+1-_xlfn.NORM.S.DIST((3-O27)/SQRT(SessionLeft),TRUE)),"") -> 0 | AB27: =IFERROR(IF(INDEX(Feed!$M:$M,$AG27)="","",INDEX(Feed!$M:$M,$AG27)),"") -> 46287.671 | AD27: COP | AE27: Holding | AF27: EQUITY | AG27: =IFERROR(MATCH($AD27,Feed!$A:$A,0),"") -> 131
A28: XLV | B28: =IF(NOT(ISNUMBER(V28)),"",IF((NOW()-N(AB28))*1440>StaleMin,"STALE",IF(AND($AF28="EQUITY",ABS(N(T28))>ExDivFlag),"EX-DIV?",IF(X28>IF($AF28="FI",EdgeFI,EdgeEq),"SELL ETF / BUY "&UPPER($A$29),IF(Y28>IF($AF28="FI",EdgeFI,EdgeEq),"BUY ETF / SELL "&UPPER($A$29),""))))) -> STALE | C28: =IFERROR(IF(INDEX(Feed!$N:$N,$AG28)="","",INDEX(Feed!$N:$N,$AG28)),"") -> 1 | D28: =IFERROR(IF(INDEX(Feed!$B:$B,$AG28)="","",INDEX(Feed!$B:$B,$AG28)),"") -> 170.34 | E28: =IFERROR(IF(INDEX(Feed!$C:$C,$AG28)="","",INDEX(Feed!$C:$C,$AG28)),"") -> 169.55 | F28: =IFERROR(IF(INDEX(Feed!$D:$D,$AG28)="","",INDEX(Feed!$D:$D,$AG28)),"") -> 170.35 | G28: =IFERROR(IF(INDEX(Feed!$E:$E,$AG28)="","",INDEX(Feed!$E:$E,$AG28)),"") -> 100 | H28: =IFERROR(IF(INDEX(Feed!$F:$F,$AG28)="","",INDEX(Feed!$F:$F,$AG28)),"") -> 700 | I28: =IF(AND(N(E28)>0,N(F28)>0),(F28-E28)/((F28+E28)/2)*10000,"") -> 47.072668 | J28: =IF(N(D28)>0,IFERROR(D28/INDEX(Feed!$G:$G,$AG28)-1,""),"") -> 0.01158026 | K28: =IFERROR(IF(INDEX(Feed!$H:$H,$AG28)="","",INDEX(Feed!$H:$H,$AG28)),"") -> 7618319 | L28: =IFERROR(IF(INDEX(Feed!$I:$I,$AG28)="","",INDEX(Feed!$I:$I,$AG28)),"") | M28: =IF(AND(N(K28)>0,N(L28)>0),K28/L28,"") | N28: =IFERROR(IF(INDEX(Feed!$L:$L,$AG28)="","",INDEX(Feed!$L:$L,$AG28)),"") -> 0.012011046 | O28: =IF(AND(ISNUMBER(J28),N(N28)>0),J28/N28,"") -> 0.96413422 | P28: =IF(ISNUMBER(O28),IF(SessionLeft<=0,--(ABS(O28)>1),_xlfn.NORM.S.DIST((-1-O28)/SQRT(SessionLeft),TRUE)+1-_xlfn.NORM.S.DIST((1-O28)/SQRT(SessionLeft),TRUE)),"") -> 0 | Q28: =IF(ISNUMBER(O28),IF(SessionLeft<=0,--(ABS(O28)>2),_xlfn.NORM.S.DIST((-2-O28)/SQRT(SessionLeft),TRUE)+1-_xlfn.NORM.S.DIST((2-O28)/SQRT(SessionLeft),TRUE)),"") -> 0 | R28: =IF(ISNUMBER(O28),IF(SessionLeft<=0,--(ABS(O28)>3),_xlfn.NORM.S.DIST((-3-O28)/SQRT(SessionLeft),TRUE)+1-_xlfn.NORM.S.DIST((3-O28)/SQRT(SessionLeft),TRUE)),"") -> 0 | S28: =IFERROR(IF(INDEX(Feed!$J:$J,$AG28)="","",INDEX(Feed!$J:$J,$AG28)),"") -> 168.47356 | T28: =IFERROR(IF(N(S28)>0,(INDEX(Feed!$G:$G,$AG28)/S28-1)*10000,""),"") -> -4.9598287 | U28: =IFERROR(C28*$J$29,"") -> 0.013971663 | V28: =IF(ISNUMBER(U28),IF(AND(Anchor="NAV",N(S28)>0),S28,INDEX(Feed!$G:$G,$AG28))*(1+U28),"") -> 170.74269 | W28: =IF(ISNUMBER(V28),(IF(AND(N(E28)>0,N(F28)>0),(E28+F28)/2,D28)/V28-1)*10000,"") -> -46.425899 | X28: =IF(ISNUMBER(V28),(IF(N(E28)>0,E28,D28)/V28-1)*10000-IF($AF28="FI",CostFI,CostEq),"") -> -72.852964 | Y28: =IF(ISNUMBER(V28),(1-IF(N(F28)>0,F28,D28)/V28)*10000-IF($AF28="FI",CostFI,CostEq),"") -> 19.998834 | Z28: =IFERROR((J28-U28-INDEX(Feed!$O:$O,$AG28))/INDEX(Feed!$P:$P,$AG28),"") -> -5.0744295 | AA28: =IFERROR(IF(INDEX(Feed!$K:$K,$AG28)="","",INDEX(Feed!$K:$K,$AG28)),"") -> 0.0149 | AB28: =IFERROR(IF(INDEX(Feed!$M:$M,$AG28)="","",INDEX(Feed!$M:$M,$AG28)),"") -> 46287.673 | AD28: XLV | AE28: ETF | AF28: EQUITY | AG28: =IFERROR(MATCH($AD28,Feed!$A:$A,0),"") -> 7
A29: Basket | C29: =IFERROR(SUMIFS(Holdings!$G:$G,Holdings!$A:$A,$A$28)/SUMIFS(Holdings!$D:$D,Holdings!$A:$A,$A$28),"") -> 0.89305529 | J29: =IFERROR(SUMIFS(Holdings!$F:$F,Holdings!$A:$A,$A$28)/SUMIFS(Holdings!$G:$G,Holdings!$A:$A,$A$28),"") -> 0.013971663 | N29: =IFERROR(IF(INDEX(Feed!$L:$L,$AG29)="","",INDEX(Feed!$L:$L,$AG29)),"") -> 0.012162636 | O29: =IF(AND(ISNUMBER(J29),N(N29)>0),J29/N29,"") -> 1.1487364 | P29: =IF(ISNUMBER(O29),IF(SessionLeft<=0,--(ABS(O29)>1),_xlfn.NORM.S.DIST((-1-O29)/SQRT(SessionLeft),TRUE)+1-_xlfn.NORM.S.DIST((1-O29)/SQRT(SessionLeft),TRUE)),"") -> 1 | Q29: =IF(ISNUMBER(O29),IF(SessionLeft<=0,--(ABS(O29)>2),_xlfn.NORM.S.DIST((-2-O29)/SQRT(SessionLeft),TRUE)+1-_xlfn.NORM.S.DIST((2-O29)/SQRT(SessionLeft),TRUE)),"") -> 0 | R29: =IF(ISNUMBER(O29),IF(SessionLeft<=0,--(ABS(O29)>3),_xlfn.NORM.S.DIST((-3-O29)/SQRT(SessionLeft),TRUE)+1-_xlfn.NORM.S.DIST((3-O29)/SQRT(SessionLeft),TRUE)),"") -> 0 | AD29: XLV BASKET | AE29: Basket | AF29: EQUITY | AG29: =IFERROR(MATCH($AD29,Feed!$A:$A,0),"") -> 564
A30: LLY | C30: =SUMIFS(Holdings!$D:$D,Holdings!$A:$A,$A$28,Holdings!$B:$B,A30) -> 0.1516036 | D30: =IFERROR(IF(INDEX(Feed!$B:$B,$AG30)="","",INDEX(Feed!$B:$B,$AG30)),"") -> 1169 | E30: =IFERROR(IF(INDEX(Feed!$C:$C,$AG30)="","",INDEX(Feed!$C:$C,$AG30)),"") | F30: =IFERROR(IF(INDEX(Feed!$D:$D,$AG30)="","",INDEX(Feed!$D:$D,$AG30)),"") | G30: =IFERROR(IF(INDEX(Feed!$E:$E,$AG30)="","",INDEX(Feed!$E:$E,$AG30)),"") | H30: =IFERROR(IF(INDEX(Feed!$F:$F,$AG30)="","",INDEX(Feed!$F:$F,$AG30)),"") | I30: =IF(AND(N(E30)>0,N(F30)>0),(F30-E30)/((F30+E30)/2)*10000,"") | J30: =IF(N(D30)>0,IFERROR(D30/INDEX(Feed!$G:$G,$AG30)-1,""),"") -> 0.0139384 | K30: =IFERROR(IF(INDEX(Feed!$H:$H,$AG30)="","",INDEX(Feed!$H:$H,$AG30)),"") -> 2480210 | L30: =IFERROR(IF(INDEX(Feed!$I:$I,$AG30)="","",INDEX(Feed!$I:$I,$AG30)),"") | M30: =IF(AND(N(K30)>0,N(L30)>0),K30/L30,"") | N30: =IFERROR(IF(INDEX(Feed!$L:$L,$AG30)="","",INDEX(Feed!$L:$L,$AG30)),"") -> 0.021168384 | O30: =IF(AND(ISNUMBER(J30),N(N30)>0),J30/N30,"") -> 0.65845369 | P30: =IF(ISNUMBER(O30),IF(SessionLeft<=0,--(ABS(O30)>1),_xlfn.NORM.S.DIST((-1-O30)/SQRT(SessionLeft),TRUE)+1-_xlfn.NORM.S.DIST((1-O30)/SQRT(SessionLeft),TRUE)),"") -> 0 | Q30: =IF(ISNUMBER(O30),IF(SessionLeft<=0,--(ABS(O30)>2),_xlfn.NORM.S.DIST((-2-O30)/SQRT(SessionLeft),TRUE)+1-_xlfn.NORM.S.DIST((2-O30)/SQRT(SessionLeft),TRUE)),"") -> 0 | R30: =IF(ISNUMBER(O30),IF(SessionLeft<=0,--(ABS(O30)>3),_xlfn.NORM.S.DIST((-3-O30)/SQRT(SessionLeft),TRUE)+1-_xlfn.NORM.S.DIST((3-O30)/SQRT(SessionLeft),TRUE)),"") -> 0 | AB30: =IFERROR(IF(INDEX(Feed!$M:$M,$AG30)="","",INDEX(Feed!$M:$M,$AG30)),"") -> 46287.671 | AD30: LLY | AE30: Holding | AF30: EQUITY | AG30: =IFERROR(MATCH($AD30,Feed!$A:$A,0),"") -> 313
A31: JNJ | C31: =SUMIFS(Holdings!$D:$D,Holdings!$A:$A,$A$28,Holdings!$B:$B,A31) -> 0.10504005 | D31: =IFERROR(IF(INDEX(Feed!$B:$B,$AG31)="","",INDEX(Feed!$B:$B,$AG31)),"") -> 269.19 | E31: =IFERROR(IF(INDEX(Feed!$C:$C,$AG31)="","",INDEX(Feed!$C:$C,$AG31)),"") | F31: =IFERROR(IF(INDEX(Feed!$D:$D,$AG31)="","",INDEX(Feed!$D:$D,$AG31)),"") | G31: =IFERROR(IF(INDEX(Feed!$E:$E,$AG31)="","",INDEX(Feed!$E:$E,$AG31)),"") | H31: =IFERROR(IF(INDEX(Feed!$F:$F,$AG31)="","",INDEX(Feed!$F:$F,$AG31)),"") | I31: =IF(AND(N(E31)>0,N(F31)>0),(F31-E31)/((F31+E31)/2)*10000,"") | J31: =IF(N(D31)>0,IFERROR(D31/INDEX(Feed!$G:$G,$AG31)-1,""),"") -> -0.0029630727 | K31: =IFERROR(IF(INDEX(Feed!$H:$H,$AG31)="","",INDEX(Feed!$H:$H,$AG31)),"") -> 4487741 | L31: =IFERROR(IF(INDEX(Feed!$I:$I,$AG31)="","",INDEX(Feed!$I:$I,$AG31)),"") | M31: =IF(AND(N(K31)>0,N(L31)>0),K31/L31,"") | N31: =IFERROR(IF(INDEX(Feed!$L:$L,$AG31)="","",INDEX(Feed!$L:$L,$AG31)),"") -> 0.015061652 | O31: =IF(AND(ISNUMBER(J31),N(N31)>0),J31/N31,"") -> -0.1967296 | P31: =IF(ISNUMBER(O31),IF(SessionLeft<=0,--(ABS(O31)>1),_xlfn.NORM.S.DIST((-1-O31)/SQRT(SessionLeft),TRUE)+1-_xlfn.NORM.S.DIST((1-O31)/SQRT(SessionLeft),TRUE)),"") -> 0 | Q31: =IF(ISNUMBER(O31),IF(SessionLeft<=0,--(ABS(O31)>2),_xlfn.NORM.S.DIST((-2-O31)/SQRT(SessionLeft),TRUE)+1-_xlfn.NORM.S.DIST((2-O31)/SQRT(SessionLeft),TRUE)),"") -> 0 | R31: =IF(ISNUMBER(O31),IF(SessionLeft<=0,--(ABS(O31)>3),_xlfn.NORM.S.DIST((-3-O31)/SQRT(SessionLeft),TRUE)+1-_xlfn.NORM.S.DIST((3-O31)/SQRT(SessionLeft),TRUE)),"") -> 0 | AB31: =IFERROR(IF(INDEX(Feed!$M:$M,$AG31)="","",INDEX(Feed!$M:$M,$AG31)),"") -> 46287.671 | AD31: JNJ | AE31: Holding | AF31: EQUITY | AG31: =IFERROR(MATCH($AD31,Feed!$A:$A,0),"") -> 290
A32: ABBV | C32: =SUMIFS(Holdings!$D:$D,Holdings!$A:$A,$A$28,Holdings!$B:$B,A32) -> 0.07588456 | D32: =IFERROR(IF(INDEX(Feed!$B:$B,$AG32)="","",INDEX(Feed!$B:$B,$AG32)),"") -> 265.21 | E32: =IFERROR(IF(INDEX(Feed!$C:$C,$AG32)="","",INDEX(Feed!$C:$C,$AG32)),"") | F32: =IFERROR(IF(INDEX(Feed!$D:$D,$AG32)="","",INDEX(Feed!$D:$D,$AG32)),"") | G32: =IFERROR(IF(INDEX(Feed!$E:$E,$AG32)="","",INDEX(Feed!$E:$E,$AG32)),"") | H32: =IFERROR(IF(INDEX(Feed!$F:$F,$AG32)="","",INDEX(Feed!$F:$F,$AG32)),"") | I32: =IF(AND(N(E32)>0,N(F32)>0),(F32-E32)/((F32+E32)/2)*10000,"") | J32: =IF(N(D32)>0,IFERROR(D32/INDEX(Feed!$G:$G,$AG32)-1,""),"") -> 0.004735566 | K32: =IFERROR(IF(INDEX(Feed!$H:$H,$AG32)="","",INDEX(Feed!$H:$H,$AG32)),"") -> 3438160 | L32: =IFERROR(IF(INDEX(Feed!$I:$I,$AG32)="","",INDEX(Feed!$I:$I,$AG32)),"") | M32: =IF(AND(N(K32)>0,N(L32)>0),K32/L32,"") | N32: =IFERROR(IF(INDEX(Feed!$L:$L,$AG32)="","",INDEX(Feed!$L:$L,$AG32)),"") -> 0.015757903 | O32: =IF(AND(ISNUMBER(J32),N(N32)>0),J32/N32,"") -> 0.30052007 | P32: =IF(ISNUMBER(O32),IF(SessionLeft<=0,--(ABS(O32)>1),_xlfn.NORM.S.DIST((-1-O32)/SQRT(SessionLeft),TRUE)+1-_xlfn.NORM.S.DIST((1-O32)/SQRT(SessionLeft),TRUE)),"") -> 0 | Q32: =IF(ISNUMBER(O32),IF(SessionLeft<=0,--(ABS(O32)>2),_xlfn.NORM.S.DIST((-2-O32)/SQRT(SessionLeft),TRUE)+1-_xlfn.NORM.S.DIST((2-O32)/SQRT(SessionLeft),TRUE)),"") -> 0 | R32: =IF(ISNUMBER(O32),IF(SessionLeft<=0,--(ABS(O32)>3),_xlfn.NORM.S.DIST((-3-O32)/SQRT(SessionLeft),TRUE)+1-_xlfn.NORM.S.DIST((3-O32)/SQRT(SessionLeft),TRUE)),"") -> 0 | AB32: =IFERROR(IF(INDEX(Feed!$M:$M,$AG32)="","",INDEX(Feed!$M:$M,$AG32)),"") -> 46287.671 | AD32: ABBV | AE32: Holding | AF32: EQUITY | AG32: =IFERROR(MATCH($AD32,Feed!$A:$A,0),"") -> 21
A33: IWM | B33: =IF(NOT(ISNUMBER(V33)),"",IF((NOW()-N(AB33))*1440>StaleMin,"STALE",IF(AND($AF33="EQUITY",ABS(N(T33))>ExDivFlag),"EX-DIV?",IF(X33>IF($AF33="FI",EdgeFI,EdgeEq),"SELL ETF / BUY "&UPPER($A$34),IF(Y33>IF($AF33="FI",EdgeFI,EdgeEq),"BUY ETF / SELL "&UPPER($A$34),""))))) -> STALE | C33: =IFERROR(IF(INDEX(Feed!$N:$N,$AG33)="","",INDEX(Feed!$N:$N,$AG33)),"") -> 0.99819867 | D33: =IFERROR(IF(INDEX(Feed!$B:$B,$AG33)="","",INDEX(Feed!$B:$B,$AG33)),"") -> 285.4921 | E33: =IFERROR(IF(INDEX(Feed!$C:$C,$AG33)="","",INDEX(Feed!$C:$C,$AG33)),"") | F33: =IFERROR(IF(INDEX(Feed!$D:$D,$AG33)="","",INDEX(Feed!$D:$D,$AG33)),"") | G33: =IFERROR(IF(INDEX(Feed!$E:$E,$AG33)="","",INDEX(Feed!$E:$E,$AG33)),"") | H33: =IFERROR(IF(INDEX(Feed!$F:$F,$AG33)="","",INDEX(Feed!$F:$F,$AG33)),"") | I33: =IF(AND(N(E33)>0,N(F33)>0),(F33-E33)/((F33+E33)/2)*10000,"") | J33: =IF(N(D33)>0,IFERROR(D33/INDEX(Feed!$G:$G,$AG33)-1,""),"") -> 0.0049000352 | K33: =IFERROR(IF(INDEX(Feed!$H:$H,$AG33)="","",INDEX(Feed!$H:$H,$AG33)),"") -> 18968224 | L33: =IFERROR(IF(INDEX(Feed!$I:$I,$AG33)="","",INDEX(Feed!$I:$I,$AG33)),"") | M33: =IF(AND(N(K33)>0,N(L33)>0),K33/L33,"") | N33: =IFERROR(IF(INDEX(Feed!$L:$L,$AG33)="","",INDEX(Feed!$L:$L,$AG33)),"") -> 0.008127509 | O33: =IF(AND(ISNUMBER(J33),N(N33)>0),J33/N33,"") -> 0.60289508 | P33: =IF(ISNUMBER(O33),IF(SessionLeft<=0,--(ABS(O33)>1),_xlfn.NORM.S.DIST((-1-O33)/SQRT(SessionLeft),TRUE)+1-_xlfn.NORM.S.DIST((1-O33)/SQRT(SessionLeft),TRUE)),"") -> 0 | Q33: =IF(ISNUMBER(O33),IF(SessionLeft<=0,--(ABS(O33)>2),_xlfn.NORM.S.DIST((-2-O33)/SQRT(SessionLeft),TRUE)+1-_xlfn.NORM.S.DIST((2-O33)/SQRT(SessionLeft),TRUE)),"") -> 0 | R33: =IF(ISNUMBER(O33),IF(SessionLeft<=0,--(ABS(O33)>3),_xlfn.NORM.S.DIST((-3-O33)/SQRT(SessionLeft),TRUE)+1-_xlfn.NORM.S.DIST((3-O33)/SQRT(SessionLeft),TRUE)),"") -> 0 | S33: =IFERROR(IF(INDEX(Feed!$J:$J,$AG33)="","",INDEX(Feed!$J:$J,$AG33)),"") -> 283.9969 | T33: =IFERROR(IF(N(S33)>0,(INDEX(Feed!$G:$G,$AG33)/S33-1)*10000,""),"") -> 3.6303213 | U33: =IFERROR(C33*$J$34,"") -> 0.0056921831 | V33: =IF(ISNUMBER(U33),IF(AND(Anchor="NAV",N(S33)>0),S33,INDEX(Feed!$G:$G,$AG33))*(1+U33),"") -> 285.71715 | W33: =IF(ISNUMBER(V33),(IF(AND(N(E33)>0,N(F33)>0),(E33+F33)/2,D33)/V33-1)*10000,"") -> -7.8766435 | X33: =IF(ISNUMBER(V33),(IF(N(E33)>0,E33,D33)/V33-1)*10000-IF($AF33="FI",CostFI,CostEq),"") -> -10.876644 | Y33: =IF(ISNUMBER(V33),(1-IF(N(F33)>0,F33,D33)/V33)*10000-IF($AF33="FI",CostFI,CostEq),"") -> 4.8766435 | Z33: =IFERROR((J33-U33-INDEX(Feed!$O:$O,$AG33))/INDEX(Feed!$P:$P,$AG33),"") -> -0.57140361 | AA33: =IFERROR(IF(INDEX(Feed!$K:$K,$AG33)="","",INDEX(Feed!$K:$K,$AG33)),"") -> 0.009 | AB33: =IFERROR(IF(INDEX(Feed!$M:$M,$AG33)="","",INDEX(Feed!$M:$M,$AG33)),"") -> 46287.672 | AD33: IWM | AE33: ETF | AF33: EQUITY | AG33: =IFERROR(MATCH($AD33,Feed!$A:$A,0),"") -> 8
A34: VTWO | D34: =IFERROR(IF(INDEX(Feed!$B:$B,$AG34)="","",INDEX(Feed!$B:$B,$AG34)),"") -> 116.4 | E34: =IFERROR(IF(INDEX(Feed!$C:$C,$AG34)="","",INDEX(Feed!$C:$C,$AG34)),"") -> 116.35 | F34: =IFERROR(IF(INDEX(Feed!$D:$D,$AG34)="","",INDEX(Feed!$D:$D,$AG34)),"") -> 116.38 | G34: =IFERROR(IF(INDEX(Feed!$E:$E,$AG34)="","",INDEX(Feed!$E:$E,$AG34)),"") -> 1300 | H34: =IFERROR(IF(INDEX(Feed!$F:$F,$AG34)="","",INDEX(Feed!$F:$F,$AG34)),"") -> 1300 | I34: =IF(AND(N(E34)>0,N(F34)>0),(F34-E34)/((F34+E34)/2)*10000,"") -> 2.5780948 | J34: =IF(N(D34)>0,IFERROR(D34/INDEX(Feed!$G:$G,$AG34)-1,""),"") -> 0.0057024551 | K34: =IFERROR(IF(INDEX(Feed!$H:$H,$AG34)="","",INDEX(Feed!$H:$H,$AG34)),"") | L34: =IFERROR(IF(INDEX(Feed!$I:$I,$AG34)="","",INDEX(Feed!$I:$I,$AG34)),"") | M34: =IF(AND(N(K34)>0,N(L34)>0),K34/L34,"") | N34: =IFERROR(IF(INDEX(Feed!$L:$L,$AG34)="","",INDEX(Feed!$L:$L,$AG34)),"") -> 0.0080839738 | O34: =IF(AND(ISNUMBER(J34),N(N34)>0),J34/N34,"") -> 0.70540246 | P34: =IF(ISNUMBER(O34),IF(SessionLeft<=0,--(ABS(O34)>1),_xlfn.NORM.S.DIST((-1-O34)/SQRT(SessionLeft),TRUE)+1-_xlfn.NORM.S.DIST((1-O34)/SQRT(SessionLeft),TRUE)),"") -> 0 | Q34: =IF(ISNUMBER(O34),IF(SessionLeft<=0,--(ABS(O34)>2),_xlfn.NORM.S.DIST((-2-O34)/SQRT(SessionLeft),TRUE)+1-_xlfn.NORM.S.DIST((2-O34)/SQRT(SessionLeft),TRUE)),"") -> 0 | R34: =IF(ISNUMBER(O34),IF(SessionLeft<=0,--(ABS(O34)>3),_xlfn.NORM.S.DIST((-3-O34)/SQRT(SessionLeft),TRUE)+1-_xlfn.NORM.S.DIST((3-O34)/SQRT(SessionLeft),TRUE)),"") -> 0 | AB34: =IFERROR(IF(INDEX(Feed!$M:$M,$AG34)="","",INDEX(Feed!$M:$M,$AG34)),"") -> 46287.683 | AD34: VTWO | AE34: Underlying | AF34: EQUITY | AG34: =IFERROR(MATCH($AD34,Feed!$A:$A,0),"") -> 532
