Workbook

Sheet Summary
A1: Pair | B1: ETF | C1: Underlying | D1: ρ 1m | E1: ρ 5m | F1: ρ 15m | G1: ρ daily (1y) | H1: β 1m | I1: β 5m | J1: β 15m | K1: β daily (1y) | L1: R² 15m | M1: R² daily | N1: n 1m | O1: n 15m | P1: n daily | Q1: ETF minutes traded
A2: AVS/AVGO | B2: AVS | C2: AVGO | D2: =CORREL(R1!$E$2:$E$2731,R1!$F$2:$F$2731) | E2: =CORREL(R5!$E$2:$E$554,R5!$F$2:$F$554) | F2: =CORREL(R15!$E$2:$E$190,R15!$F$2:$F$190) | G2: =CORREL(RD!$D$2:$D$252,RD!$E$2:$E$252) | H2: =SLOPE(R1!$E$2:$E$2731,R1!$F$2:$F$2731) | I2: =SLOPE(R5!$E$2:$E$554,R5!$F$2:$F$554) | J2: =SLOPE(R15!$E$2:$E$190,R15!$F$2:$F$190) | K2: =SLOPE(RD!$D$2:$D$252,RD!$E$2:$E$252) | L2: =RSQ(R15!$E$2:$E$190,R15!$F$2:$F$190) | M2: =RSQ(RD!$D$2:$D$252,RD!$E$2:$E$252) | N2: =COUNT(R1!$E$2:$E$2731) | O2: =COUNT(R15!$E$2:$E$190) | P2: =COUNT(RD!$D$2:$D$252) | Q2: =COUNTIF(R1!$D$2:$D$2731,1)/2730
A3: AAPD/AAPL | B3: AAPD | C3: AAPL | D3: =CORREL(R1!$J$2:$J$2731,R1!$K$2:$K$2731) | E3: =CORREL(R5!$J$2:$J$554,R5!$K$2:$K$554) | F3: =CORREL(R15!$J$2:$J$190,R15!$K$2:$K$190) | G3: =CORREL(RD!$H$2:$H$252,RD!$I$2:$I$252) | H3: =SLOPE(R1!$J$2:$J$2731,R1!$K$2:$K$2731) | I3: =SLOPE(R5!$J$2:$J$554,R5!$K$2:$K$554) | J3: =SLOPE(R15!$J$2:$J$190,R15!$K$2:$K$190) | K3: =SLOPE(RD!$H$2:$H$252,RD!$I$2:$I$252) | L3: =RSQ(R15!$J$2:$J$190,R15!$K$2:$K$190) | M3: =RSQ(RD!$H$2:$H$252,RD!$I$2:$I$252) | N3: =COUNT(R1!$J$2:$J$2731) | O3: =COUNT(R15!$J$2:$J$190) | P3: =COUNT(RD!$H$2:$H$252) | Q3: =COUNTIF(R1!$I$2:$I$2731,1)/2730
A4: METD/META | B4: METD | C4: META | D4: =CORREL(R1!$O$2:$O$2731,R1!$P$2:$P$2731) | E4: =CORREL(R5!$O$2:$O$554,R5!$P$2:$P$554) | F4: =CORREL(R15!$O$2:$O$190,R15!$P$2:$P$190) | G4: =CORREL(RD!$L$2:$L$252,RD!$M$2:$M$252) | H4: =SLOPE(R1!$O$2:$O$2731,R1!$P$2:$P$2731) | I4: =SLOPE(R5!$O$2:$O$554,R5!$P$2:$P$554) | J4: =SLOPE(R15!$O$2:$O$190,R15!$P$2:$P$190) | K4: =SLOPE(RD!$L$2:$L$252,RD!$M$2:$M$252) | L4: =RSQ(R15!$O$2:$O$190,R15!$P$2:$P$190) | M4: =RSQ(RD!$L$2:$L$252,RD!$M$2:$M$252) | N4: =COUNT(R1!$O$2:$O$2731) | O4: =COUNT(R15!$O$2:$O$190) | P4: =COUNT(RD!$L$2:$L$252) | Q4: =COUNTIF(R1!$N$2:$N$2731,1)/2730
A5: MSFD/MSFT | B5: MSFD | C5: MSFT | D5: =CORREL(R1!$T$2:$T$2731,R1!$U$2:$U$2731) | E5: =CORREL(R5!$T$2:$T$554,R5!$U$2:$U$554) | F5: =CORREL(R15!$T$2:$T$190,R15!$U$2:$U$190) | G5: =CORREL(RD!$P$2:$P$252,RD!$Q$2:$Q$252) | H5: =SLOPE(R1!$T$2:$T$2731,R1!$U$2:$U$2731) | I5: =SLOPE(R5!$T$2:$T$554,R5!$U$2:$U$554) | J5: =SLOPE(R15!$T$2:$T$190,R15!$U$2:$U$190) | K5: =SLOPE(RD!$P$2:$P$252,RD!$Q$2:$Q$252) | L5: =RSQ(R15!$T$2:$T$190,R15!$U$2:$U$190) | M5: =RSQ(RD!$P$2:$P$252,RD!$Q$2:$Q$252) | N5: =COUNT(R1!$T$2:$T$2731) | O5: =COUNT(R15!$T$2:$T$190) | P5: =COUNT(RD!$P$2:$P$252) | Q5: =COUNTIF(R1!$S$2:$S$2731,1)/2730
A6: SPDN/SPX | B6: SPDN | C6: SPX | D6: =CORREL(R1!$Y$2:$Y$2731,R1!$Z$2:$Z$2731) | E6: =CORREL(R5!$Y$2:$Y$554,R5!$Z$2:$Z$554) | F6: =CORREL(R15!$Y$2:$Y$190,R15!$Z$2:$Z$190) | G6: =CORREL(RD!$T$2:$T$252,RD!$U$2:$U$252) | H6: =SLOPE(R1!$Y$2:$Y$2731,R1!$Z$2:$Z$2731) | I6: =SLOPE(R5!$Y$2:$Y$554,R5!$Z$2:$Z$554) | J6: =SLOPE(R15!$Y$2:$Y$190,R15!$Z$2:$Z$190) | K6: =SLOPE(RD!$T$2:$T$252,RD!$U$2:$U$252) | L6: =RSQ(R15!$Y$2:$Y$190,R15!$Z$2:$Z$190) | M6: =RSQ(RD!$T$2:$T$252,RD!$U$2:$U$252) | N6: =COUNT(R1!$Y$2:$Y$2731) | O6: =COUNT(R15!$Y$2:$Y$190) | P6: =COUNT(RD!$T$2:$T$252) | Q6: =COUNTIF(R1!$X$2:$X$2731,1)/2730
A7: AMZD/AMZN | B7: AMZD | C7: AMZN | D7: =CORREL(R1!$AD$2:$AD$2731,R1!$AE$2:$AE$2731) | E7: =CORREL(R5!$AD$2:$AD$554,R5!$AE$2:$AE$554) | F7: =CORREL(R15!$AD$2:$AD$190,R15!$AE$2:$AE$190) | G7: =CORREL(RD!$X$2:$X$252,RD!$Y$2:$Y$252) | H7: =SLOPE(R1!$AD$2:$AD$2731,R1!$AE$2:$AE$2731) | I7: =SLOPE(R5!$AD$2:$AD$554,R5!$AE$2:$AE$554) | J7: =SLOPE(R15!$AD$2:$AD$190,R15!$AE$2:$AE$190) | K7: =SLOPE(RD!$X$2:$X$252,RD!$Y$2:$Y$252) | L7: =RSQ(R15!$AD$2:$AD$190,R15!$AE$2:$AE$190) | M7: =RSQ(RD!$X$2:$X$252,RD!$Y$2:$Y$252) | N7: =COUNT(R1!$AD$2:$AD$2731) | O7: =COUNT(R15!$AD$2:$AD$190) | P7: =COUNT(RD!$X$2:$X$252) | Q7: =COUNTIF(R1!$AC$2:$AC$2731,1)/2730
A8: PLTD/PLTR | B8: PLTD | C8: PLTR | D8: =CORREL(R1!$AI$2:$AI$2731,R1!$AJ$2:$AJ$2731) | E8: =CORREL(R5!$AI$2:$AI$554,R5!$AJ$2:$AJ$554) | F8: =CORREL(R15!$AI$2:$AI$190,R15!$AJ$2:$AJ$190) | G8: =CORREL(RD!$AB$2:$AB$252,RD!$AC$2:$AC$252) | H8: =SLOPE(R1!$AI$2:$AI$2731,R1!$AJ$2:$AJ$2731) | I8: =SLOPE(R5!$AI$2:$AI$554,R5!$AJ$2:$AJ$554) | J8: =SLOPE(R15!$AI$2:$AI$190,R15!$AJ$2:$AJ$190) | K8: =SLOPE(RD!$AB$2:$AB$252,RD!$AC$2:$AC$252) | L8: =RSQ(R15!$AI$2:$AI$190,R15!$AJ$2:$AJ$190) | M8: =RSQ(RD!$AB$2:$AB$252,RD!$AC$2:$AC$252) | N8: =COUNT(R1!$AI$2:$AI$2731) | O8: =COUNT(R15!$AI$2:$AI$190) | P8: =COUNT(RD!$AB$2:$AB$252) | Q8: =COUNTIF(R1!$AH$2:$AH$2731,1)/2730

Sheet By Day
A1: Date | B1: ETF | C1: Underlying | D1: ρ 1m | E1: ρ 5m | F1: ρ 15m | G1: β 1m | H1: β 5m | I1: β 15m | J1: n 1m | K1: n 5m | L1: n 15m
A2: 46286 | B2: AVS | C2: AVGO | D2: =IFERROR(CORREL(R1!$E$2:$E$391,R1!$F$2:$F$391),"") | E2: =IFERROR(CORREL(R5!$E$2:$E$80,R5!$F$2:$F$80),"") | F2: =IFERROR(CORREL(R15!$E$2:$E$28,R15!$F$2:$F$28),"") | G2: =IFERROR(SLOPE(R1!$E$2:$E$391,R1!$F$2:$F$391),"") | H2: =IFERROR(SLOPE(R5!$E$2:$E$80,R5!$F$2:$F$80),"") | I2: =IFERROR(SLOPE(R15!$E$2:$E$28,R15!$F$2:$F$28),"") | J2: =COUNT(R1!$E$2:$E$391) | K2: =COUNT(R5!$E$2:$E$80) | L2: =COUNT(R15!$E$2:$E$28)
A3: 46286 | B3: AAPD | C3: AAPL | D3: =IFERROR(CORREL(R1!$J$2:$J$391,R1!$K$2:$K$391),"") | E3: =IFERROR(CORREL(R5!$J$2:$J$80,R5!$K$2:$K$80),"") | F3: =IFERROR(CORREL(R15!$J$2:$J$28,R15!$K$2:$K$28),"") | G3: =IFERROR(SLOPE(R1!$J$2:$J$391,R1!$K$2:$K$391),"") | H3: =IFERROR(SLOPE(R5!$J$2:$J$80,R5!$K$2:$K$80),"") | I3: =IFERROR(SLOPE(R15!$J$2:$J$28,R15!$K$2:$K$28),"") | J3: =COUNT(R1!$J$2:$J$391) | K3: =COUNT(R5!$J$2:$J$80) | L3: =COUNT(R15!$J$2:$J$28)
A4: 46286 | B4: METD | C4: META | D4: =IFERROR(CORREL(R1!$O$2:$O$391,R1!$P$2:$P$391),"") | E4: =IFERROR(CORREL(R5!$O$2:$O$80,R5!$P$2:$P$80),"") | F4: =IFERROR(CORREL(R15!$O$2:$O$28,R15!$P$2:$P$28),"") | G4: =IFERROR(SLOPE(R1!$O$2:$O$391,R1!$P$2:$P$391),"") | H4: =IFERROR(SLOPE(R5!$O$2:$O$80,R5!$P$2:$P$80),"") | I4: =IFERROR(SLOPE(R15!$O$2:$O$28,R15!$P$2:$P$28),"") | J4: =COUNT(R1!$O$2:$O$391) | K4: =COUNT(R5!$O$2:$O$80) | L4: =COUNT(R15!$O$2:$O$28)
A5: 46286 | B5: MSFD | C5: MSFT | D5: =IFERROR(CORREL(R1!$T$2:$T$391,R1!$U$2:$U$391),"") | E5: =IFERROR(CORREL(R5!$T$2:$T$80,R5!$U$2:$U$80),"") | F5: =IFERROR(CORREL(R15!$T$2:$T$28,R15!$U$2:$U$28),"") | G5: =IFERROR(SLOPE(R1!$T$2:$T$391,R1!$U$2:$U$391),"") | H5: =IFERROR(SLOPE(R5!$T$2:$T$80,R5!$U$2:$U$80),"") | I5: =IFERROR(SLOPE(R15!$T$2:$T$28,R15!$U$2:$U$28),"") | J5: =COUNT(R1!$T$2:$T$391) | K5: =COUNT(R5!$T$2:$T$80) | L5: =COUNT(R15!$T$2:$T$28)
A6: 46286 | B6: SPDN | C6: SPX | D6: =IFERROR(CORREL(R1!$Y$2:$Y$391,R1!$Z$2:$Z$391),"") | E6: =IFERROR(CORREL(R5!$Y$2:$Y$80,R5!$Z$2:$Z$80),"") | F6: =IFERROR(CORREL(R15!$Y$2:$Y$28,R15!$Z$2:$Z$28),"") | G6: =IFERROR(SLOPE(R1!$Y$2:$Y$391,R1!$Z$2:$Z$391),"") | H6: =IFERROR(SLOPE(R5!$Y$2:$Y$80,R5!$Z$2:$Z$80),"") | I6: =IFERROR(SLOPE(R15!$Y$2:$Y$28,R15!$Z$2:$Z$28),"") | J6: =COUNT(R1!$Y$2:$Y$391) | K6: =COUNT(R5!$Y$2:$Y$80) | L6: =COUNT(R15!$Y$2:$Y$28)
A7: 46286 | B7: AMZD | C7: AMZN | D7: =IFERROR(CORREL(R1!$AD$2:$AD$391,R1!$AE$2:$AE$391),"") | E7: =IFERROR(CORREL(R5!$AD$2:$AD$80,R5!$AE$2:$AE$80),"") | F7: =IFERROR(CORREL(R15!$AD$2:$AD$28,R15!$AE$2:$AE$28),"") | G7: =IFERROR(SLOPE(R1!$AD$2:$AD$391,R1!$AE$2:$AE$391),"") | H7: =IFERROR(SLOPE(R5!$AD$2:$AD$80,R5!$AE$2:$AE$80),"") | I7: =IFERROR(SLOPE(R15!$AD$2:$AD$28,R15!$AE$2:$AE$28),"") | J7: =COUNT(R1!$AD$2:$AD$391) | K7: =COUNT(R5!$AD$2:$AD$80) | L7: =COUNT(R15!$AD$2:$AD$28)
A8: 46286 | B8: PLTD | C8: PLTR | D8: =IFERROR(CORREL(R1!$AI$2:$AI$391,R1!$AJ$2:$AJ$391),"") | E8: =IFERROR(CORREL(R5!$AI$2:$AI$80,R5!$AJ$2:$AJ$80),"") | F8: =IFERROR(CORREL(R15!$AI$2:$AI$28,R15!$AJ$2:$AJ$28),"") | G8: =IFERROR(SLOPE(R1!$AI$2:$AI$391,R1!$AJ$2:$AJ$391),"") | H8: =IFERROR(SLOPE(R5!$AI$2:$AI$80,R5!$AJ$2:$AJ$80),"") | I8: =IFERROR(SLOPE(R15!$AI$2:$AI$28,R15!$AJ$2:$AJ$28),"") | J8: =COUNT(R1!$AI$2:$AI$391) | K8: =COUNT(R5!$AI$2:$AI$80) | L8: =COUNT(R15!$AI$2:$AI$28)
A9: 46287 | B9: AVS | C9: AVGO | D9: =IFERROR(CORREL(R1!$E$392:$E$781,R1!$F$392:$F$781),"") | E9: =IFERROR(CORREL(R5!$E$81:$E$159,R5!$F$81:$F$159),"") | F9: =IFERROR(CORREL(R15!$E$29:$E$55,R15!$F$29:$F$55),"") | G9: =IFERROR(SLOPE(R1!$E$392:$E$781,R1!$F$392:$F$781),"") | H9: =IFERROR(SLOPE(R5!$E$81:$E$159,R5!$F$81:$F$159),"") | I9: =IFERROR(SLOPE(R15!$E$29:$E$55,R15!$F$29:$F$55),"") | J9: =COUNT(R1!$E$392:$E$781) | K9: =COUNT(R5!$E$81:$E$159) | L9: =COUNT(R15!$E$29:$E$55)
A10: 46287 | B10: AAPD | C10: AAPL | D10: =IFERROR(CORREL(R1!$J$392:$J$781,R1!$K$392:$K$781),"") | E10: =IFERROR(CORREL(R5!$J$81:$J$159,R5!$K$81:$K$159),"") | F10: =IFERROR(CORREL(R15!$J$29:$J$55,R15!$K$29:$K$55),"") | G10: =IFERROR(SLOPE(R1!$J$392:$J$781,R1!$K$392:$K$781),"") | H10: =IFERROR(SLOPE(R5!$J$81:$J$159,R5!$K$81:$K$159),"") | I10: =IFERROR(SLOPE(R15!$J$29:$J$55,R15!$K$29:$K$55),"") | J10: =COUNT(R1!$J$392:$J$781) | K10: =COUNT(R5!$J$81:$J$159) | L10: =COUNT(R15!$J$29:$J$55)
A11: 46287 | B11: METD | C11: META | D11: =IFERROR(CORREL(R1!$O$392:$O$781,R1!$P$392:$P$781),"") | E11: =IFERROR(CORREL(R5!$O$81:$O$159,R5!$P$81:$P$159),"") | F11: =IFERROR(CORREL(R15!$O$29:$O$55,R15!$P$29:$P$55),"") | G11: =IFERROR(SLOPE(R1!$O$392:$O$781,R1!$P$392:$P$781),"") | H11: =IFERROR(SLOPE(R5!$O$81:$O$159,R5!$P$81:$P$159),"") | I11: =IFERROR(SLOPE(R15!$O$29:$O$55,R15!$P$29:$P$55),"") | J11: =COUNT(R1!$O$392:$O$781) | K11: =COUNT(R5!$O$81:$O$159) | L11: =COUNT(R15!$O$29:$O$55)
A12: 46287 | B12: MSFD | C12: MSFT | D12: =IFERROR(CORREL(R1!$T$392:$T$781,R1!$U$392:$U$781),"") | E12: =IFERROR(CORREL(R5!$T$81:$T$159,R5!$U$81:$U$159),"") | F12: =IFERROR(CORREL(R15!$T$29:$T$55,R15!$U$29:$U$55),"") | G12: =IFERROR(SLOPE(R1!$T$392:$T$781,R1!$U$392:$U$781),"") | H12: =IFERROR(SLOPE(R5!$T$81:$T$159,R5!$U$81:$U$159),"") | I12: =IFERROR(SLOPE(R15!$T$29:$T$55,R15!$U$29:$U$55),"") | J12: =COUNT(R1!$T$392:$T$781) | K12: =COUNT(R5!$T$81:$T$159) | L12: =COUNT(R15!$T$29:$T$55)
A13: 46287 | B13: SPDN | C13: SPX | D13: =IFERROR(CORREL(R1!$Y$392:$Y$781,R1!$Z$392:$Z$781),"") | E13: =IFERROR(CORREL(R5!$Y$81:$Y$159,R5!$Z$81:$Z$159),"") | F13: =IFERROR(CORREL(R15!$Y$29:$Y$55,R15!$Z$29:$Z$55),"") | G13: =IFERROR(SLOPE(R1!$Y$392:$Y$781,R1!$Z$392:$Z$781),"") | H13: =IFERROR(SLOPE(R5!$Y$81:$Y$159,R5!$Z$81:$Z$159),"") | I13: =IFERROR(SLOPE(R15!$Y$29:$Y$55,R15!$Z$29:$Z$55),"") | J13: =COUNT(R1!$Y$392:$Y$781) | K13: =COUNT(R5!$Y$81:$Y$159) | L13: =COUNT(R15!$Y$29:$Y$55)
A14: 46287 | B14: AMZD | C14: AMZN | D14: =IFERROR(CORREL(R1!$AD$392:$AD$781,R1!$AE$392:$AE$781),"") | E14: =IFERROR(CORREL(R5!$AD$81:$AD$159,R5!$AE$81:$AE$159),"") | F14: =IFERROR(CORREL(R15!$AD$29:$AD$55,R15!$AE$29:$AE$55),"") | G14: =IFERROR(SLOPE(R1!$AD$392:$AD$781,R1!$AE$392:$AE$781),"") | H14: =IFERROR(SLOPE(R5!$AD$81:$AD$159,R5!$AE$81:$AE$159),"") | I14: =IFERROR(SLOPE(R15!$AD$29:$AD$55,R15!$AE$29:$AE$55),"") | J14: =COUNT(R1!$AD$392:$AD$781) | K14: =COUNT(R5!$AD$81:$AD$159) | L14: =COUNT(R15!$AD$29:$AD$55)
A15: 46287 | B15: PLTD | C15: PLTR | D15: =IFERROR(CORREL(R1!$AI$392:$AI$781,R1!$AJ$392:$AJ$781),"") | E15: =IFERROR(CORREL(R5!$AI$81:$AI$159,R5!$AJ$81:$AJ$159),"") | F15: =IFERROR(CORREL(R15!$AI$29:$AI$55,R15!$AJ$29:$AJ$55),"") | G15: =IFERROR(SLOPE(R1!$AI$392:$AI$781,R1!$AJ$392:$AJ$781),"") | H15: =IFERROR(SLOPE(R5!$AI$81:$AI$159,R5!$AJ$81:$AJ$159),"") | I15: =IFERROR(SLOPE(R15!$AI$29:$AI$55,R15!$AJ$29:$AJ$55),"") | J15: =COUNT(R1!$AI$392:$AI$781) | K15: =COUNT(R5!$AI$81:$AI$159) | L15: =COUNT(R15!$AI$29:$AI$55)
A16: 46288 | B16: AVS | C16: AVGO | D16: =IFERROR(CORREL(R1!$E$782:$E$1171,R1!$F$782:$F$1171),"") | E16: =IFERROR(CORREL(R5!$E$160:$E$238,R5!$F$160:$F$238),"") | F16: =IFERROR(CORREL(R15!$E$56:$E$82,R15!$F$56:$F$82),"") | G16: =IFERROR(SLOPE(R1!$E$782:$E$1171,R1!$F$782:$F$1171),"") | H16: =IFERROR(SLOPE(R5!$E$160:$E$238,R5!$F$160:$F$238),"") | I16: =IFERROR(SLOPE(R15!$E$56:$E$82,R15!$F$56:$F$82),"") | J16: =COUNT(R1!$E$782:$E$1171) | K16: =COUNT(R5!$E$160:$E$238) | L16: =COUNT(R15!$E$56:$E$82)
A17: 46288 | B17: AAPD | C17: AAPL | D17: =IFERROR(CORREL(R1!$J$782:$J$1171,R1!$K$782:$K$1171),"") | E17: =IFERROR(CORREL(R5!$J$160:$J$238,R5!$K$160:$K$238),"") | F17: =IFERROR(CORREL(R15!$J$56:$J$82,R15!$K$56:$K$82),"") | G17: =IFERROR(SLOPE(R1!$J$782:$J$1171,R1!$K$782:$K$1171),"") | H17: =IFERROR(SLOPE(R5!$J$160:$J$238,R5!$K$160:$K$238),"") | I17: =IFERROR(SLOPE(R15!$J$56:$J$82,R15!$K$56:$K$82),"") | J17: =COUNT(R1!$J$782:$J$1171) | K17: =COUNT(R5!$J$160:$J$238) | L17: =COUNT(R15!$J$56:$J$82)
A18: 46288 | B18: METD | C18: META | D18: =IFERROR(CORREL(R1!$O$782:$O$1171,R1!$P$782:$P$1171),"") | E18: =IFERROR(CORREL(R5!$O$160:$O$238,R5!$P$160:$P$238),"") | F18: =IFERROR(CORREL(R15!$O$56:$O$82,R15!$P$56:$P$82),"") | G18: =IFERROR(SLOPE(R1!$O$782:$O$1171,R1!$P$782:$P$1171),"") | H18: =IFERROR(SLOPE(R5!$O$160:$O$238,R5!$P$160:$P$238),"") | I18: =IFERROR(SLOPE(R15!$O$56:$O$82,R15!$P$56:$P$82),"") | J18: =COUNT(R1!$O$782:$O$1171) | K18: =COUNT(R5!$O$160:$O$238) | L18: =COUNT(R15!$O$56:$O$82)
A19: 46288 | B19: MSFD | C19: MSFT | D19: =IFERROR(CORREL(R1!$T$782:$T$1171,R1!$U$782:$U$1171),"") | E19: =IFERROR(CORREL(R5!$T$160:$T$238,R5!$U$160:$U$238),"") | F19: =IFERROR(CORREL(R15!$T$56:$T$82,R15!$U$56:$U$82),"") | G19: =IFERROR(SLOPE(R1!$T$782:$T$1171,R1!$U$782:$U$1171),"") | H19: =IFERROR(SLOPE(R5!$T$160:$T$238,R5!$U$160:$U$238),"") | I19: =IFERROR(SLOPE(R15!$T$56:$T$82,R15!$U$56:$U$82),"") | J19: =COUNT(R1!$T$782:$T$1171) | K19: =COUNT(R5!$T$160:$T$238) | L19: =COUNT(R15!$T$56:$T$82)
A20: 46288 | B20: SPDN | C20: SPX | D20: =IFERROR(CORREL(R1!$Y$782:$Y$1171,R1!$Z$782:$Z$1171),"") | E20: =IFERROR(CORREL(R5!$Y$160:$Y$238,R5!$Z$160:$Z$238),"") | F20: =IFERROR(CORREL(R15!$Y$56:$Y$82,R15!$Z$56:$Z$82),"") | G20: =IFERROR(SLOPE(R1!$Y$782:$Y$1171,R1!$Z$782:$Z$1171),"") | H20: =IFERROR(SLOPE(R5!$Y$160:$Y$238,R5!$Z$160:$Z$238),"") | I20: =IFERROR(SLOPE(R15!$Y$56:$Y$82,R15!$Z$56:$Z$82),"") | J20: =COUNT(R1!$Y$782:$Y$1171) | K20: =COUNT(R5!$Y$160:$Y$238) | L20: =COUNT(R15!$Y$56:$Y$82)
A21: 46288 | B21: AMZD | C21: AMZN | D21: =IFERROR(CORREL(R1!$AD$782:$AD$1171,R1!$AE$782:$AE$1171),"") | E21: =IFERROR(CORREL(R5!$AD$160:$AD$238,R5!$AE$160:$AE$238),"") | F21: =IFERROR(CORREL(R15!$AD$56:$AD$82,R15!$AE$56:$AE$82),"") | G21: =IFERROR(SLOPE(R1!$AD$782:$AD$1171,R1!$AE$782:$AE$1171),"") | H21: =IFERROR(SLOPE(R5!$AD$160:$AD$238,R5!$AE$160:$AE$238),"") | I21: =IFERROR(SLOPE(R15!$AD$56:$AD$82,R15!$AE$56:$AE$82),"") | J21: =COUNT(R1!$AD$782:$AD$1171) | K21: =COUNT(R5!$AD$160:$AD$238) | L21: =COUNT(R15!$AD$56:$AD$82)
A22: 46288 | B22: PLTD | C22: PLTR | D22: =IFERROR(CORREL(R1!$AI$782:$AI$1171,R1!$AJ$782:$AJ$1171),"") | E22: =IFERROR(CORREL(R5!$AI$160:$AI$238,R5!$AJ$160:$AJ$238),"") | F22: =IFERROR(CORREL(R15!$AI$56:$AI$82,R15!$AJ$56:$AJ$82),"") | G22: =IFERROR(SLOPE(R1!$AI$782:$AI$1171,R1!$AJ$782:$AJ$1171),"") | H22: =IFERROR(SLOPE(R5!$AI$160:$AI$238,R5!$AJ$160:$AJ$238),"") | I22: =IFERROR(SLOPE(R15!$AI$56:$AI$82,R15!$AJ$56:$AJ$82),"") | J22: =COUNT(R1!$AI$782:$AI$1171) | K22: =COUNT(R5!$AI$160:$AI$238) | L22: =COUNT(R15!$AI$56:$AI$82)
A23: 46289 | B23: AVS | C23: AVGO | D23: =IFERROR(CORREL(R1!$E$1172:$E$1561,R1!$F$1172:$F$1561),"") | E23: =IFERROR(CORREL(R5!$E$239:$E$317,R5!$F$239:$F$317),"") | F23: =IFERROR(CORREL(R15!$E$83:$E$109,R15!$F$83:$F$109),"") | G23: =IFERROR(SLOPE(R1!$E$1172:$E$1561,R1!$F$1172:$F$1561),"") | H23: =IFERROR(SLOPE(R5!$E$239:$E$317,R5!$F$239:$F$317),"") | I23: =IFERROR(SLOPE(R15!$E$83:$E$109,R15!$F$83:$F$109),"") | J23: =COUNT(R1!$E$1172:$E$1561) | K23: =COUNT(R5!$E$239:$E$317) | L23: =COUNT(R15!$E$83:$E$109)
A24: 46289 | B24: AAPD | C24: AAPL | D24: =IFERROR(CORREL(R1!$J$1172:$J$1561,R1!$K$1172:$K$1561),"") | E24: =IFERROR(CORREL(R5!$J$239:$J$317,R5!$K$239:$K$317),"") | F24: =IFERROR(CORREL(R15!$J$83:$J$109,R15!$K$83:$K$109),"") | G24: =IFERROR(SLOPE(R1!$J$1172:$J$1561,R1!$K$1172:$K$1561),"") | H24: =IFERROR(SLOPE(R5!$J$239:$J$317,R5!$K$239:$K$317),"") | I24: =IFERROR(SLOPE(R15!$J$83:$J$109,R15!$K$83:$K$109),"") | J24: =COUNT(R1!$J$1172:$J$1561) | K24: =COUNT(R5!$J$239:$J$317) | L24: =COUNT(R15!$J$83:$J$109)
A25: 46289 | B25: METD | C25: META | D25: =IFERROR(CORREL(R1!$O$1172:$O$1561,R1!$P$1172:$P$1561),"") | E25: =IFERROR(CORREL(R5!$O$239:$O$317,R5!$P$239:$P$317),"") | F25: =IFERROR(CORREL(R15!$O$83:$O$109,R15!$P$83:$P$109),"") | G25: =IFERROR(SLOPE(R1!$O$1172:$O$1561,R1!$P$1172:$P$1561),"") | H25: =IFERROR(SLOPE(R5!$O$239:$O$317,R5!$P$239:$P$317),"") | I25: =IFERROR(SLOPE(R15!$O$83:$O$109,R15!$P$83:$P$109),"") | J25: =COUNT(R1!$O$1172:$O$1561) | K25: =COUNT(R5!$O$239:$O$317) | L25: =COUNT(R15!$O$83:$O$109)
A26: 46289 | B26: MSFD | C26: MSFT | D26: =IFERROR(CORREL(R1!$T$1172:$T$1561,R1!$U$1172:$U$1561),"") | E26: =IFERROR(CORREL(R5!$T$239:$T$317,R5!$U$239:$U$317),"") | F26: =IFERROR(CORREL(R15!$T$83:$T$109,R15!$U$83:$U$109),"") | G26: =IFERROR(SLOPE(R1!$T$1172:$T$1561,R1!$U$1172:$U$1561),"") | H26: =IFERROR(SLOPE(R5!$T$239:$T$317,R5!$U$239:$U$317),"") | I26: =IFERROR(SLOPE(R15!$T$83:$T$109,R15!$U$83:$U$109),"") | J26: =COUNT(R1!$T$1172:$T$1561) | K26: =COUNT(R5!$T$239:$T$317) | L26: =COUNT(R15!$T$83:$T$109)
A27: 46289 | B27: SPDN | C27: SPX | D27: =IFERROR(CORREL(R1!$Y$1172:$Y$1561,R1!$Z$1172:$Z$1561),"") | E27: =IFERROR(CORREL(R5!$Y$239:$Y$317,R5!$Z$239:$Z$317),"") | F27: =IFERROR(CORREL(R15!$Y$83:$Y$109,R15!$Z$83:$Z$109),"") | G27: =IFERROR(SLOPE(R1!$Y$1172:$Y$1561,R1!$Z$1172:$Z$1561),"") | H27: =IFERROR(SLOPE(R5!$Y$239:$Y$317,R5!$Z$239:$Z$317),"") | I27: =IFERROR(SLOPE(R15!$Y$83:$Y$109,R15!$Z$83:$Z$109),"") | J27: =COUNT(R1!$Y$1172:$Y$1561) | K27: =COUNT(R5!$Y$239:$Y$317) | L27: =COUNT(R15!$Y$83:$Y$109)
A28: 46289 | B28: AMZD | C28: AMZN | D28: =IFERROR(CORREL(R1!$AD$1172:$AD$1561,R1!$AE$1172:$AE$1561),"") | E28: =IFERROR(CORREL(R5!$AD$239:$AD$317,R5!$AE$239:$AE$317),"") | F28: =IFERROR(CORREL(R15!$AD$83:$AD$109,R15!$AE$83:$AE$109),"") | G28: =IFERROR(SLOPE(R1!$AD$1172:$AD$1561,R1!$AE$1172:$AE$1561),"") | H28: =IFERROR(SLOPE(R5!$AD$239:$AD$317,R5!$AE$239:$AE$317),"") | I28: =IFERROR(SLOPE(R15!$AD$83:$AD$109,R15!$AE$83:$AE$109),"") | J28: =COUNT(R1!$AD$1172:$AD$1561) | K28: =COUNT(R5!$AD$239:$AD$317) | L28: =COUNT(R15!$AD$83:$AD$109)
A29: 46289 | B29: PLTD | C29: PLTR | D29: =IFERROR(CORREL(R1!$AI$1172:$AI$1561,R1!$AJ$1172:$AJ$1561),"") | E29: =IFERROR(CORREL(R5!$AI$239:$AI$317,R5!$AJ$239:$AJ$317),"") | F29: =IFERROR(CORREL(R15!$AI$83:$AI$109,R15!$AJ$83:$AJ$109),"") | G29: =IFERROR(SLOPE(R1!$AI$1172:$AI$1561,R1!$AJ$1172:$AJ$1561),"") | H29: =IFERROR(SLOPE(R5!$AI$239:$AI$317,R5!$AJ$239:$AJ$317),"") | I29: =IFERROR(SLOPE(R15!$AI$83:$AI$109,R15!$AJ$83:$AJ$109),"") | J29: =COUNT(R1!$AI$1172:$AI$1561) | K29: =COUNT(R5!$AI$239:$AI$317) | L29: =COUNT(R15!$AI$83:$AI$109)
A30: 46290 | B30: AVS | C30: AVGO | D30: =IFERROR(CORREL(R1!$E$1562:$E$1951,R1!$F$1562:$F$1951),"") | E30: =IFERROR(CORREL(R5!$E$318:$E$396,R5!$F$318:$F$396),"") | F30: =IFERROR(CORREL(R15!$E$110:$E$136,R15!$F$110:$F$136),"") | G30: =IFERROR(SLOPE(R1!$E$1562:$E$1951,R1!$F$1562:$F$1951),"") | H30: =IFERROR(SLOPE(R5!$E$318:$E$396,R5!$F$318:$F$396),"") | I30: =IFERROR(SLOPE(R15!$E$110:$E$136,R15!$F$110:$F$136),"") | J30: =COUNT(R1!$E$1562:$E$1951) | K30: =COUNT(R5!$E$318:$E$396) | L30: =COUNT(R15!$E$110:$E$136)
A31: 46290 | B31: AAPD | C31: AAPL | D31: =IFERROR(CORREL(R1!$J$1562:$J$1951,R1!$K$1562:$K$1951),"") | E31: =IFERROR(CORREL(R5!$J$318:$J$396,R5!$K$318:$K$396),"") | F31: =IFERROR(CORREL(R15!$J$110:$J$136,R15!$K$110:$K$136),"") | G31: =IFERROR(SLOPE(R1!$J$1562:$J$1951,R1!$K$1562:$K$1951),"") | H31: =IFERROR(SLOPE(R5!$J$318:$J$396,R5!$K$318:$K$396),"") | I31: =IFERROR(SLOPE(R15!$J$110:$J$136,R15!$K$110:$K$136),"") | J31: =COUNT(R1!$J$1562:$J$1951) | K31: =COUNT(R5!$J$318:$J$396) | L31: =COUNT(R15!$J$110:$J$136)
A32: 46290 | B32: METD | C32: META | D32: =IFERROR(CORREL(R1!$O$1562:$O$1951,R1!$P$1562:$P$1951),"") | E32: =IFERROR(CORREL(R5!$O$318:$O$396,R5!$P$318:$P$396),"") | F32: =IFERROR(CORREL(R15!$O$110:$O$136,R15!$P$110:$P$136),"") | G32: =IFERROR(SLOPE(R1!$O$1562:$O$1951,R1!$P$1562:$P$1951),"") | H32: =IFERROR(SLOPE(R5!$O$318:$O$396,R5!$P$318:$P$396),"") | I32: =IFERROR(SLOPE(R15!$O$110:$O$136,R15!$P$110:$P$136),"") | J32: =COUNT(R1!$O$1562:$O$1951) | K32: =COUNT(R5!$O$318:$O$396) | L32: =COUNT(R15!$O$110:$O$136)
A33: 46290 | B33: MSFD | C33: MSFT | D33: =IFERROR(CORREL(R1!$T$1562:$T$1951,R1!$U$1562:$U$1951),"") | E33: =IFERROR(CORREL(R5!$T$318:$T$396,R5!$U$318:$U$396),"") | F33: =IFERROR(CORREL(R15!$T$110:$T$136,R15!$U$110:$U$136),"") | G33: =IFERROR(SLOPE(R1!$T$1562:$T$1951,R1!$U$1562:$U$1951),"") | H33: =IFERROR(SLOPE(R5!$T$318:$T$396,R5!$U$318:$U$396),"") | I33: =IFERROR(SLOPE(R15!$T$110:$T$136,R15!$U$110:$U$136),"") | J33: =COUNT(R1!$T$1562:$T$1951) | K33: =COUNT(R5!$T$318:$T$396) | L33: =COUNT(R15!$T$110:$T$136)
A34: 46290 | B34: SPDN | C34: SPX | D34: =IFERROR(CORREL(R1!$Y$1562:$Y$1951,R1!$Z$1562:$Z$1951),"") | E34: =IFERROR(CORREL(R5!$Y$318:$Y$396,R5!$Z$318:$Z$396),"") | F34: =IFERROR(CORREL(R15!$Y$110:$Y$136,R15!$Z$110:$Z$136),"") | G34: =IFERROR(SLOPE(R1!$Y$1562:$Y$1951,R1!$Z$1562:$Z$1951),"") | H34: =IFERROR(SLOPE(R5!$Y$318:$Y$396,R5!$Z$318:$Z$396),"") | I34: =IFERROR(SLOPE(R15!$Y$110:$Y$136,R15!$Z$110:$Z$136),"") | J34: =COUNT(R1!$Y$1562:$Y$1951) | K34: =COUNT(R5!$Y$318:$Y$396) | L34: =COUNT(R15!$Y$110:$Y$136)
A35: 46290 | B35: AMZD | C35: AMZN | D35: =IFERROR(CORREL(R1!$AD$1562:$AD$1951,R1!$AE$1562:$AE$1951),"") | E35: =IFERROR(CORREL(R5!$AD$318:$AD$396,R5!$AE$318:$AE$396),"") | F35: =IFERROR(CORREL(R15!$AD$110:$AD$136,R15!$AE$110:$AE$136),"") | G35: =IFERROR(SLOPE(R1!$AD$1562:$AD$1951,R1!$AE$1562:$AE$1951),"") | H35: =IFERROR(SLOPE(R5!$AD$318:$AD$396,R5!$AE$318:$AE$396),"") | I35: =IFERROR(SLOPE(R15!$AD$110:$AD$136,R15!$AE$110:$AE$136),"") | J35: =COUNT(R1!$AD$1562:$AD$1951) | K35: =COUNT(R5!$AD$318:$AD$396) | L35: =COUNT(R15!$AD$110:$AD$136)
A36: 46290 | B36: PLTD | C36: PLTR | D36: =IFERROR(CORREL(R1!$AI$1562:$AI$1951,R1!$AJ$1562:$AJ$1951),"") | E36: =IFERROR(CORREL(R5!$AI$318:$AI$396,R5!$AJ$318:$AJ$396),"") | F36: =IFERROR(CORREL(R15!$AI$110:$AI$136,R15!$AJ$110:$AJ$136),"") | G36: =IFERROR(SLOPE(R1!$AI$1562:$AI$1951,R1!$AJ$1562:$AJ$1951),"") | H36: =IFERROR(SLOPE(R5!$AI$318:$AI$396,R5!$AJ$318:$AJ$396),"") | I36: =IFERROR(SLOPE(R15!$AI$110:$AI$136,R15!$AJ$110:$AJ$136),"") | J36: =COUNT(R1!$AI$1562:$AI$1951) | K36: =COUNT(R5!$AI$318:$AI$396) | L36: =COUNT(R15!$AI$110:$AI$136)
A37: 46293 | B37: AVS | C37: AVGO | D37: =IFERROR(CORREL(R1!$E$1952:$E$2341,R1!$F$1952:$F$2341),"") | E37: =IFERROR(CORREL(R5!$E$397:$E$475,R5!$F$397:$F$475),"") | F37: =IFERROR(CORREL(R15!$E$137:$E$163,R15!$F$137:$F$163),"") | G37: =IFERROR(SLOPE(R1!$E$1952:$E$2341,R1!$F$1952:$F$2341),"") | H37: =IFERROR(SLOPE(R5!$E$397:$E$475,R5!$F$397:$F$475),"") | I37: =IFERROR(SLOPE(R15!$E$137:$E$163,R15!$F$137:$F$163),"") | J37: =COUNT(R1!$E$1952:$E$2341) | K37: =COUNT(R5!$E$397:$E$475) | L37: =COUNT(R15!$E$137:$E$163)
A38: 46293 | B38: AAPD | C38: AAPL | D38: =IFERROR(CORREL(R1!$J$1952:$J$2341,R1!$K$1952:$K$2341),"") | E38: =IFERROR(CORREL(R5!$J$397:$J$475,R5!$K$397:$K$475),"") | F38: =IFERROR(CORREL(R15!$J$137:$J$163,R15!$K$137:$K$163),"") | G38: =IFERROR(SLOPE(R1!$J$1952:$J$2341,R1!$K$1952:$K$2341),"") | H38: =IFERROR(SLOPE(R5!$J$397:$J$475,R5!$K$397:$K$475),"") | I38: =IFERROR(SLOPE(R15!$J$137:$J$163,R15!$K$137:$K$163),"") | J38: =COUNT(R1!$J$1952:$J$2341) | K38: =COUNT(R5!$J$397:$J$475) | L38: =COUNT(R15!$J$137:$J$163)
A39: 46293 | B39: METD | C39: META | D39: =IFERROR(CORREL(R1!$O$1952:$O$2341,R1!$P$1952:$P$2341),"") | E39: =IFERROR(CORREL(R5!$O$397:$O$475,R5!$P$397:$P$475),"") | F39: =IFERROR(CORREL(R15!$O$137:$O$163,R15!$P$137:$P$163),"") | G39: =IFERROR(SLOPE(R1!$O$1952:$O$2341,R1!$P$1952:$P$2341),"") | H39: =IFERROR(SLOPE(R5!$O$397:$O$475,R5!$P$397:$P$475),"") | I39: =IFERROR(SLOPE(R15!$O$137:$O$163,R15!$P$137:$P$163),"") | J39: =COUNT(R1!$O$1952:$O$2341) | K39: =COUNT(R5!$O$397:$O$475) | L39: =COUNT(R15!$O$137:$O$163)
A40: 46293 | B40: MSFD | C40: MSFT | D40: =IFERROR(CORREL(R1!$T$1952:$T$2341,R1!$U$1952:$U$2341),"") | E40: =IFERROR(CORREL(R5!$T$397:$T$475,R5!$U$397:$U$475),"") | F40: =IFERROR(CORREL(R15!$T$137:$T$163,R15!$U$137:$U$163),"") | G40: =IFERROR(SLOPE(R1!$T$1952:$T$2341,R1!$U$1952:$U$2341),"") | H40: =IFERROR(SLOPE(R5!$T$397:$T$475,R5!$U$397:$U$475),"") | I40: =IFERROR(SLOPE(R15!$T$137:$T$163,R15!$U$137:$U$163),"") | J40: =COUNT(R1!$T$1952:$T$2341) | K40: =COUNT(R5!$T$397:$T$475) | L40: =COUNT(R15!$T$137:$T$163)
...

Sheet 1m Matrix
A1: ETF | B1: Underlying | C1: 46286 | D1: 46287 | E1: 46288 | F1: 46289 | G1: 46290 | H1: 46293 | I1: 46294
A2: AVS | B2: AVGO | C2: ='By Day'!D2 | D2: ='By Day'!D9 | E2: ='By Day'!D16 | F2: ='By Day'!D23 | G2: ='By Day'!D30 | H2: ='By Day'!D37 | I2: ='By Day'!D44
A3: AAPD | B3: AAPL | C3: ='By Day'!D3 | D3: ='By Day'!D10 | E3: ='By Day'!D17 | F3: ='By Day'!D24 | G3: ='By Day'!D31 | H3: ='By Day'!D38 | I3: ='By Day'!D45
A4: METD | B4: META | C4: ='By Day'!D4 | D4: ='By Day'!D11 | E4: ='By Day'!D18 | F4: ='By Day'!D25 | G4: ='By Day'!D32 | H4: ='By Day'!D39 | I4: ='By Day'!D46
A5: MSFD | B5: MSFT | C5: ='By Day'!D5 | D5: ='By Day'!D12 | E5: ='By Day'!D19 | F5: ='By Day'!D26 | G5: ='By Day'!D33 | H5: ='By Day'!D40 | I5: ='By Day'!D47
A6: SPDN | B6: SPX | C6: ='By Day'!D6 | D6: ='By Day'!D13 | E6: ='By Day'!D20 | F6: ='By Day'!D27 | G6: ='By Day'!D34 | H6: ='By Day'!D41 | I6: ='By Day'!D48
A7: AMZD | B7: AMZN | C7: ='By Day'!D7 | D7: ='By Day'!D14 | E7: ='By Day'!D21 | F7: ='By Day'!D28 | G7: ='By Day'!D35 | H7: ='By Day'!D42 | I7: ='By Day'!D49
A8: PLTD | B8: PLTR | C8: ='By Day'!D8 | D8: ='By Day'!D15 | E8: ='By Day'!D22 | F8: ='By Day'!D29 | G8: ='By Day'!D36 | H8: ='By Day'!D43 | I8: ='By Day'!D50

Sheet 5m Matrix
A1: ETF | B1: Underlying | C1: 46286 | D1: 46287 | E1: 46288 | F1: 46289 | G1: 46290 | H1: 46293 | I1: 46294
A2: AVS | B2: AVGO | C2: ='By Day'!E2 | D2: ='By Day'!E9 | E2: ='By Day'!E16 | F2: ='By Day'!E23 | G2: ='By Day'!E30 | H2: ='By Day'!E37 | I2: ='By Day'!E44
A3: AAPD | B3: AAPL | C3: ='By Day'!E3 | D3: ='By Day'!E10 | E3: ='By Day'!E17 | F3: ='By Day'!E24 | G3: ='By Day'!E31 | H3: ='By Day'!E38 | I3: ='By Day'!E45
A4: METD | B4: META | C4: ='By Day'!E4 | D4: ='By Day'!E11 | E4: ='By Day'!E18 | F4: ='By Day'!E25 | G4: ='By Day'!E32 | H4: ='By Day'!E39 | I4: ='By Day'!E46
A5: MSFD | B5: MSFT | C5: ='By Day'!E5 | D5: ='By Day'!E12 | E5: ='By Day'!E19 | F5: ='By Day'!E26 | G5: ='By Day'!E33 | H5: ='By Day'!E40 | I5: ='By Day'!E47
A6: SPDN | B6: SPX | C6: ='By Day'!E6 | D6: ='By Day'!E13 | E6: ='By Day'!E20 | F6: ='By Day'!E27 | G6: ='By Day'!E34 | H6: ='By Day'!E41 | I6: ='By Day'!E48
A7: AMZD | B7: AMZN | C7: ='By Day'!E7 | D7: ='By Day'!E14 | E7: ='By Day'!E21 | F7: ='By Day'!E28 | G7: ='By Day'!E35 | H7: ='By Day'!E42 | I7: ='By Day'!E49
A8: PLTD | B8: PLTR | C8: ='By Day'!E8 | D8: ='By Day'!E15 | E8: ='By Day'!E22 | F8: ='By Day'!E29 | G8: ='By Day'!E36 | H8: ='By Day'!E43 | I8: ='By Day'!E50

Sheet 15m Matrix
A1: ETF | B1: Underlying | C1: 46286 | D1: 46287 | E1: 46288 | F1: 46289 | G1: 46290 | H1: 46293 | I1: 46294
A2: AVS | B2: AVGO | C2: ='By Day'!F2 | D2: ='By Day'!F9 | E2: ='By Day'!F16 | F2: ='By Day'!F23 | G2: ='By Day'!F30 | H2: ='By Day'!F37 | I2: ='By Day'!F44
A3: AAPD | B3: AAPL | C3: ='By Day'!F3 | D3: ='By Day'!F10 | E3: ='By Day'!F17 | F3: ='By Day'!F24 | G3: ='By Day'!F31 | H3: ='By Day'!F38 | I3: ='By Day'!F45
A4: METD | B4: META | C4: ='By Day'!F4 | D4: ='By Day'!F11 | E4: ='By Day'!F18 | F4: ='By Day'!F25 | G4: ='By Day'!F32 | H4: ='By Day'!F39 | I4: ='By Day'!F46
A5: MSFD | B5: MSFT | C5: ='By Day'!F5 | D5: ='By Day'!F12 | E5: ='By Day'!F19 | F5: ='By Day'!F26 | G5: ='By Day'!F33 | H5: ='By Day'!F40 | I5: ='By Day'!F47
A6: SPDN | B6: SPX | C6: ='By Day'!F6 | D6: ='By Day'!F13 | E6: ='By Day'!F20 | F6: ='By Day'!F27 | G6: ='By Day'!F34 | H6: ='By Day'!F41 | I6: ='By Day'!F48
A7: AMZD | B7: AMZN | C7: ='By Day'!F7 | D7: ='By Day'!F14 | E7: ='By Day'!F21 | F7: ='By Day'!F28 | G7: ='By Day'!F35 | H7: ='By Day'!F42 | I7: ='By Day'!F49
A8: PLTD | B8: PLTR | C8: ='By Day'!F8 | D8: ='By Day'!F15 | E8: ='By Day'!F22 | F8: ='By Day'!F29 | G8: ='By Day'!F36 | H8: ='By Day'!F43 | I8: ='By Day'!F50

Sheet Epps
A1: ρ | B1: 1 | C1: 2 | D1: 3 | E1: 5 | F1: 10 | G1: 15 | H1: 30 | I1: 60
A2: AVS/AVGO | B2: =CORREL(R1!$E$2:$E$2731,R1!$F$2:$F$2731) | C2: =CORREL(R2!$E$2:$E$1373,R2!$F$2:$F$1373) | D2: =CORREL(R3!$E$2:$E$918,R3!$F$2:$F$918) | E2: =CORREL(R5!$E$2:$E$554,R5!$F$2:$F$554) | F2: =CORREL(R10!$E$2:$E$281,R10!$F$2:$F$281) | G2: =CORREL(R15!$E$2:$E$190,R15!$F$2:$F$190) | H2: =CORREL(R30!$E$2:$E$99,R30!$F$2:$F$99) | I2: =CORREL(R60!$E$2:$E$57,R60!$F$2:$F$57)
A3: AAPD/AAPL | B3: =CORREL(R1!$J$2:$J$2731,R1!$K$2:$K$2731) | C3: =CORREL(R2!$J$2:$J$1373,R2!$K$2:$K$1373) | D3: =CORREL(R3!$J$2:$J$918,R3!$K$2:$K$918) | E3: =CORREL(R5!$J$2:$J$554,R5!$K$2:$K$554) | F3: =CORREL(R10!$J$2:$J$281,R10!$K$2:$K$281) | G3: =CORREL(R15!$J$2:$J$190,R15!$K$2:$K$190) | H3: =CORREL(R30!$J$2:$J$99,R30!$K$2:$K$99) | I3: =CORREL(R60!$J$2:$J$57,R60!$K$2:$K$57)
A4: METD/META | B4: =CORREL(R1!$O$2:$O$2731,R1!$P$2:$P$2731) | C4: =CORREL(R2!$O$2:$O$1373,R2!$P$2:$P$1373) | D4: =CORREL(R3!$O$2:$O$918,R3!$P$2:$P$918) | E4: =CORREL(R5!$O$2:$O$554,R5!$P$2:$P$554) | F4: =CORREL(R10!$O$2:$O$281,R10!$P$2:$P$281) | G4: =CORREL(R15!$O$2:$O$190,R15!$P$2:$P$190) | H4: =CORREL(R30!$O$2:$O$99,R30!$P$2:$P$99) | I4: =CORREL(R60!$O$2:$O$57,R60!$P$2:$P$57)
A5: MSFD/MSFT | B5: =CORREL(R1!$T$2:$T$2731,R1!$U$2:$U$2731) | C5: =CORREL(R2!$T$2:$T$1373,R2!$U$2:$U$1373) | D5: =CORREL(R3!$T$2:$T$918,R3!$U$2:$U$918) | E5: =CORREL(R5!$T$2:$T$554,R5!$U$2:$U$554) | F5: =CORREL(R10!$T$2:$T$281,R10!$U$2:$U$281) | G5: =CORREL(R15!$T$2:$T$190,R15!$U$2:$U$190) | H5: =CORREL(R30!$T$2:$T$99,R30!$U$2:$U$99) | I5: =CORREL(R60!$T$2:$T$57,R60!$U$2:$U$57)
A6: SPDN/SPX | B6: =CORREL(R1!$Y$2:$Y$2731,R1!$Z$2:$Z$2731) | C6: =CORREL(R2!$Y$2:$Y$1373,R2!$Z$2:$Z$1373) | D6: =CORREL(R3!$Y$2:$Y$918,R3!$Z$2:$Z$918) | E6: =CORREL(R5!$Y$2:$Y$554,R5!$Z$2:$Z$554) | F6: =CORREL(R10!$Y$2:$Y$281,R10!$Z$2:$Z$281) | G6: =CORREL(R15!$Y$2:$Y$190,R15!$Z$2:$Z$190) | H6: =CORREL(R30!$Y$2:$Y$99,R30!$Z$2:$Z$99) | I6: =CORREL(R60!$Y$2:$Y$57,R60!$Z$2:$Z$57)
A7: AMZD/AMZN | B7: =CORREL(R1!$AD$2:$AD$2731,R1!$AE$2:$AE$2731) | C7: =CORREL(R2!$AD$2:$AD$1373,R2!$AE$2:$AE$1373) | D7: =CORREL(R3!$AD$2:$AD$918,R3!$AE$2:$AE$918) | E7: =CORREL(R5!$AD$2:$AD$554,R5!$AE$2:$AE$554) | F7: =CORREL(R10!$AD$2:$AD$281,R10!$AE$2:$AE$281) | G7: =CORREL(R15!$AD$2:$AD$190,R15!$AE$2:$AE$190) | H7: =CORREL(R30!$AD$2:$AD$99,R30!$AE$2:$AE$99) | I7: =CORREL(R60!$AD$2:$AD$57,R60!$AE$2:$AE$57)
A8: PLTD/PLTR | B8: =CORREL(R1!$AI$2:$AI$2731,R1!$AJ$2:$AJ$2731) | C8: =CORREL(R2!$AI$2:$AI$1373,R2!$AJ$2:$AJ$1373) | D8: =CORREL(R3!$AI$2:$AI$918,R3!$AJ$2:$AJ$918) | E8: =CORREL(R5!$AI$2:$AI$554,R5!$AJ$2:$AJ$554) | F8: =CORREL(R10!$AI$2:$AI$281,R10!$AJ$2:$AJ$281) | G8: =CORREL(R15!$AI$2:$AI$190,R15!$AJ$2:$AJ$190) | H8: =CORREL(R30!$AI$2:$AI$99,R30!$AJ$2:$AJ$99) | I8: =CORREL(R60!$AI$2:$AI$57,R60!$AJ$2:$AJ$57)
A10: β | B10: 1 | C10: 2 | D10: 3 | E10: 5 | F10: 10 | G10: 15 | H10: 30 | I10: 60
A11: AVS/AVGO | B11: =SLOPE(R1!$E$2:$E$2731,R1!$F$2:$F$2731) | C11: =SLOPE(R2!$E$2:$E$1373,R2!$F$2:$F$1373) | D11: =SLOPE(R3!$E$2:$E$918,R3!$F$2:$F$918) | E11: =SLOPE(R5!$E$2:$E$554,R5!$F$2:$F$554) | F11: =SLOPE(R10!$E$2:$E$281,R10!$F$2:$F$281) | G11: =SLOPE(R15!$E$2:$E$190,R15!$F$2:$F$190) | H11: =SLOPE(R30!$E$2:$E$99,R30!$F$2:$F$99) | I11: =SLOPE(R60!$E$2:$E$57,R60!$F$2:$F$57)
A12: AAPD/AAPL | B12: =SLOPE(R1!$J$2:$J$2731,R1!$K$2:$K$2731) | C12: =SLOPE(R2!$J$2:$J$1373,R2!$K$2:$K$1373) | D12: =SLOPE(R3!$J$2:$J$918,R3!$K$2:$K$918) | E12: =SLOPE(R5!$J$2:$J$554,R5!$K$2:$K$554) | F12: =SLOPE(R10!$J$2:$J$281,R10!$K$2:$K$281) | G12: =SLOPE(R15!$J$2:$J$190,R15!$K$2:$K$190) | H12: =SLOPE(R30!$J$2:$J$99,R30!$K$2:$K$99) | I12: =SLOPE(R60!$J$2:$J$57,R60!$K$2:$K$57)
A13: METD/META | B13: =SLOPE(R1!$O$2:$O$2731,R1!$P$2:$P$2731) | C13: =SLOPE(R2!$O$2:$O$1373,R2!$P$2:$P$1373) | D13: =SLOPE(R3!$O$2:$O$918,R3!$P$2:$P$918) | E13: =SLOPE(R5!$O$2:$O$554,R5!$P$2:$P$554) | F13: =SLOPE(R10!$O$2:$O$281,R10!$P$2:$P$281) | G13: =SLOPE(R15!$O$2:$O$190,R15!$P$2:$P$190) | H13: =SLOPE(R30!$O$2:$O$99,R30!$P$2:$P$99) | I13: =SLOPE(R60!$O$2:$O$57,R60!$P$2:$P$57)
A14: MSFD/MSFT | B14: =SLOPE(R1!$T$2:$T$2731,R1!$U$2:$U$2731) | C14: =SLOPE(R2!$T$2:$T$1373,R2!$U$2:$U$1373) | D14: =SLOPE(R3!$T$2:$T$918,R3!$U$2:$U$918) | E14: =SLOPE(R5!$T$2:$T$554,R5!$U$2:$U$554) | F14: =SLOPE(R10!$T$2:$T$281,R10!$U$2:$U$281) | G14: =SLOPE(R15!$T$2:$T$190,R15!$U$2:$U$190) | H14: =SLOPE(R30!$T$2:$T$99,R30!$U$2:$U$99) | I14: =SLOPE(R60!$T$2:$T$57,R60!$U$2:$U$57)
A15: SPDN/SPX | B15: =SLOPE(R1!$Y$2:$Y$2731,R1!$Z$2:$Z$2731) | C15: =SLOPE(R2!$Y$2:$Y$1373,R2!$Z$2:$Z$1373) | D15: =SLOPE(R3!$Y$2:$Y$918,R3!$Z$2:$Z$918) | E15: =SLOPE(R5!$Y$2:$Y$554,R5!$Z$2:$Z$554) | F15: =SLOPE(R10!$Y$2:$Y$281,R10!$Z$2:$Z$281) | G15: =SLOPE(R15!$Y$2:$Y$190,R15!$Z$2:$Z$190) | H15: =SLOPE(R30!$Y$2:$Y$99,R30!$Z$2:$Z$99) | I15: =SLOPE(R60!$Y$2:$Y$57,R60!$Z$2:$Z$57)
A16: AMZD/AMZN | B16: =SLOPE(R1!$AD$2:$AD$2731,R1!$AE$2:$AE$2731) | C16: =SLOPE(R2!$AD$2:$AD$1373,R2!$AE$2:$AE$1373) | D16: =SLOPE(R3!$AD$2:$AD$918,R3!$AE$2:$AE$918) | E16: =SLOPE(R5!$AD$2:$AD$554,R5!$AE$2:$AE$554) | F16: =SLOPE(R10!$AD$2:$AD$281,R10!$AE$2:$AE$281) | G16: =SLOPE(R15!$AD$2:$AD$190,R15!$AE$2:$AE$190) | H16: =SLOPE(R30!$AD$2:$AD$99,R30!$AE$2:$AE$99) | I16: =SLOPE(R60!$AD$2:$AD$57,R60!$AE$2:$AE$57)
A17: PLTD/PLTR | B17: =SLOPE(R1!$AI$2:$AI$2731,R1!$AJ$2:$AJ$2731) | C17: =SLOPE(R2!$AI$2:$AI$1373,R2!$AJ$2:$AJ$1373) | D17: =SLOPE(R3!$AI$2:$AI$918,R3!$AJ$2:$AJ$918) | E17: =SLOPE(R5!$AI$2:$AI$554,R5!$AJ$2:$AJ$554) | F17: =SLOPE(R10!$AI$2:$AI$281,R10!$AJ$2:$AJ$281) | G17: =SLOPE(R15!$AI$2:$AI$190,R15!$AJ$2:$AJ$190) | H17: =SLOPE(R30!$AI$2:$AI$99,R30!$AJ$2:$AJ$99) | I17: =SLOPE(R60!$AI$2:$AI$57,R60!$AJ$2:$AJ$57)

Sheet Data Quality
A1: Symbol | B1: 1m bars traded | C1: of possible | D1: % of minutes traded | E1: median volume / traded min | F1: last price | G1: tick (bps) | H1: σ per minute (bps) | I1: tick / σ | J1: zero returns
A2: AVS | B2: 1687 | C2: 2730 | D2: =B2/C2 | E2: 22180 | F2: 8.1549997 | G2: =0.01/F2*10000 | H2: =SQRT(SUMSQ(R1!$E$2:$E$2731)/2723)*10000 | I2: =G2/H2 | J2: =COUNTIF(R1!$E$2:$E$2731,0)/COUNT(R1!$E$2:$E$2731)
A3: AVGO | B3: 2730 | C3: 2730 | D3: =B3/C3 | E3: 26031 | F3: 355.17999 | H3: =SQRT(SUMSQ(R1!$F$2:$F$2731)/2723)*10000 | J3: =COUNTIF(R1!$F$2:$F$2731,0)/COUNT(R1!$F$2:$F$2731)
A4: AAPD | B4: 1636 | C4: 2730 | D4: =B4/C4 | E4: 14934 | F4: 10.405 | G4: =0.01/F4*10000 | H4: =SQRT(SUMSQ(R1!$J$2:$J$2731)/2723)*10000 | I4: =G4/H4 | J4: =COUNTIF(R1!$J$2:$J$2731,0)/COUNT(R1!$J$2:$J$2731)
A5: AAPL | B5: 2730 | C5: 2730 | D5: =B5/C5 | E5: 42881 | F5: 329.59 | H5: =SQRT(SUMSQ(R1!$K$2:$K$2731)/2723)*10000 | J5: =COUNTIF(R1!$K$2:$K$2731,0)/COUNT(R1!$K$2:$K$2731)
A6: METD | B6: 1914 | C6: 2730 | D6: =B6/C6 | E6: 2917.5 | F6: 12.585 | G6: =0.01/F6*10000 | H6: =SQRT(SUMSQ(R1!$O$2:$O$2731)/2723)*10000 | I6: =G6/H6 | J6: =COUNTIF(R1!$O$2:$O$2731,0)/COUNT(R1!$O$2:$O$2731)
A7: META | B7: 2730 | C7: 2730 | D7: =B7/C7 | E7: 46985 | F7: 739.02002 | H7: =SQRT(SUMSQ(R1!$P$2:$P$2731)/2723)*10000 | J7: =COUNTIF(R1!$P$2:$P$2731,0)/COUNT(R1!$P$2:$P$2731)
A8: MSFD | B8: 967 | C8: 2730 | D8: =B8/C8 | E8: 6984 | F8: 10.05 | G8: =0.01/F8*10000 | H8: =SQRT(SUMSQ(R1!$T$2:$T$2731)/2723)*10000 | I8: =G8/H8 | J8: =COUNTIF(R1!$T$2:$T$2731,0)/COUNT(R1!$T$2:$T$2731)
A9: MSFT | B9: 2730 | C9: 2730 | D9: =B9/C9 | E9: 28650.5 | F9: 509.04001 | H9: =SQRT(SUMSQ(R1!$U$2:$U$2731)/2723)*10000 | J9: =COUNTIF(R1!$U$2:$U$2731,0)/COUNT(R1!$U$2:$U$2731)
A10: SPDN | B10: 1959 | C10: 2730 | D10: =B10/C10 | E10: 12000 | F10: 8.4700003 | G10: =0.01/F10*10000 | H10: =SQRT(SUMSQ(R1!$Y$2:$Y$2731)/2723)*10000 | I10: =G10/H10 | J10: =COUNTIF(R1!$Y$2:$Y$2731,0)/COUNT(R1!$Y$2:$Y$2731)
A11: SPX | B11: 2730 | C11: 2730 | D11: =B11/C11 | E11: 4831006.5 | F11: 7671.8501 | H11: =SQRT(SUMSQ(R1!$Z$2:$Z$2731)/2723)*10000 | J11: =COUNTIF(R1!$Z$2:$Z$2731,0)/COUNT(R1!$Z$2:$Z$2731)
A12: AMZD | B12: 1467 | C12: 2730 | D12: =B12/C12 | E12: 34419 | F12: 8.8400002 | G12: =0.01/F12*10000 | H12: =SQRT(SUMSQ(R1!$AD$2:$AD$2731)/2723)*10000 | I12: =G12/H12 | J12: =COUNTIF(R1!$AD$2:$AD$2731,0)/COUNT(R1!$AD$2:$AD$2731)
A13: AMZN | B13: 2730 | C13: 2730 | D13: =B13/C13 | E13: 52185 | F13: 246.69501 | H13: =SQRT(SUMSQ(R1!$AE$2:$AE$2731)/2723)*10000 | J13: =COUNTIF(R1!$AE$2:$AE$2731,0)/COUNT(R1!$AE$2:$AE$2731)
A14: PLTD | B14: 1731 | C14: 2730 | D14: =B14/C14 | E14: 49000 | F14: 4.7849998 | G14: =0.01/F14*10000 | H14: =SQRT(SUMSQ(R1!$AI$2:$AI$2731)/2723)*10000 | I14: =G14/H14 | J14: =COUNTIF(R1!$AI$2:$AI$2731,0)/COUNT(R1!$AI$2:$AI$2731)
A15: PLTR | B15: 2730 | C15: 2730 | D15: =B15/C15 | E15: 27949.5 | F15: 186.97 | H15: =SQRT(SUMSQ(R1!$AJ$2:$AJ$2731)/2723)*10000 | J15: =COUNTIF(R1!$AJ$2:$AJ$2731,0)/COUNT(R1!$AJ$2:$AJ$2731)

Sheet R1
A1: Time | B1: AVS | C1: AVGO | D1: AVS both traded | E1: AVS return | F1: AVGO return | G1: AAPD | H1: AAPL | I1: AAPD both traded | J1: AAPD return | K1: AAPL return | L1: METD | M1: META | N1: METD both traded | O1: METD return | P1: META return | Q1: MSFD | R1: MSFT | S1: MSFD both traded | T1: MSFD return | U1: MSFT return | V1: SPDN | W1: SPX | X1: SPDN both traded | Y1: SPDN return | Z1: SPX return | AA1: AMZD | AB1: AMZN | AC1: AMZD both traded | AD1: AMZD return | AE1: AMZN return | AF1: PLTD | AG1: PLTR | AH1: PLTD both traded | AI1: PLTD return | AJ1: PLTR return
A2: 46286.396 | B2: 8.1149998 | C2: 356.04001 | D2: 1 | G2: 10.44 | H2: 334.01501 | I2: 1 | L2: 13.8 | M2: 690.19 | N2: 1 | Q2: 10.41 | R2: 494.53 | S2: 1 | V2: 8.5494003 | W2: 7695.7402 | X2: 1 | AA2: 8.5499001 | AB2: 256.38 | AC2: 1 | AF2: 5.0500002 | AG2: 178.8501 | AH2: 1
A3: 46286.397 | B3: 8.1999998 | C3: 354.47 | D3: 1 | E3: =IF(AND(D3=1,INT($A3)=INT($A2),ISNUMBER(B2)),B3/B2-1,"") | F3: =IF(AND(D3=1,INT($A3)=INT($A2),ISNUMBER(C2)),C3/C2-1,"") | G3: 10.43 | H3: 334.06 | I3: 1 | J3: =IF(AND(I3=1,INT($A3)=INT($A2),ISNUMBER(G2)),G3/G2-1,"") | K3: =IF(AND(I3=1,INT($A3)=INT($A2),ISNUMBER(H2)),H3/H2-1,"") | L3: 13.69 | M3: 696.57001 | N3: 1 | O3: =IF(AND(N3=1,INT($A3)=INT($A2),ISNUMBER(L2)),L3/L2-1,"") | P3: =IF(AND(N3=1,INT($A3)=INT($A2),ISNUMBER(M2)),M3/M2-1,"") | Q3: 10.42 | R3: 494.59 | S3: 1 | T3: =IF(AND(S3=1,INT($A3)=INT($A2),ISNUMBER(Q2)),Q3/Q2-1,"") | U3: =IF(AND(S3=1,INT($A3)=INT($A2),ISNUMBER(R2)),R3/R2-1,"") | V3: 8.5450001 | W3: 7693.0898 | X3: 1 | Y3: =IF(AND(X3=1,INT($A3)=INT($A2),ISNUMBER(V2)),V3/V2-1,"") | Z3: =IF(AND(X3=1,INT($A3)=INT($A2),ISNUMBER(W2)),W3/W2-1,"") | AA3: 8.54 | AB3: 256.42499 | AC3: 1 | AD3: =IF(AND(AC3=1,INT($A3)=INT($A2),ISNUMBER(AA2)),AA3/AA2-1,"") | AE3: =IF(AND(AC3=1,INT($A3)=INT($A2),ISNUMBER(AB2)),AB3/AB2-1,"") | AF3: 5.0300002 | AG3: 179.53999 | AH3: 1 | AI3: =IF(AND(AH3=1,INT($A3)=INT($A2),ISNUMBER(AF2)),AF3/AF2-1,"") | AJ3: =IF(AND(AH3=1,INT($A3)=INT($A2),ISNUMBER(AG2)),AG3/AG2-1,"")
A4: 46286.397 | B4: 8.1999998 | C4: 354.64499 | D4: 1 | E4: =IF(AND(D4=1,INT($A4)=INT($A3),ISNUMBER(B3)),B4/B3-1,"") | F4: =IF(AND(D4=1,INT($A4)=INT($A3),ISNUMBER(C3)),C4/C3-1,"") | G4: 10.43 | H4: 334.54999 | I4: 1 | J4: =IF(AND(I4=1,INT($A4)=INT($A3),ISNUMBER(G3)),G4/G3-1,"") | K4: =IF(AND(I4=1,INT($A4)=INT($A3),ISNUMBER(H3)),H4/H3-1,"") | L4: 13.6 | M4: 698.05499 | N4: 1 | O4: =IF(AND(N4=1,INT($A4)=INT($A3),ISNUMBER(L3)),L4/L3-1,"") | P4: =IF(AND(N4=1,INT($A4)=INT($A3),ISNUMBER(M3)),M4/M3-1,"") | Q4: 10.43 | R4: 493.39001 | S4: 1 | T4: =IF(AND(S4=1,INT($A4)=INT($A3),ISNUMBER(Q3)),Q4/Q3-1,"") | U4: =IF(AND(S4=1,INT($A4)=INT($A3),ISNUMBER(R3)),R4/R3-1,"") | V4: 8.5450001 | W4: 7693.0898 | X4: 0 | Y4: =IF(AND(X4=1,INT($A4)=INT($A3),ISNUMBER(V3)),V4/V3-1,"") | Z4: =IF(AND(X4=1,INT($A4)=INT($A3),ISNUMBER(W3)),W4/W3-1,"") | AA4: 8.54 | AB4: 256.42499 | AC4: 0 | AD4: =IF(AND(AC4=1,INT($A4)=INT($A3),ISNUMBER(AA3)),AA4/AA3-1,"") | AE4: =IF(AND(AC4=1,INT($A4)=INT($A3),ISNUMBER(AB3)),AB4/AB3-1,"") | AF4: 5.0500002 | AG4: 178.66 | AH4: 1 | AI4: =IF(AND(AH4=1,INT($A4)=INT($A3),ISNUMBER(AF3)),AF4/AF3-1,"") | AJ4: =IF(AND(AH4=1,INT($A4)=INT($A3),ISNUMBER(AG3)),AG4/AG3-1,"")
A5: 46286.398 | B5: 8.21 | C5: 354.595 | D5: 1 | E5: =IF(AND(D5=1,INT($A5)=INT($A4),ISNUMBER(B4)),B5/B4-1,"") | F5: =IF(AND(D5=1,INT($A5)=INT($A4),ISNUMBER(C4)),C5/C4-1,"") | G5: 10.43 | H5: 334.05051 | I5: 1 | J5: =IF(AND(I5=1,INT($A5)=INT($A4),ISNUMBER(G4)),G5/G4-1,"") | K5: =IF(AND(I5=1,INT($A5)=INT($A4),ISNUMBER(H4)),H5/H4-1,"") | L5: 13.57 | M5: 699.78998 | N5: 1 | O5: =IF(AND(N5=1,INT($A5)=INT($A4),ISNUMBER(L4)),L5/L4-1,"") | P5: =IF(AND(N5=1,INT($A5)=INT($A4),ISNUMBER(M4)),M5/M4-1,"") | Q5: 10.43 | R5: 493.39001 | S5: 0 | T5: =IF(AND(S5=1,INT($A5)=INT($A4),ISNUMBER(Q4)),Q5/Q4-1,"") | U5: =IF(AND(S5=1,INT($A5)=INT($A4),ISNUMBER(R4)),R5/R4-1,"") | V5: 8.5450001 | W5: 7693.8901 | X5: 1 | Y5: =IF(AND(X5=1,INT($A5)=INT($A4),ISNUMBER(V4)),V5/V4-1,"") | Z5: =IF(AND(X5=1,INT($A5)=INT($A4),ISNUMBER(W4)),W5/W4-1,"") | AA5: 8.5799999 | AB5: 255.27 | AC5: 1 | AD5: =IF(AND(AC5=1,INT($A5)=INT($A4),ISNUMBER(AA4)),AA5/AA4-1,"") | AE5: =IF(AND(AC5=1,INT($A5)=INT($A4),ISNUMBER(AB4)),AB5/AB4-1,"") | AF5: 5.0749998 | AG5: 178.17 | AH5: 1 | AI5: =IF(AND(AH5=1,INT($A5)=INT($A4),ISNUMBER(AF4)),AF5/AF4-1,"") | AJ5: =IF(AND(AH5=1,INT($A5)=INT($A4),ISNUMBER(AG4)),AG5/AG4-1,"")
A6: 46286.399 | B6: 8.1999998 | C6: 355.16501 | D6: 1 | E6: =IF(AND(D6=1,INT($A6)=INT($A5),ISNUMBER(B5)),B6/B5-1,"") | F6: =IF(AND(D6=1,INT($A6)=INT($A5),ISNUMBER(C5)),C6/C5-1,"") | G6: 10.43 | H6: 334.05051 | I6: 0 | J6: =IF(AND(I6=1,INT($A6)=INT($A5),ISNUMBER(G5)),G6/G5-1,"") | K6: =IF(AND(I6=1,INT($A6)=INT($A5),ISNUMBER(H5)),H6/H5-1,"") | L6: 13.57 | M6: 699.47998 | N6: 1 | O6: =IF(AND(N6=1,INT($A6)=INT($A5),ISNUMBER(L5)),L6/L5-1,"") | P6: =IF(AND(N6=1,INT($A6)=INT($A5),ISNUMBER(M5)),M6/M5-1,"") | Q6: 10.43 | R6: 493.39001 | S6: 0 | T6: =IF(AND(S6=1,INT($A6)=INT($A5),ISNUMBER(Q5)),Q6/Q5-1,"") | U6: =IF(AND(S6=1,INT($A6)=INT($A5),ISNUMBER(R5)),R6/R5-1,"") | V6: 8.5450001 | W6: 7693.8901 | X6: 0 | Y6: =IF(AND(X6=1,INT($A6)=INT($A5),ISNUMBER(V5)),V6/V5-1,"") | Z6: =IF(AND(X6=1,INT($A6)=INT($A5),ISNUMBER(W5)),W6/W5-1,"") | AA6: 8.5900002 | AB6: 254.94 | AC6: 1 | AD6: =IF(AND(AC6=1,INT($A6)=INT($A5),ISNUMBER(AA5)),AA6/AA5-1,"") | AE6: =IF(AND(AC6=1,INT($A6)=INT($A5),ISNUMBER(AB5)),AB6/AB5-1,"") | AF6: 5.0599999 | AG6: 178.71001 | AH6: 1 | AI6: =IF(AND(AH6=1,INT($A6)=INT($A5),ISNUMBER(AF5)),AF6/AF5-1,"") | AJ6: =IF(AND(AH6=1,INT($A6)=INT($A5),ISNUMBER(AG5)),AG6/AG5-1,"")
A7: 46286.399 | B7: 8.1800003 | C7: 355.16989 | D7: 1 | E7: =IF(AND(D7=1,INT($A7)=INT($A6),ISNUMBER(B6)),B7/B6-1,"") | F7: =IF(AND(D7=1,INT($A7)=INT($A6),ISNUMBER(C6)),C7/C6-1,"") | G7: 10.4208 | H7: 334.41 | I7: 1 | J7: =IF(AND(I7=1,INT($A7)=INT($A6),ISNUMBER(G6)),G7/G6-1,"") | K7: =IF(AND(I7=1,INT($A7)=INT($A6),ISNUMBER(H6)),H7/H6-1,"") | L7: 13.57 | M7: 698.20001 | N7: 1 | O7: =IF(AND(N7=1,INT($A7)=INT($A6),ISNUMBER(L6)),L7/L6-1,"") | P7: =IF(AND(N7=1,INT($A7)=INT($A6),ISNUMBER(M6)),M7/M6-1,"") | Q7: 10.42 | R7: 494.35999 | S7: 1 | T7: =IF(AND(S7=1,INT($A7)=INT($A6),ISNUMBER(Q6)),Q7/Q6-1,"") | U7: =IF(AND(S7=1,INT($A7)=INT($A6),ISNUMBER(R6)),R7/R6-1,"") | V7: 8.5450001 | W7: 7693.8901 | X7: 0 | Y7: =IF(AND(X7=1,INT($A7)=INT($A6),ISNUMBER(V6)),V7/V6-1,"") | Z7: =IF(AND(X7=1,INT($A7)=INT($A6),ISNUMBER(W6)),W7/W6-1,"") | AA7: 8.6000004 | AB7: 254.72501 | AC7: 1 | AD7: =IF(AND(AC7=1,INT($A7)=INT($A6),ISNUMBER(AA6)),AA7/AA6-1,"") | AE7: =IF(AND(AC7=1,INT($A7)=INT($A6),ISNUMBER(AB6)),AB7/AB6-1,"") | AF7: 5.04 | AG7: 179.32001 | AH7: 1 | AI7: =IF(AND(AH7=1,INT($A7)=INT($A6),ISNUMBER(AF6)),AF7/AF6-1,"") | AJ7: =IF(AND(AH7=1,INT($A7)=INT($A6),ISNUMBER(AG6)),AG7/AG6-1,"")
A8: 46286.4 | B8: 8.1800003 | C8: 355.55499 | D8: 1 | E8: =IF(AND(D8=1,INT($A8)=INT($A7),ISNUMBER(B7)),B8/B7-1,"") | F8: =IF(AND(D8=1,INT($A8)=INT($A7),ISNUMBER(C7)),C8/C7-1,"") | G8: 10.42 | H8: 333.91 | I8: 1 | J8: =IF(AND(I8=1,INT($A8)=INT($A7),ISNUMBER(G7)),G8/G7-1,"") | K8: =IF(AND(I8=1,INT($A8)=INT($A7),ISNUMBER(H7)),H8/H7-1,"") | L8: 13.6 | M8: 699.25 | N8: 1 | O8: =IF(AND(N8=1,INT($A8)=INT($A7),ISNUMBER(L7)),L8/L7-1,"") | P8: =IF(AND(N8=1,INT($A8)=INT($A7),ISNUMBER(M7)),M8/M7-1,"") | Q8: 10.41 | R8: 494.5 | S8: 1 | T8: =IF(AND(S8=1,INT($A8)=INT($A7),ISNUMBER(Q7)),Q8/Q7-1,"") | U8: =IF(AND(S8=1,INT($A8)=INT($A7),ISNUMBER(R7)),R8/R7-1,"") | V8: 8.5450001 | W8: 7693.8901 | X8: 0 | Y8: =IF(AND(X8=1,INT($A8)=INT($A7),ISNUMBER(V7)),V8/V7-1,"") | Z8: =IF(AND(X8=1,INT($A8)=INT($A7),ISNUMBER(W7)),W8/W7-1,"") | AA8: 8.5900002 | AB8: 255.36 | AC8: 1 | AD8: =IF(AND(AC8=1,INT($A8)=INT($A7),ISNUMBER(AA7)),AA8/AA7-1,"") | AE8: =IF(AND(AC8=1,INT($A8)=INT($A7),ISNUMBER(AB7)),AB8/AB7-1,"") | AF8: 5.0407 | AG8: 179.21851 | AH8: 1 | AI8: =IF(AND(AH8=1,INT($A8)=INT($A7),ISNUMBER(AF7)),AF8/AF7-1,"") | AJ8: =IF(AND(AH8=1,INT($A8)=INT($A7),ISNUMBER(AG7)),AG8/AG7-1,"")
A9: 46286.401 | B9: 8.1899996 | C9: 355.53021 | D9: 1 | E9: =IF(AND(D9=1,INT($A9)=INT($A8),ISNUMBER(B8)),B9/B8-1,"") | F9: =IF(AND(D9=1,INT($A9)=INT($A8),ISNUMBER(C8)),C9/C8-1,"") | G9: 10.44 | H9: 333.64001 | I9: 1 | J9: =IF(AND(I9=1,INT($A9)=INT($A8),ISNUMBER(G8)),G9/G8-1,"") | K9: =IF(AND(I9=1,INT($A9)=INT($A8),ISNUMBER(H8)),H9/H8-1,"") | L9: 13.5778 | M9: 699.625 | N9: 1 | O9: =IF(AND(N9=1,INT($A9)=INT($A8),ISNUMBER(L8)),L9/L8-1,"") | P9: =IF(AND(N9=1,INT($A9)=INT($A8),ISNUMBER(M8)),M9/M8-1,"") | Q9: 10.4213 | R9: 494.245 | S9: 1 | T9: =IF(AND(S9=1,INT($A9)=INT($A8),ISNUMBER(Q8)),Q9/Q8-1,"") | U9: =IF(AND(S9=1,INT($A9)=INT($A8),ISNUMBER(R8)),R9/R8-1,"") | V9: 8.5450001 | W9: 7693.8901 | X9: 0 | Y9: =IF(AND(X9=1,INT($A9)=INT($A8),ISNUMBER(V8)),V9/V8-1,"") | Z9: =IF(AND(X9=1,INT($A9)=INT($A8),ISNUMBER(W8)),W9/W8-1,"") | AA9: 8.5699997 | AB9: 255.91409 | AC9: 1 | AD9: =IF(AND(AC9=1,INT($A9)=INT($A8),ISNUMBER(AA8)),AA9/AA8-1,"") | AE9: =IF(AND(AC9=1,INT($A9)=INT($A8),ISNUMBER(AB8)),AB9/AB8-1,"") | AF9: 5.0500002 | AG9: 178.99001 | AH9: 1 | AI9: =IF(AND(AH9=1,INT($A9)=INT($A8),ISNUMBER(AF8)),AF9/AF8-1,"") | AJ9: =IF(AND(AH9=1,INT($A9)=INT($A8),ISNUMBER(AG8)),AG9/AG8-1,"")
A10: 46286.401 | B10: 8.1807003 | C10: 355.26001 | D10: 1 | E10: =IF(AND(D10=1,INT($A10)=INT($A9),ISNUMBER(B9)),B10/B9-1,"") | F10: =IF(AND(D10=1,INT($A10)=INT($A9),ISNUMBER(C9)),C10/C9-1,"") | G10: 10.46 | H10: 333.13 | I10: 1 | J10: =IF(AND(I10=1,INT($A10)=INT($A9),ISNUMBER(G9)),G10/G9-1,"") | K10: =IF(AND(I10=1,INT($A10)=INT($A9),ISNUMBER(H9)),H10/H9-1,"") | L10: 13.59 | M10: 698.94501 | N10: 1 | O10: =IF(AND(N10=1,INT($A10)=INT($A9),ISNUMBER(L9)),L10/L9-1,"") | P10: =IF(AND(N10=1,INT($A10)=INT($A9),ISNUMBER(M9)),M10/M9-1,"") | Q10: 10.4213 | R10: 494.245 | S10: 0 | T10: =IF(AND(S10=1,INT($A10)=INT($A9),ISNUMBER(Q9)),Q10/Q9-1,"") | U10: =IF(AND(S10=1,INT($A10)=INT($A9),ISNUMBER(R9)),R10/R9-1,"") | V10: 8.5450001 | W10: 7697.25 | X10: 1 | Y10: =IF(AND(X10=1,INT($A10)=INT($A9),ISNUMBER(V9)),V10/V9-1,"") | Z10: =IF(AND(X10=1,INT($A10)=INT($A9),ISNUMBER(W9)),W10/W9-1,"") | AA10: 8.5571003 | AB10: 256.17999 | AC10: 1 | AD10: =IF(AND(AC10=1,INT($A10)=INT($A9),ISNUMBER(AA9)),AA10/AA9-1,"") | AE10: =IF(AND(AC10=1,INT($A10)=INT($A9),ISNUMBER(AB9)),AB10/AB9-1,"") | AF10: 5.0749998 | AG10: 178.14999 | AH10: 1 | AI10: =IF(AND(AH10=1,INT($A10)=INT($A9),ISNUMBER(AF9)),AF10/AF9-1,"") | AJ10: =IF(AND(AH10=1,INT($A10)=INT($A9),ISNUMBER(AG9)),AG10/AG9-1,"")
A11: 46286.402 | B11: 8.1899996 | C11: 355.09 | D11: 1 | E11: =IF(AND(D11=1,INT($A11)=INT($A10),ISNUMBER(B10)),B11/B10-1,"") | F11: =IF(AND(D11=1,INT($A11)=INT($A10),ISNUMBER(C10)),C11/C10-1,"") | G11: 10.45 | H11: 333.37 | I11: 1 | J11: =IF(AND(I11=1,INT($A11)=INT($A10),ISNUMBER(G10)),G11/G10-1,"") | K11: =IF(AND(I11=1,INT($A11)=INT($A10),ISNUMBER(H10)),H11/H10-1,"") | L11: 13.5899 | M11: 698.59998 | N11: 1 | O11: =IF(AND(N11=1,INT($A11)=INT($A10),ISNUMBER(L10)),L11/L10-1,"") | P11: =IF(AND(N11=1,INT($A11)=INT($A10),ISNUMBER(M10)),M11/M10-1,"") | Q11: 10.4213 | R11: 494.245 | S11: 0 | T11: =IF(AND(S11=1,INT($A11)=INT($A10),ISNUMBER(Q10)),Q11/Q10-1,"") | U11: =IF(AND(S11=1,INT($A11)=INT($A10),ISNUMBER(R10)),R11/R10-1,"") | V11: 8.54 | W11: 7697.4902 | X11: 1 | Y11: =IF(AND(X11=1,INT($A11)=INT($A10),ISNUMBER(V10)),V11/V10-1,"") | Z11: =IF(AND(X11=1,INT($A11)=INT($A10),ISNUMBER(W10)),W11/W10-1,"") | AA11: 8.5571003 | AB11: 256.17999 | AC11: 0 | AD11: =IF(AND(AC11=1,INT($A11)=INT($A10),ISNUMBER(AA10)),AA11/AA10-1,"") | AE11: =IF(AND(AC11=1,INT($A11)=INT($A10),ISNUMBER(AB10)),AB11/AB10-1,"") | AF11: 5.0799999 | AG11: 177.96001 | AH11: 1 | AI11: =IF(AND(AH11=1,INT($A11)=INT($A10),ISNUMBER(AF10)),AF11/AF10-1,"") | AJ11: =IF(AND(AH11=1,INT($A11)=INT($A10),ISNUMBER(AG10)),AG11/AG10-1,"")
A12: 46286.403 | B12: 8.1850004 | C12: 355.35999 | D12: 1 | E12: =IF(AND(D12=1,INT($A12)=INT($A11),ISNUMBER(B11)),B12/B11-1,"") | F12: =IF(AND(D12=1,INT($A12)=INT($A11),ISNUMBER(C11)),C12/C11-1,"") | G12: 10.45 | H12: 333.38 | I12: 1 | J12: =IF(AND(I12=1,INT($A12)=INT($A11),ISNUMBER(G11)),G12/G11-1,"") | K12: =IF(AND(I12=1,INT($A12)=INT($A11),ISNUMBER(H11)),H12/H11-1,"") | L12: 13.5699 | M12: 699.79633 | N12: 1 | O12: =IF(AND(N12=1,INT($A12)=INT($A11),ISNUMBER(L11)),L12/L11-1,"") | P12: =IF(AND(N12=1,INT($A12)=INT($A11),ISNUMBER(M11)),M12/M11-1,"") | Q12: 10.44 | R12: 493.67499 | S12: 1 | T12: =IF(AND(S12=1,INT($A12)=INT($A11),ISNUMBER(Q11)),Q12/Q11-1,"") | U12: =IF(AND(S12=1,INT($A12)=INT($A11),ISNUMBER(R11)),R12/R11-1,"") | V12: 8.5401001 | W12: 7697.0801 | X12: 1 | Y12: =IF(AND(X12=1,INT($A12)=INT($A11),ISNUMBER(V11)),V12/V11-1,"") | Z12: =IF(AND(X12=1,INT($A12)=INT($A11),ISNUMBER(W11)),W12/W11-1,"") | AA12: 8.5600996 | AB12: 255.85001 | AC12: 1 | AD12: =IF(AND(AC12=1,INT($A12)=INT($A11),ISNUMBER(AA11)),AA12/AA11-1,"") | AE12: =IF(AND(AC12=1,INT($A12)=INT($A11),ISNUMBER(AB11)),AB12/AB11-1,"") | AF12: 5.0949998 | AG12: 177.27 | AH12: 1 | AI12: =IF(AND(AH12=1,INT($A12)=INT($A11),ISNUMBER(AF11)),AF12/AF11-1,"") | AJ12: =IF(AND(AH12=1,INT($A12)=INT($A11),ISNUMBER(AG11)),AG12/AG11-1,"")
A13: 46286.403 | B13: 8.1700001 | C13: 356.27499 | D13: 1 | E13: =IF(AND(D13=1,INT($A13)=INT($A12),ISNUMBER(B12)),B13/B12-1,"") | F13: =IF(AND(D13=1,INT($A13)=INT($A12),ISNUMBER(C12)),C13/C12-1,"") | G13: 10.45 | H13: 333.38 | I13: 0 | J13: =IF(AND(I13=1,INT($A13)=INT($A12),ISNUMBER(G12)),G13/G12-1,"") | K13: =IF(AND(I13=1,INT($A13)=INT($A12),ISNUMBER(H12)),H13/H12-1,"") | L13: 13.575 | M13: 698.91998 | N13: 1 | O13: =IF(AND(N13=1,INT($A13)=INT($A12),ISNUMBER(L12)),L13/L12-1,"") | P13: =IF(AND(N13=1,INT($A13)=INT($A12),ISNUMBER(M12)),M13/M12-1,"") | Q13: 10.45 | R13: 492.17499 | S13: 1 | T13: =IF(AND(S13=1,INT($A13)=INT($A12),ISNUMBER(Q12)),Q13/Q12-1,"") | U13: =IF(AND(S13=1,INT($A13)=INT($A12),ISNUMBER(R12)),R13/R12-1,"") | V13: 8.5401001 | W13: 7696.5601 | X13: 1 | Y13: =IF(AND(X13=1,INT($A13)=INT($A12),ISNUMBER(V12)),V13/V12-1,"") | Z13: =IF(AND(X13=1,INT($A13)=INT($A12),ISNUMBER(W12)),W13/W12-1,"") | AA13: 8.5749998 | AB13: 255.66499 | AC13: 1 | AD13: =IF(AND(AC13=1,INT($A13)=INT($A12),ISNUMBER(AA12)),AA13/AA12-1,"") | AE13: =IF(AND(AC13=1,INT($A13)=INT($A12),ISNUMBER(AB12)),AB13/AB12-1,"") | AF13: 5.0998998 | AG13: 177.28 | AH13: 1 | AI13: =IF(AND(AH13=1,INT($A13)=INT($A12),ISNUMBER(AF12)),AF13/AF12-1,"") | AJ13: =IF(AND(AH13=1,INT($A13)=INT($A12),ISNUMBER(AG12)),AG13/AG12-1,"")
A14: 46286.404 | B14: 8.1599998 | C14: 356.73001 | D14: 1 | E14: =IF(AND(D14=1,INT($A14)=INT($A13),ISNUMBER(B13)),B14/B13-1,"") | F14: =IF(AND(D14=1,INT($A14)=INT($A13),ISNUMBER(C13)),C14/C13-1,"") | G14: 10.45 | H14: 333.38 | I14: 0 | J14: =IF(AND(I14=1,INT($A14)=INT($A13),ISNUMBER(G13)),G14/G13-1,"") | K14: =IF(AND(I14=1,INT($A14)=INT($A13),ISNUMBER(H13)),H14/H13-1,"") | L14: 13.56 | M14: 699.57013 | N14: 1 | O14: =IF(AND(N14=1,INT($A14)=INT($A13),ISNUMBER(L13)),L14/L13-1,"") | P14: =IF(AND(N14=1,INT($A14)=INT($A13),ISNUMBER(M13)),M14/M13-1,"") | Q14: 10.465 | R14: 492.60999 | S14: 1 | T14: =IF(AND(S14=1,INT($A14)=INT($A13),ISNUMBER(Q13)),Q14/Q13-1,"") | U14: =IF(AND(S14=1,INT($A14)=INT($A13),ISNUMBER(R13)),R14/R13-1,"") | V14: 8.5401001 | W14: 7696.5601 | X14: 0 | Y14: =IF(AND(X14=1,INT($A14)=INT($A13),ISNUMBER(V13)),V14/V13-1,"") | Z14: =IF(AND(X14=1,INT($A14)=INT($A13),ISNUMBER(W13)),W14/W13-1,"") | AA14: 8.5801001 | AB14: 255.31 | AC14: 1 | AD14: =IF(AND(AC14=1,INT($A14)=INT($A13),ISNUMBER(AA13)),AA14/AA13-1,"") | AE14: =IF(AND(AC14=1,INT($A14)=INT($A13),ISNUMBER(AB13)),AB14/AB13-1,"") | AF14: 5.0899 | AG14: 177.515 | AH14: 1 | AI14: =IF(AND(AH14=1,INT($A14)=INT($A13),ISNUMBER(AF13)),AF14/AF13-1,"") | AJ14: =IF(AND(AH14=1,INT($A14)=INT($A13),ISNUMBER(AG13)),AG14/AG13-1,"")
... A2731: 46294.666 | B2731: 8.1549997 | C2731: 355.13 | D2731: 0 | E2731: =IF(AND(D2731=1,INT($A2731)=INT($A2730),ISNUMBER(B2730)),B2731/B2730-1,"") | F2731: =IF(AND(D2731=1,INT($A2731)=INT($A2730),ISNUMBER(C2730)),C2731/C2730-1,"") | G2731: 10.405 | H2731: 329.59 | I2731: 1 | J2731: =IF(AND(I2731=1,INT($A2731)=INT($A2730),ISNUMBER(G2730)),G2731/G2730-1,"") | K2731: =IF(AND(I2731=1,INT($A2731)=INT($A2730),ISNUMBER(H2730)),H2731/H2730-1,"") | L2731: 12.585 | M2731: 739.02002 | N2731: 1 | O2731: =IF(AND(N2731=1,INT($A2731)=INT($A2730),ISNUMBER(L2730)),L2731/L2730-1,"") | P2731: =IF(AND(N2731=1,INT($A2731)=INT($A2730),ISNUMBER(M2730)),M2731/M2730-1,"") | Q2731: 10.05 | R2731: 509.04001 | S2731: 1 | T2731: =IF(AND(S2731=1,INT($A2731)=INT($A2730),ISNUMBER(Q2730)),Q2731/Q2730-1,"") | U2731: =IF(AND(S2731=1,INT($A2731)=INT($A2730),ISNUMBER(R2730)),R2731/R2730-1,"") | V2731: 8.4700003 | W2731: 7671.8501 | X2731: 1 | Y2731: =IF(AND(X2731=1,INT($A2731)=INT($A2730),ISNUMBER(V2730)),V2731/V2730-1,"") | Z2731: =IF(AND(X2731=1,INT($A2731)=INT($A2730),ISNUMBER(W2730)),W2731/W2730-1,"") | AA2731: 8.8400002 | AB2731: 246.69501 | AC2731: 1 | AD2731: =IF(AND(AC2731=1,INT($A2731)=INT($A2730),ISNUMBER(AA2730)),AA2731/AA2730-1,"") | AE2731: =IF(AND(AC2731=1,INT($A2731)=INT($A2730),ISNUMBER(AB2730)),AB2731/AB2730-1,"") | AF2731: 4.7849998 | AG2731: 186.97 | AH2731: 1 | AI2731: =IF(AND(AH2731=1,INT($A2731)=INT($A2730),ISNUMBER(AF2730)),AF2731/AF2730-1,"") | AJ2731: =IF(AND(AH2731=1,INT($A2731)=INT($A2730),ISNUMBER(AG2730)),AG2731/AG2730-1,"")

Sheet R2
A1: Time | B1: AVS | C1: AVGO | D1: AVS both traded | E1: AVS return | F1: AVGO return | G1: AAPD | H1: AAPL | I1: AAPD both traded | J1: AAPD return | K1: AAPL return | L1: METD | M1: META | N1: METD both traded | O1: METD return | P1: META return | Q1: MSFD | R1: MSFT | S1: MSFD both traded | T1: MSFD return | U1: MSFT return | V1: SPDN | W1: SPX | X1: SPDN both traded | Y1: SPDN return | Z1: SPX return | AA1: AMZD | AB1: AMZN | AC1: AMZD both traded | AD1: AMZD return | AE1: AMZN return | AF1: PLTD | AG1: PLTR | AH1: PLTD both traded | AI1: PLTD return | AJ1: PLTR return
A2: 46286.396 | B2: 8.1149998 | C2: 356.04001 | D2: 1 | G2: 10.44 | H2: 334.01501 | I2: 1 | L2: 13.8 | M2: 690.19 | N2: 1 | Q2: 10.41 | R2: 494.53 | S2: 1 | V2: 8.5494003 | W2: 7695.7402 | X2: 1 | AA2: 8.5499001 | AB2: 256.38 | AC2: 1 | AF2: 5.0500002 | AG2: 178.8501 | AH2: 1
A3: 46286.397 | B3: 8.1999998 | C3: 354.64499 | D3: 1 | E3: =IF(AND(D3=1,INT($A3)=INT($A2),ISNUMBER(B2)),B3/B2-1,"") | F3: =IF(AND(D3=1,INT($A3)=INT($A2),ISNUMBER(C2)),C3/C2-1,"") | G3: 10.43 | H3: 334.54999 | I3: 1 | J3: =IF(AND(I3=1,INT($A3)=INT($A2),ISNUMBER(G2)),G3/G2-1,"") | K3: =IF(AND(I3=1,INT($A3)=INT($A2),ISNUMBER(H2)),H3/H2-1,"") | L3: 13.6 | M3: 698.05499 | N3: 1 | O3: =IF(AND(N3=1,INT($A3)=INT($A2),ISNUMBER(L2)),L3/L2-1,"") | P3: =IF(AND(N3=1,INT($A3)=INT($A2),ISNUMBER(M2)),M3/M2-1,"") | Q3: 10.43 | R3: 493.39001 | S3: 1 | T3: =IF(AND(S3=1,INT($A3)=INT($A2),ISNUMBER(Q2)),Q3/Q2-1,"") | U3: =IF(AND(S3=1,INT($A3)=INT($A2),ISNUMBER(R2)),R3/R2-1,"") | V3: 8.5450001 | W3: 7693.0898 | X3: 1 | Y3: =IF(AND(X3=1,INT($A3)=INT($A2),ISNUMBER(V2)),V3/V2-1,"") | Z3: =IF(AND(X3=1,INT($A3)=INT($A2),ISNUMBER(W2)),W3/W2-1,"") | AA3: 8.54 | AB3: 256.42499 | AC3: 1 | AD3: =IF(AND(AC3=1,INT($A3)=INT($A2),ISNUMBER(AA2)),AA3/AA2-1,"") | AE3: =IF(AND(AC3=1,INT($A3)=INT($A2),ISNUMBER(AB2)),AB3/AB2-1,"") | AF3: 5.0500002 | AG3: 178.66 | AH3: 1 | AI3: =IF(AND(AH3=1,INT($A3)=INT($A2),ISNUMBER(AF2)),AF3/AF2-1,"") | AJ3: =IF(AND(AH3=1,INT($A3)=INT($A2),ISNUMBER(AG2)),AG3/AG2-1,"")
A4: 46286.399 | B4: 8.1999998 | C4: 355.16501 | D4: 1 | E4: =IF(AND(D4=1,INT($A4)=INT($A3),ISNUMBER(B3)),B4/B3-1,"") | F4: =IF(AND(D4=1,INT($A4)=INT($A3),ISNUMBER(C3)),C4/C3-1,"") | G4: 10.43 | H4: 334.05051 | I4: 1 | J4: =IF(AND(I4=1,INT($A4)=INT($A3),ISNUMBER(G3)),G4/G3-1,"") | K4: =IF(AND(I4=1,INT($A4)=INT($A3),ISNUMBER(H3)),H4/H3-1,"") | L4: 13.57 | M4: 699.47998 | N4: 1 | O4: =IF(AND(N4=1,INT($A4)=INT($A3),ISNUMBER(L3)),L4/L3-1,"") | P4: =IF(AND(N4=1,INT($A4)=INT($A3),ISNUMBER(M3)),M4/M3-1,"") | Q4: 10.43 | R4: 493.39001 | S4: 0 | T4: =IF(AND(S4=1,INT($A4)=INT($A3),ISNUMBER(Q3)),Q4/Q3-1,"") | U4: =IF(AND(S4=1,INT($A4)=INT($A3),ISNUMBER(R3)),R4/R3-1,"") | V4: 8.5450001 | W4: 7693.8901 | X4: 1 | Y4: =IF(AND(X4=1,INT($A4)=INT($A3),ISNUMBER(V3)),V4/V3-1,"") | Z4: =IF(AND(X4=1,INT($A4)=INT($A3),ISNUMBER(W3)),W4/W3-1,"") | AA4: 8.5900002 | AB4: 254.94 | AC4: 1 | AD4: =IF(AND(AC4=1,INT($A4)=INT($A3),ISNUMBER(AA3)),AA4/AA3-1,"") | AE4: =IF(AND(AC4=1,INT($A4)=INT($A3),ISNUMBER(AB3)),AB4/AB3-1,"") | AF4: 5.0599999 | AG4: 178.71001 | AH4: 1 | AI4: =IF(AND(AH4=1,INT($A4)=INT($A3),ISNUMBER(AF3)),AF4/AF3-1,"") | AJ4: =IF(AND(AH4=1,INT($A4)=INT($A3),ISNUMBER(AG3)),AG4/AG3-1,"")
A5: 46286.4 | B5: 8.1800003 | C5: 355.55499 | D5: 1 | E5: =IF(AND(D5=1,INT($A5)=INT($A4),ISNUMBER(B4)),B5/B4-1,"") | F5: =IF(AND(D5=1,INT($A5)=INT($A4),ISNUMBER(C4)),C5/C4-1,"") | G5: 10.42 | H5: 333.91 | I5: 1 | J5: =IF(AND(I5=1,INT($A5)=INT($A4),ISNUMBER(G4)),G5/G4-1,"") | K5: =IF(AND(I5=1,INT($A5)=INT($A4),ISNUMBER(H4)),H5/H4-1,"") | L5: 13.6 | M5: 699.25 | N5: 1 | O5: =IF(AND(N5=1,INT($A5)=INT($A4),ISNUMBER(L4)),L5/L4-1,"") | P5: =IF(AND(N5=1,INT($A5)=INT($A4),ISNUMBER(M4)),M5/M4-1,"") | Q5: 10.41 | R5: 494.5 | S5: 1 | T5: =IF(AND(S5=1,INT($A5)=INT($A4),ISNUMBER(Q4)),Q5/Q4-1,"") | U5: =IF(AND(S5=1,INT($A5)=INT($A4),ISNUMBER(R4)),R5/R4-1,"") | V5: 8.5450001 | W5: 7693.8901 | X5: 0 | Y5: =IF(AND(X5=1,INT($A5)=INT($A4),ISNUMBER(V4)),V5/V4-1,"") | Z5: =IF(AND(X5=1,INT($A5)=INT($A4),ISNUMBER(W4)),W5/W4-1,"") | AA5: 8.5900002 | AB5: 255.36 | AC5: 1 | AD5: =IF(AND(AC5=1,INT($A5)=INT($A4),ISNUMBER(AA4)),AA5/AA4-1,"") | AE5: =IF(AND(AC5=1,INT($A5)=INT($A4),ISNUMBER(AB4)),AB5/AB4-1,"") | AF5: 5.0407 | AG5: 179.21851 | AH5: 1 | AI5: =IF(AND(AH5=1,INT($A5)=INT($A4),ISNUMBER(AF4)),AF5/AF4-1,"") | AJ5: =IF(AND(AH5=1,INT($A5)=INT($A4),ISNUMBER(AG4)),AG5/AG4-1,"")
A6: 46286.401 | B6: 8.1807003 | C6: 355.26001 | D6: 1 | E6: =IF(AND(D6=1,INT($A6)=INT($A5),ISNUMBER(B5)),B6/B5-1,"") | F6: =IF(AND(D6=1,INT($A6)=INT($A5),ISNUMBER(C5)),C6/C5-1,"") | G6: 10.46 | H6: 333.13 | I6: 1 | J6: =IF(AND(I6=1,INT($A6)=INT($A5),ISNUMBER(G5)),G6/G5-1,"") | K6: =IF(AND(I6=1,INT($A6)=INT($A5),ISNUMBER(H5)),H6/H5-1,"") | L6: 13.59 | M6: 698.94501 | N6: 1 | O6: =IF(AND(N6=1,INT($A6)=INT($A5),ISNUMBER(L5)),L6/L5-1,"") | P6: =IF(AND(N6=1,INT($A6)=INT($A5),ISNUMBER(M5)),M6/M5-1,"") | Q6: 10.4213 | R6: 494.245 | S6: 1 | T6: =IF(AND(S6=1,INT($A6)=INT($A5),ISNUMBER(Q5)),Q6/Q5-1,"") | U6: =IF(AND(S6=1,INT($A6)=INT($A5),ISNUMBER(R5)),R6/R5-1,"") | V6: 8.5450001 | W6: 7697.25 | X6: 1 | Y6: =IF(AND(X6=1,INT($A6)=INT($A5),ISNUMBER(V5)),V6/V5-1,"") | Z6: =IF(AND(X6=1,INT($A6)=INT($A5),ISNUMBER(W5)),W6/W5-1,"") | AA6: 8.5571003 | AB6: 256.17999 | AC6: 1 | AD6: =IF(AND(AC6=1,INT($A6)=INT($A5),ISNUMBER(AA5)),AA6/AA5-1,"") | AE6: =IF(AND(AC6=1,INT($A6)=INT($A5),ISNUMBER(AB5)),AB6/AB5-1,"") | AF6: 5.0749998 | AG6: 178.14999 | AH6: 1 | AI6: =IF(AND(AH6=1,INT($A6)=INT($A5),ISNUMBER(AF5)),AF6/AF5-1,"") | AJ6: =IF(AND(AH6=1,INT($A6)=INT($A5),ISNUMBER(AG5)),AG6/AG5-1,"")
